Workbook
Name UPDATE: 'Data Sheet'!$E$1

Sheet Financial>

Sheet Historical FS
B2: ="Historical Financial Statement-"&'Data Sheet'!B1 -> Historical Financial Statement-JSW STEEL LTD
B3: Years | C3: ='Data Sheet'!B16 -> 42094 | D3: ='Data Sheet'!C16 -> 42460 | E3: ='Data Sheet'!D16 -> 42825 | F3: ='Data Sheet'!E16 -> 43190 | G3: ='Data Sheet'!F16 -> 43555 | H3: ='Data Sheet'!G16 -> 43921 | I3: ='Data Sheet'!H16 -> 44286 | J3: ='Data Sheet'!I16 -> 44651 | ... L3: ='Data Sheet'!K16 -> 45382 | M3: LTM
A5: # | B5: Income Statement
B6: ='Data Sheet'!A17 -> Sales | C6: ='Data Sheet'!B17 -> 52971.51 | D6: ='Data Sheet'!C17 -> 41546.17 | E6: ='Data Sheet'!D17 -> 55604 | F6: ='Data Sheet'!E17 -> 71933 | G6: ='Data Sheet'!F17 -> 84757 | H6: ='Data Sheet'!G17 -> 73326 | I6: ='Data Sheet'!H17 -> 79839 | ... L6: ='Data Sheet'!K17 -> 175006 | M6: =SUM('Data Sheet'!H42:K42) -> 170274
B7: (Sales Growth) | D7: =D6/C6-1 -> -0.2156884 | E7: =E6/D6-1 -> 0.33836645 | F7: =F6/E6-1 -> 0.29366592 | G7: =G6/F6-1 -> 0.17827701 | H7: =H6/G6-1 -> -0.13486792 | I7: =I6/H6-1 -> 0.088822519 | J7: =J6/I6-1 -> 0.83332707 | K7: =K6/J6-1 -> 0.13383116 | L7: =L6/K6-1 -> 0.05450711
B9: COGS | C9: =IFERROR(SUM('Data Sheet'!B18,'Data Sheet'!B20:B22)*1-'Data Sheet'!B19,0) -> 42072.92 | D9: =IFERROR(SUM('Data Sheet'!C18,'Data Sheet'!C20:C22)*1-'Data Sheet'!C19,0) -> 33468.38 | E9: =IFERROR(SUM('Data Sheet'!D18,'Data Sheet'!D20:D22)*1-'Data Sheet'!D19,0) -> 41733 | F9: =IFERROR(SUM('Data Sheet'!E18,'Data Sheet'!E20:E22)*1-'Data Sheet'!E19,0) -> 55278 | G9: =IFERROR(SUM('Data Sheet'!F18,'Data Sheet'!F20:F22)*1-'Data Sheet'!F19,0) -> 62906 | H9: =IFERROR(SUM('Data Sheet'!G18,'Data Sheet'!G20:G22)*1-'Data Sheet'!G19,0) -> 58084 | I9: =IFERROR(SUM('Data Sheet'!H18,'Data Sheet'!H20:H22)*1-'Data Sheet'!H19,0) -> 57246 | J9: =IFERROR(SUM('Data Sheet'!I18,'Data Sheet'!I20:I22)*1-'Data Sheet'!I19,0) -> 103778 | ... L9: =IFERROR(SUM('Data Sheet'!K18,'Data Sheet'!K20:K22)*1-'Data Sheet'!K19,0) -> 141101 | M9: =SUM('Data Sheet'!H43:K43) -> 147796
B10: (COGS% OF SALES) | C10: =C9/C6 -> 0.79425563 | D10: =D9/D6 -> 0.80557077 | E10: =E9/E6 -> 0.75053953 | F10: =F9/F6 -> 0.7684651 | G10: =G9/G6 -> 0.74219239 | H10: =H9/H6 -> 0.79213376 | I10: =I9/I6 -> 0.717018 | J10: =J9/J6 -> 0.70900657 | ... L10: =L9/L6 -> 0.80626379
B12: Gross Profit | C12: =C6-C9 -> 10898.59 | D12: =D6-D9 -> 8077.79 | E12: =E6-E9 -> 13871 | F12: =F6-F9 -> 16655 | G12: =G6-G9 -> 21851 | H12: =H6-H9 -> 15242 | I12: =I6-I9 -> 22593 | J12: =J6-J9 -> 42593 | ... M12: =M6-M9 -> 22478
B13: (Gross Margin) | C13: =C12/C6 -> 0.20574437 | D13: =D12/D6 -> 0.19442923 | E13: =E12/E6 -> 0.24946047 | F13: =F12/F6 -> 0.2315349 | G13: =G12/G6 -> 0.25780761 | H13: =H12/H6 -> 0.20786624 | I13: =I12/I6 -> 0.282982 | J13: =J12/J6 -> 0.29099343 | ... L13: =L12/L6 -> 0.19373621
B15: Selling & General Expense | C15: =IFERROR(SUM('Data Sheet'!B23:B24),0) -> 1534.73 | D15: =IFERROR(SUM('Data Sheet'!C23:C24),0) -> 1655.48 | E15: =IFERROR(SUM('Data Sheet'!D23:D24),0) -> 1563 | F15: =IFERROR(SUM('Data Sheet'!E23:E24),0) -> 1739 | G15: =IFERROR(SUM('Data Sheet'!F23:F24),0) -> 2921 | H15: =IFERROR(SUM('Data Sheet'!G23:G24),0) -> 3429 | I15: =IFERROR(SUM('Data Sheet'!H23:H24),0) -> 2415 | J15: =IFERROR(SUM('Data Sheet'!I23:I24),0) -> 3479 | ... L15: =IFERROR(SUM('Data Sheet'!K23:K24),0) -> 5748 | M15: 0
B16: S&G Exp % of Sales | C16: =C15/C6 -> 0.028972744 | D16: =D15/D6 -> 0.039846754 | E16: =E15/E6 -> 0.028109489 | F16: =F15/F6 -> 0.024175274 | G16: =G15/G6 -> 0.03446323 | H16: =H15/H6 -> 0.046763767 | I16: =I15/I6 -> 0.030248375 | J16: =J15/J6 -> 0.023768369 | ... L16: =L15/L6 -> 0.032844588
B17: Operating Profit(EBITDA) | C17: =C12-C15 -> 9363.86 | D17: =D12-D15 -> 6422.31 | E17: =E12-E15 -> 12308 | F17: =F12-F15 -> 14916 | G17: =G12-G15 -> 18930 | H17: =H12-H15 -> 11813 | I17: =I12-I15 -> 20178 | J17: =J12-J15 -> 39114 | ... M17: =M12-M15 -> 22478
B18: Ebitda Margin | C18: =C17/C6 -> 0.17677163 | D18: =D17/D6 -> 0.15458248 | E18: =E17/E6 -> 0.22135098 | F18: =F17/F6 -> 0.20735963 | G18: =G17/G6 -> 0.22334438 | H18: =H17/H6 -> 0.16110247 | I18: =I17/I6 -> 0.25273363 | J18: =J17/J6 -> 0.26722507 | ... L18: =L17/L6 -> 0.16089163
B19: Intrest | C19: ='Data Sheet'!B27 -> 3493.03 | D19: ='Data Sheet'!C27 -> 3601.18 | E19: ='Data Sheet'!D27 -> 3768 | F19: ='Data Sheet'!E27 -> 3701 | G19: ='Data Sheet'!F27 -> 3917 | H19: ='Data Sheet'!G27 -> 4265 | I19: ='Data Sheet'!H27 -> 3957 | J19: ='Data Sheet'!I27 -> 4968 | ... L19: ='Data Sheet'!K27 -> 8105 | M19: =SUM('Data Sheet'!H46:K46) -> 8380
B20: Intrest% of Sales | C20: =C19/C6 -> 0.065941673 | D20: =D19/D6 -> 0.086678989 | E20: =E19/E6 -> 0.067764909 | F20: =F19/F6 -> 0.051450655 | G20: =G19/G6 -> 0.046214472 | H20: =H19/H6 -> 0.058164907 | I20: =I19/I6 -> 0.049562244 | J20: =J19/J6 -> 0.03394115 | ... L20: =L19/L6 -> 0.046312698
B21: ='Data Sheet'!A26 -> Depreciation | C21: ='Data Sheet'!B26 -> 3434.49 | D21: ='Data Sheet'!C26 -> 3322.56 | E21: ='Data Sheet'!D26 -> 3430 | F21: ='Data Sheet'!E26 -> 3387 | G21: ='Data Sheet'!F26 -> 4041 | H21: ='Data Sheet'!G26 -> 4246 | I21: ='Data Sheet'!H26 -> 4679 | ... L21: ='Data Sheet'!K26 -> 8172 | M21: =SUM('Data Sheet'!H45:K45) -> 9006
B22: Dep % of Sales | C22: =C21/C6 -> 0.064836551 | D22: =D21/D6 -> 0.079972715 | E22: =E21/E6 -> 0.06168621 | F22: =F21/F6 -> 0.047085482 | G22: =G21/G6 -> 0.047677478 | H22: =H21/H6 -> 0.057905791 | I22: =I21/I6 -> 0.058605443 | J22: =J21/J6 -> 0.040998558 | ... L22: =L21/L6 -> 0.046695542
B23: Earning Befor Tax | C23: =C17-SUM(C19,C21) -> 2436.34 | D23: =D17-SUM(D19,D21) -> -501.43 | E23: =E17-SUM(E19,E21) -> 5110 | F23: =F17-SUM(F19,F21) -> 7828 | G23: =G17-SUM(G19,G21) -> 10972 | H23: =H17-SUM(H19,H21) -> 3302 | I23: =I17-SUM(I19,I21) -> 11542 | J23: =J17-SUM(J19,J21) -> 28145 | ... L23: =L17-SUM(L19,L21) -> 11880 | M23: =M17-SUM(M19:M21) -> 5092
B24: EBT Margin | C24: =C23/C6 -> 0.045993403 | D24: =D23/D6 -> -0.012069223 | E24: =E23/E6 -> 0.091899863 | F24: =F23/F6 -> 0.10882349 | G24: =G23/G6 -> 0.12945243 | H24: =H23/H6 -> 0.045031776 | I24: =I23/I6 -> 0.14456594 | J24: =J23/J6 -> 0.19228536 | ... L24: =L23/L6 -> 0.067883387
B25: Tax | C25: ='Data Sheet'!B29 -> 819.41 | D25: ='Data Sheet'!C29 -> -1966.21 | E25: ='Data Sheet'!D29 -> 1674 | F25: ='Data Sheet'!E29 -> 1538 | G25: ='Data Sheet'!F29 -> 3644 | H25: ='Data Sheet'!G29 -> -906 | I25: ='Data Sheet'!H29 -> 4142 | J25: ='Data Sheet'!I29 -> 8807 | ... L25: ='Data Sheet'!K29 -> 4407 | M25: =SUM('Data Sheet'!H48:K48) -> 2047
B26: Effective Tax Rate | C26: =C25/C23 -> 0.33632826 | D26: =D25/D23 -> 3.9212054 | E26: =E25/E23 -> 0.32759295 | F26: =F25/F23 -> 0.1964742 | G26: =G25/G23 -> 0.33211812 | H26: =H25/H23 -> -0.27437916 | I26: =I25/I23 -> 0.35886328 | J26: =J25/J23 -> 0.31291526 | ... L26: =L25/L23 -> 0.3709596
B27: Net Profit | C27: =C23-C25 -> 1616.93 | D27: =D23-D25 -> 1464.78 | E27: =E23-E25 -> 3436 | F27: =F23-F25 -> 6290 | G27: =G23-G25 -> 7328 | H27: =H23-H25 -> 4208 | I27: =I23-I25 -> 7400 | J27: =J23-J25 -> 19338 | ... M27: =M23-M25 -> 3045
B28: Net Profit Margin | C28: =C27/C6 -> 0.030524522 | D28: =D27/D6 -> 0.035256679 | E28: =E27/E6 -> 0.061794116 | F28: =F27/F6 -> 0.087442481 | G28: =G27/G6 -> 0.086458936 | H28: =H27/H6 -> 0.057387557 | I28: =I27/I6 -> 0.092686532 | J28: =J27/J6 -> 0.13211633 | ... L28: =L27/L6 -> 0.042701393
B29: No Of Equity Shares | C29: ='Data Sheet'!B93 -> 241.72 | D29: ='Data Sheet'!C93 -> 241.72 | E29: ='Data Sheet'!D93 -> 241.72 | F29: ='Data Sheet'!E93 -> 241.72 | G29: ='Data Sheet'!F93 -> 241.72 | H29: ='Data Sheet'!G93 -> 241.72 | I29: ='Data Sheet'!H93 -> 241.72 | J29: ='Data Sheet'!I93 -> 241.72 | ... L29: ='Data Sheet'!K93 -> 244.55 | M29: =L29 -> 244.55
B31: EPS | C31: =C27/C29 -> 6.6892686 | D31: =D27/D29 -> 6.0598213 | E31: =E27/E29 -> 14.214794 | F31: =F27/F29 -> 26.021843 | G31: =G27/G29 -> 30.316068 | H31: =H27/H29 -> 17.408572 | I31: =I27/I29 -> 30.613933 | J31: =J27/J29 -> 80.001655 | ... M31: =M27/M29 -> 12.451441
B32: Earning Per Growth | D32: =D31/C31 -> 0.90590193 | E32: =E31/D31 -> 2.3457448 | F32: =F31/E31 -> 1.830617 | G32: =G31/F31 -> 1.1650238 | H32: =H31/G31 -> 0.57423581 | I32: =I31/H31 -> 1.7585551 | J32: =J31/I31 -> 2.6132432 | K32: =K31/J31 -> 0.13331265 | ... M32: =M31/L31 -> 0.40746688
B33: Divident Per Share | C33: ='Data Sheet'!B31/'Historical FS'!C29 -> 1.3777097 | D33: ='Data Sheet'!C31/'Historical FS'!D29 -> 0.93364223 | E33: ='Data Sheet'!D31/'Historical FS'!E29 -> 2.8017955 | F33: ='Data Sheet'!E31/'Historical FS'!F29 -> 3.9980142 | G33: ='Data Sheet'!F31/'Historical FS'!G29 -> 5.105494 | H33: ='Data Sheet'!G31/'Historical FS'!H29 -> 2.4904849 | I33: ='Data Sheet'!H31/'Historical FS'!I29 -> 8.1209664 | J33: ='Data Sheet'!I31/'Historical FS'!J29 -> 21.604956 | ... L33: ='Data Sheet'!K31/'Historical FS'!L29 -> 9.1044776 | M33: 0
B34: Deivident Payout | C34: =C33/C31 -> 0.2059582 | D34: =D33/D31 -> 0.15407092 | E34: =E33/E31 -> 0.19710419 | F34: =F33/F31 -> 0.1536407 | G34: =G33/G31 -> 0.16840884 | H34: =H33/H31 -> 0.14306084 | I34: =I33/I31 -> 0.26527027 | J34: =J33/J31 -> 0.27005637 | ... M34: =M33/M31 -> 0
B35: Retained Earning | C35: =C31-C33 -> 5.3115588 | D35: =D31-D33 -> 5.1261791 | E35: =E31-E33 -> 11.412999 | F35: =F31-F33 -> 22.023829 | G35: =G31-G33 -> 25.210574 | H35: =H31-H33 -> 14.918087 | I35: =I31-I33 -> 22.492967 | J35: =J31-J33 -> 58.396699 | ... M35: =M31-M33 -> 12.451441
A37: # | B37: Balance Sheet
B39: ='Data Sheet'!A57 -> Equity Share Capital | C39: ='Data Sheet'!B57 -> 302.75 | D39: ='Data Sheet'!C57 -> 300.9 | E39: ='Data Sheet'!D57 -> 301 | F39: ='Data Sheet'!E57 -> 302 | G39: ='Data Sheet'!F57 -> 301 | H39: ='Data Sheet'!G57 -> 301 | I39: ='Data Sheet'!H57 -> 302 | ... L39: ='Data Sheet'!K57 -> 305
B40: ='Data Sheet'!A58 -> Reserves | C40: ='Data Sheet'!B58 -> 21986.89 | D40: ='Data Sheet'!C58 -> 18664.55 | E40: ='Data Sheet'!D58 -> 22346 | F40: ='Data Sheet'!E58 -> 27696 | G40: ='Data Sheet'!F58 -> 34494 | H40: ='Data Sheet'!G58 -> 36298 | I40: ='Data Sheet'!H58 -> 46462 | ... L40: ='Data Sheet'!K58 -> 77364
B41: ='Data Sheet'!A59 -> Borrowings | C41: ='Data Sheet'!B59 -> 38754.26 | D41: ='Data Sheet'!C59 -> 42204.03 | E41: ='Data Sheet'!D59 -> 43334 | F41: ='Data Sheet'!E59 -> 39393 | G41: ='Data Sheet'!F59 -> 47396 | H41: ='Data Sheet'!G59 -> 61423 | I41: ='Data Sheet'!H59 -> 62392 | ... L41: ='Data Sheet'!K59 -> 87984
B42: ='Data Sheet'!A60 -> Other Liabilities | C42: ='Data Sheet'!B60 -> 24609.98 | D42: ='Data Sheet'!C60 -> 20737.42 | E42: ='Data Sheet'!D60 -> 22024 | F42: ='Data Sheet'!E60 -> 24579 | G42: ='Data Sheet'!F60 -> 32606 | H42: ='Data Sheet'!G60 -> 33798 | I42: ='Data Sheet'!H60 -> 39161 | ... L42: ='Data Sheet'!K60 -> 62245
B43: Total Liabilites | C43: =SUM(C39:C42) -> 85653.88 | D43: =SUM(D39:D42) -> 81906.9 | E43: =SUM(E39:E42) -> 88005 | F43: =SUM(F39:F42) -> 91970 | G43: =SUM(G39:G42) -> 114797 | H43: =SUM(H39:H42) -> 131820 | I43: =SUM(I39:I42) -> 148317 | J43: =SUM(J39:J42) -> 196485 | ... L43: =SUM(L39:L42) -> 227898
B45: Fixed Asset Net Block | C45: ='Data Sheet'!B62 -> 52176.28 | D45: ='Data Sheet'!C62 -> 56139.52 | E45: ='Data Sheet'!D62 -> 58730 | F45: ='Data Sheet'!E62 -> 57848 | G45: ='Data Sheet'!F62 -> 62644 | H45: ='Data Sheet'!G62 -> 62085 | I45: ='Data Sheet'!H62 -> 64917 | J45: ='Data Sheet'!I62 -> 99880 | ... L45: ='Data Sheet'!K62 -> 112461
B46: ='Data Sheet'!A63 -> Capital Work in Progress | C46: ='Data Sheet'!B63 -> 8265.27 | D46: ='Data Sheet'!C63 -> 7270.85 | E46: ='Data Sheet'!D63 -> 4363 | F46: ='Data Sheet'!E63 -> 5950 | G46: ='Data Sheet'!F63 -> 11889 | H46: ='Data Sheet'!G63 -> 27191 | I46: ='Data Sheet'!H63 -> 32566 | ... L46: ='Data Sheet'!K63 -> 29676
B47: ='Data Sheet'!A64 -> Investments | C47: ='Data Sheet'!B64 -> 599.25 | D47: ='Data Sheet'!C64 -> 1194.61 | E47: ='Data Sheet'!D64 -> 1366 | F47: ='Data Sheet'!E64 -> 1469 | G47: ='Data Sheet'!F64 -> 1894 | H47: ='Data Sheet'!G64 -> 1259 | I47: ='Data Sheet'!H64 -> 8581 | ... L47: ='Data Sheet'!K64 -> 7246
B48: ='Data Sheet'!A65 -> Other Assets | C48: ='Data Sheet'!B74 -> 9191.04 | D48: ='Data Sheet'!C74 -> 5232.97 | E48: ='Data Sheet'!D74 -> 6517 | F48: ='Data Sheet'!E74 -> 8342 | G48: ='Data Sheet'!F74 -> 10475 | H48: ='Data Sheet'!G74 -> 11004 | I48: ='Data Sheet'!H74 -> 10705 | J48: ='Data Sheet'!I74 -> 16133 | ... L48: ='Data Sheet'!K74 -> 20804
B49: Total Non Current Asset | C49: =SUM(C45:C48) -> 70231.84 | D49: =SUM(D45:D48) -> 69837.95 | E49: =SUM(E45:E48) -> 70976 | F49: =SUM(F45:F48) -> 73609 | G49: =SUM(G45:G48) -> 86902 | H49: =SUM(H45:H48) -> 101539 | I49: =SUM(I45:I48) -> 116769 | J49: =SUM(J45:J48) -> 137858 | ... L49: =SUM(L45:L48) -> 170187
...

Sheet Ratio Analysis
B2: ="Ratio Analysis-"&'Data Sheet'!B1 -> Ratio Analysis-JSW STEEL LTD
B3: Years | C3: ='Data Sheet'!B16 -> 42094 | D3: ='Data Sheet'!C16 -> 42460 | E3: ='Data Sheet'!D16 -> 42825 | F3: ='Data Sheet'!E16 -> 43190 | G3: ='Data Sheet'!F16 -> 43555 | H3: ='Data Sheet'!G16 -> 43921 | I3: ='Data Sheet'!H16 -> 44286 | J3: ='Data Sheet'!I16 -> 44651 | ... L3: ='Data Sheet'!K16 -> 45382 | M3: Trend | N3: Mean | O3: Median
B5: Sales Growth | D5: ='Historical FS'!D7 -> -0.2156884 | E5: ='Historical FS'!E7 -> 0.33836645 | F5: ='Historical FS'!F7 -> 0.29366592 | G5: ='Historical FS'!G7 -> 0.17827701 | H5: ='Historical FS'!H7 -> -0.13486792 | I5: ='Historical FS'!I7 -> 0.088822519 | J5: ='Historical FS'!J7 -> 0.83332707 | K5: ='Historical FS'!K7 -> 0.13383116 | L5: ='Historical FS'!L7 -> 0.05450711 | N5: =AVERAGE(D5:L5) -> 0.17447121 | O5: =MEDIAN(D5:L5) -> 0.13383116
B6: EBITDA Growth | D6: ='Historical FS'!D17/'Historical FS'!C17-1 -> -0.31413861 | E6: ='Historical FS'!E17/'Historical FS'!D17-1 -> 0.91644439 | F6: ='Historical FS'!F17/'Historical FS'!E17-1 -> 0.2118947 | G6: ='Historical FS'!G17/'Historical FS'!F17-1 -> 0.269107 | H6: ='Historical FS'!H17/'Historical FS'!G17-1 -> -0.37596408 | I6: ='Historical FS'!I17/'Historical FS'!H17-1 -> 0.70811817 | J6: ='Historical FS'!J17/'Historical FS'!I17-1 -> 0.93844781 | K6: ='Historical FS'!K17/'Historical FS'!J17-1 -> -0.52779056 | L6: ='Historical FS'!L17/'Historical FS'!K17-1 -> 0.52447212 | N6: =AVERAGE(D6:L6) -> 0.26117677 | O6: =MEDIAN(D6:L6) -> 0.269107
B7: EBIT Growth | D7: ='Historical FS'!D23/'Historical FS'!C23-1 -> -1.2058128 | E7: ='Historical FS'!E23/'Historical FS'!D23-1 -> -11.190854 | F7: ='Historical FS'!F23/'Historical FS'!E23-1 -> 0.53189824 | G7: ='Historical FS'!G23/'Historical FS'!F23-1 -> 0.40163516 | H7: ='Historical FS'!H23/'Historical FS'!G23-1 -> -0.69905213 | I7: ='Historical FS'!I23/'Historical FS'!H23-1 -> 2.4954573 | J7: ='Historical FS'!J23/'Historical FS'!I23-1 -> 1.4384855 | K7: ='Historical FS'!K23/'Historical FS'!J23-1 -> -0.85453899 | L7: ='Historical FS'!L23/'Historical FS'!K23-1 -> 1.9018075 | N7: =AVERAGE(D7:L7) -> -0.79788604 | O7: =MEDIAN(D7:L7) -> 0.40163516
B8: Net Profit Growth | D8: ='Historical FS'!D27/'Historical FS'!C27-1 -> -0.094098075 | E8: ='Historical FS'!E27/'Historical FS'!D27-1 -> 1.3457448 | F8: ='Historical FS'!F27/'Historical FS'!E27-1 -> 0.830617 | G8: ='Historical FS'!G27/'Historical FS'!F27-1 -> 0.16502385 | H8: ='Historical FS'!H27/'Historical FS'!G27-1 -> -0.42576419 | I8: ='Historical FS'!I27/'Historical FS'!H27-1 -> 0.75855513 | J8: ='Historical FS'!J27/'Historical FS'!I27-1 -> 1.6132432 | K8: ='Historical FS'!K27/'Historical FS'!J27-1 -> -0.86668735 | L8: ='Historical FS'!L27/'Historical FS'!K27-1 -> 1.8987587 | N8: =AVERAGE(D8:L8) -> 0.58059923 | O8: =MEDIAN(D8:L8) -> 0.75855513
B9: Dividentv Growth | D9: ='Historical FS'!D33/'Historical FS'!C33-1 -> -0.32232298 | E9: ='Historical FS'!E33/'Historical FS'!D33-1 -> 2.0009305 | F9: ='Historical FS'!F33/'Historical FS'!E33-1 -> 0.42694721 | G9: ='Historical FS'!G33/'Historical FS'!F33-1 -> 0.27700745 | H9: ='Historical FS'!H33/'Historical FS'!G33-1 -> -0.51219512 | I9: ='Historical FS'!I33/'Historical FS'!H33-1 -> 2.2607973 | J9: ='Historical FS'!J33/'Historical FS'!I33-1 -> 1.6603923 | K9: ='Historical FS'!K33/'Historical FS'!J33-1 -> -0.80403458 | L9: ='Historical FS'!L33/'Historical FS'!K33-1 -> 1.1504146 | N9: =AVERAGE(D9:L9) -> 0.68199297 | O9: =MEDIAN(D9:L9) -> 0.42694721
B11: Gross Margin | C11: ='Historical FS'!C13 -> 0.20574437 | D11: ='Historical FS'!D13 -> 0.19442923 | E11: ='Historical FS'!E13 -> 0.24946047 | F11: ='Historical FS'!F13 -> 0.2315349 | G11: ='Historical FS'!G13 -> 0.25780761 | H11: ='Historical FS'!H13 -> 0.20786624 | I11: ='Historical FS'!I13 -> 0.282982 | J11: ='Historical FS'!J13 -> 0.29099343 | ... L11: ='Historical FS'!L13 -> 0.19373621 | N11: =AVERAGE(D11:L11) -> 0.22885108 | O11: =MEDIAN(D11:L11) -> 0.2315349
B12: EBITDA Margin | C12: ='Historical FS'!C18 -> 0.17677163 | D12: ='Historical FS'!D18 -> 0.15458248 | E12: ='Historical FS'!E18 -> 0.22135098 | F12: ='Historical FS'!F18 -> 0.20735963 | G12: ='Historical FS'!G18 -> 0.22334438 | H12: ='Historical FS'!H18 -> 0.16110247 | I12: ='Historical FS'!I18 -> 0.25273363 | J12: ='Historical FS'!J18 -> 0.26722507 | ... L12: ='Historical FS'!L18 -> 0.16089163 | N12: =AVERAGE(D12:L12) -> 0.19554246 | O12: =MEDIAN(D12:L12) -> 0.20735963
B13: EBIT Margin | C13: ='Data Sheet'!B35 -> 0.11193508 | D13: ='Data Sheet'!C35 -> 0.074609765 | E13: ='Data Sheet'!D35 -> 0.15966477 | F13: ='Data Sheet'!E35 -> 0.16027414 | G13: ='Data Sheet'!F35 -> 0.17566691 | H13: ='Data Sheet'!G35 -> 0.10319668 | I13: ='Data Sheet'!H35 -> 0.19412818 | J13: ='Data Sheet'!I35 -> 0.22622651 | ... L13: ='Data Sheet'!K35 -> 0.11419608 | N13: =AVERAGE(D13:L13) -> 0.14158 | O13: =MEDIAN(D13:L13) -> 0.15966477
B14: EBT Margin | C14: ='Historical FS'!C24 -> 0.045993403 | D14: ='Historical FS'!D24 -> -0.012069223 | E14: ='Historical FS'!E24 -> 0.091899863 | F14: ='Historical FS'!F24 -> 0.10882349 | G14: ='Historical FS'!G24 -> 0.12945243 | H14: ='Historical FS'!H24 -> 0.045031776 | I14: ='Historical FS'!I24 -> 0.14456594 | J14: ='Historical FS'!J24 -> 0.19228536 | ... L14: ='Historical FS'!L24 -> 0.067883387 | N14: =AVERAGE(D14:L14) -> 0.08806018 | O14: =MEDIAN(D14:L14) -> 0.091899863
B15: Net Profit Margin | C15: ='Historical FS'!C28 -> 0.030524522 | D15: ='Historical FS'!D28 -> 0.035256679 | E15: ='Historical FS'!E28 -> 0.061794116 | F15: ='Historical FS'!F28 -> 0.087442481 | G15: ='Historical FS'!G28 -> 0.086458936 | H15: ='Historical FS'!H28 -> 0.057387557 | I15: ='Historical FS'!I28 -> 0.092686532 | J15: ='Historical FS'!J28 -> 0.13211633 | ... L15: ='Historical FS'!L28 -> 0.042701393 | N15: =AVERAGE(D15:L15) -> 0.067930877 | O15: =MEDIAN(D15:L15) -> 0.061794116
B17: Sales Expense % of Sales | C17: ='Historical FS'!C16 -> 0.028972744 | D17: ='Historical FS'!D16 -> 0.039846754 | E17: ='Historical FS'!E16 -> 0.028109489 | F17: ='Historical FS'!F16 -> 0.024175274 | G17: ='Historical FS'!G16 -> 0.03446323 | H17: ='Historical FS'!H16 -> 0.046763767 | I17: ='Historical FS'!I16 -> 0.030248375 | J17: ='Historical FS'!J16 -> 0.023768369 | ... L17: ='Historical FS'!L16 -> 0.032844588 | N17: =AVERAGE(D17:L17) -> 0.033308619 | O17: =MEDIAN(D17:L17) -> 0.032844588
B18: Depriciaton% of Sales | C18: ='Historical FS'!C22 -> 0.064836551 | D18: ='Historical FS'!D22 -> 0.079972715 | E18: ='Historical FS'!E22 -> 0.06168621 | F18: ='Historical FS'!F22 -> 0.047085482 | G18: ='Historical FS'!G22 -> 0.047677478 | H18: ='Historical FS'!H22 -> 0.057905791 | I18: ='Historical FS'!I22 -> 0.058605443 | J18: ='Historical FS'!J22 -> 0.040998558 | ... L18: ='Historical FS'!L22 -> 0.046695542 | N18: =AVERAGE(D18:L18) -> 0.053962463 | O18: =MEDIAN(D18:L18) -> 0.047677478
B20: Return on Capital Employed% | C20: =('Historical FS'!C23+'Historical FS'!C19)/SUM('Historical FS'!C39,'Historical FS'!C40,'Historical FS'!C41) -> 0.097132883 | D20: =('Historical FS'!D23+'Historical FS'!D19)/SUM('Historical FS'!D39,'Historical FS'!D40,'Historical FS'!D41) -> 0.050674781 | E20: =('Historical FS'!E23+'Historical FS'!E19)/SUM('Historical FS'!E39,'Historical FS'!E40,'Historical FS'!E41) -> 0.13455389 | F20: =('Historical FS'!F23+'Historical FS'!F19)/SUM('Historical FS'!F39,'Historical FS'!F40,'Historical FS'!F41) -> 0.17107626 | G20: =('Historical FS'!G23+'Historical FS'!G19)/SUM('Historical FS'!G39,'Historical FS'!G40,'Historical FS'!G41) -> 0.18115122 | H20: =('Historical FS'!H23+'Historical FS'!H19)/SUM('Historical FS'!H39,'Historical FS'!H40,'Historical FS'!H41) -> 0.077196956 | I20: =('Historical FS'!I23+'Historical FS'!I19)/SUM('Historical FS'!I39,'Historical FS'!I40,'Historical FS'!I41) -> 0.14198945 | J20: =('Historical FS'!J23+'Historical FS'!J19)/SUM('Historical FS'!J39,'Historical FS'!J40,'Historical FS'!J41) -> 0.23731134 | ... L20: =('Historical FS'!L23+'Historical FS'!L19)/SUM('Historical FS'!L39,'Historical FS'!L40,'Historical FS'!L41) -> 0.12064376 | N20: =AVERAGE(D20:L20) -> 0.13218123 | O20: =MEDIAN(D20:L20) -> 0.13455389
B21: Return on Equity% | C21: ='Historical FS'!C27/SUM('Historical FS'!C39:C40) -> 0.072541773 | D21: ='Historical FS'!D27/SUM('Historical FS'!D39:D40) -> 0.077234128 | E21: ='Historical FS'!E27/SUM('Historical FS'!E39:E40) -> 0.15171987 | F21: ='Historical FS'!F27/SUM('Historical FS'!F39:F40) -> 0.2246589 | G21: ='Historical FS'!G27/SUM('Historical FS'!G39:G40) -> 0.21060497 | H21: ='Historical FS'!H27/SUM('Historical FS'!H39:H40) -> 0.11497582 | I21: ='Historical FS'!I27/SUM('Historical FS'!I39:I40) -> 0.15824138 | J21: ='Historical FS'!J27/SUM('Historical FS'!J39:J40) -> 0.28735308 | ... L21: ='Historical FS'!L27/SUM('Historical FS'!L39:L40) -> 0.096215994 | N21: =AVERAGE(D21:L21) -> 0.15113846 | O21: =MEDIAN(D21:L21) -> 0.15171987
B22: Reatined Earning% | C22: ='Historical FS'!C35 -> 5.3115588 | D22: ='Historical FS'!D35 -> 5.1261791 | E22: ='Historical FS'!E35 -> 11.412999 | F22: ='Historical FS'!F35 -> 22.023829 | G22: ='Historical FS'!G35 -> 25.210574 | H22: ='Historical FS'!H35 -> 14.918087 | I22: ='Historical FS'!I35 -> 22.492967 | J22: ='Historical FS'!J35 -> 58.396699 | ... L22: ='Historical FS'!L35 -> 21.45369 | N22: =AVERAGE(D22:L22) -> 20.829604 | O22: =MEDIAN(D22:L22) -> 21.45369
B23: Self Sustained Growth | C23: =C21*C22 -> 0.38530989 | D23: =D21*D22 -> 0.39591597 | E23: =E21*E22 -> 1.7315787 | F23: =F21*F22 -> 4.9478493 | G23: =G21*G22 -> 5.3094723 | H23: =H21*H22 -> 1.7152193 | I23: =I21*I22 -> 3.5593182 | J23: =J21*J22 -> 16.780471 | ... L23: =L21*L22 -> 2.0641881 | N23: =AVERAGE(D23:L23) -> 4.0840438 | O23: =MEDIAN(D23:L23) -> 2.0641881
B24: Intrest Coverage Ratio | C24: =SUM('Historical FS'!C23,'Historical FS'!C19)/'Historical FS'!C19 -> 1.6974861 | D24: =SUM('Historical FS'!D23,'Historical FS'!D19)/'Historical FS'!D19 -> 0.86075953 | E24: =SUM('Historical FS'!E23,'Historical FS'!E19)/'Historical FS'!E19 -> 2.3561571 | F24: =SUM('Historical FS'!F23,'Historical FS'!F19)/'Historical FS'!F19 -> 3.115104 | G24: =SUM('Historical FS'!G23,'Historical FS'!G19)/'Historical FS'!G19 -> 3.8011233 | H24: =SUM('Historical FS'!H23,'Historical FS'!H19)/'Historical FS'!H19 -> 1.7742087 | I24: =SUM('Historical FS'!I23,'Historical FS'!I19)/'Historical FS'!I19 -> 3.9168562 | J24: =SUM('Historical FS'!J23,'Historical FS'!J19)/'Historical FS'!J19 -> 6.6652576 | ... L24: =SUM('Historical FS'!L23,'Historical FS'!L19)/'Historical FS'!L19 -> 2.4657619 | N24: =AVERAGE(D24:L24) -> 2.9498211 | O24: =MEDIAN(D24:L24) -> 2.4657619
B26: Debtor Turnover Ratio | C26: ='Historical FS'!C6/'Historical FS'!C51 -> 21.190723 | D26: ='Historical FS'!D6/'Historical FS'!D51 -> 15.233052 | E26: ='Historical FS'!E6/'Historical FS'!E51 -> 13.401784 | F26: ='Historical FS'!F6/'Historical FS'!F51 -> 15.291879 | G26: ='Historical FS'!G6/'Historical FS'!G51 -> 11.83757 | H26: ='Historical FS'!H6/'Historical FS'!H51 -> 16.276582 | I26: ='Historical FS'!I6/'Historical FS'!I51 -> 17.79737 | J26: ='Historical FS'!J6/'Historical FS'!J51 -> 19.628671 | ... L26: ='Historical FS'!L6/'Historical FS'!L51 -> 23.185745 | N26: =AVERAGE(D26:L26) -> 17.323989 | O26: =MEDIAN(D26:L26) -> 16.276582
B27: Creditor Turnover Ratio | C27: ='Historical FS'!C6/'Data Sheet'!C77 -> 3.7165165 | D27: ='Historical FS'!D6/'Data Sheet'!D77 -> 3.2564799 | E27: ='Historical FS'!E6/'Data Sheet'!E77 -> 4.1657177 | F27: ='Historical FS'!F6/'Data Sheet'!F77 -> 4.5116031 | G27: ='Historical FS'!G6/'Data Sheet'!G77 -> 5.2451884 | H27: ='Historical FS'!H6/'Data Sheet'!H77 -> 4.0923094 | I27: ='Historical FS'!I6/'Data Sheet'!I77 -> 5.2377485 | J27: ='Historical FS'!J6/'Data Sheet'!J77 -> 4.7386125 | ... L27: ='Historical FS'!L6/'Data Sheet'!L77 -> 5.2451971 | N27: =AVERAGE(D27:L27) -> 4.5374464 | O27: =MEDIAN(D27:L27) -> 4.5116031
B28: Inventory Turnover Ratio | C28: ='Historical FS'!C6/'Historical FS'!C52 -> 4.8116375 | D28: ='Historical FS'!D6/'Historical FS'!D52 -> 4.9928219 | E28: ='Historical FS'!E6/'Historical FS'!E52 -> 4.8796841 | F28: ='Historical FS'!F6/'Historical FS'!F52 -> 5.7116881 | G28: ='Historical FS'!G6/'Historical FS'!G52 -> 5.8260242 | H28: ='Historical FS'!H6/'Historical FS'!H52 -> 5.3238946 | I28: ='Historical FS'!I6/'Historical FS'!I52 -> 5.60313 | J28: ='Historical FS'!J6/'Historical FS'!J52 -> 4.3321692 | ... L28: ='Historical FS'!L6/'Historical FS'!L52 -> 4.6279519 | N28: =AVERAGE(D28:L28) -> 5.1451072 | O28: =MEDIAN(D28:L28) -> 5.0086012
B29: Fixed Asset Turnover Ratio | C29: ='Historical FS'!C6/'Historical FS'!C45 -> 1.0152412 | D29: ='Historical FS'!D6/'Historical FS'!D45 -> 0.74005211 | E29: ='Historical FS'!E6/'Historical FS'!E45 -> 0.94677337 | F29: ='Historical FS'!F6/'Historical FS'!F45 -> 1.2434829 | G29: ='Historical FS'!G6/'Historical FS'!G45 -> 1.3529947 | H29: ='Historical FS'!H6/'Historical FS'!H45 -> 1.1810582 | I29: ='Historical FS'!I6/'Historical FS'!I45 -> 1.2298627 | J29: ='Historical FS'!J6/'Historical FS'!J45 -> 1.4654686 | ... L29: ='Historical FS'!L6/'Historical FS'!L45 -> 1.5561484 | N29: =AVERAGE(D29:L29) -> 1.2560783 | O29: =MEDIAN(D29:L29) -> 1.2434829
B30: Capital Turnover Ratio | C30: ='Historical FS'!C6/SUM('Historical FS'!C39:C40) -> 2.3765081 | D30: ='Historical FS'!D6/SUM('Historical FS'!D39:D40) -> 2.190624 | E30: ='Historical FS'!E6/SUM('Historical FS'!E39:E40) -> 2.4552479 | F30: ='Historical FS'!F6/SUM('Historical FS'!F39:F40) -> 2.5692192 | G30: ='Historical FS'!G6/SUM('Historical FS'!G39:G40) -> 2.435896 | H30: ='Historical FS'!H6/SUM('Historical FS'!H39:H40) -> 2.0034974 | I30: ='Historical FS'!I6/SUM('Historical FS'!I39:I40) -> 1.7072748 | J30: ='Historical FS'!J6/SUM('Historical FS'!J39:J40) -> 2.1750004 | ... L30: ='Historical FS'!L6/SUM('Historical FS'!L39:L40) -> 2.2532284 | N30: =AVERAGE(D30:L30) -> 2.2573564 | O30: =MEDIAN(D30:L30) -> 2.2532284
B32: Debtor Days | C32: =365/C26 -> 17.224518 | D32: =365/D26 -> 23.961055 | E32: =365/E26 -> 27.235181 | F32: =365/F26 -> 23.868878 | G32: =365/G26 -> 30.834031 | H32: =365/H26 -> 22.424856 | I32: =365/I26 -> 20.508649 | J32: =365/J26 -> 18.595248 | ... L32: =365/L26 -> 15.742432 | N32: =AVERAGE(D32:L32) -> 22.095591 | O32: =MEDIAN(D32:L32) -> 22.424856
B33: Inventory days | C33: =365/C27 -> 98.210245 | D33: =365/D27 -> 112.08422 | E33: =365/E27 -> 87.619955 | F33: =365/F27 -> 80.902506 | G33: =365/G27 -> 69.587586 | H33: =365/H27 -> 89.191692 | I33: =365/I27 -> 69.686431 | J33: =365/J27 -> 77.026768 | ... L33: =365/L27 -> 69.587471 | N33: =AVERAGE(D33:L33) -> 82.189716 | O33: =MEDIAN(D33:L33) -> 80.902506
B34: Payabel Days | C34: =365/C28 -> 75.857751 | D34: =365/D28 -> 73.10495 | E34: =365/E28 -> 74.799924 | F34: =365/F28 -> 63.90405 | G34: =365/G28 -> 62.649929 | H34: =365/H28 -> 68.558833 | I34: =365/I28 -> 65.142161 | J34: =365/J28 -> 84.253404 | ... L34: =365/L28 -> 78.868582 | N34: =AVERAGE(D34:L34) -> 71.572941 | O34: =MEDIAN(D34:L34) -> 72.874638
B35: Cash Conversion Cycel | C35: =365/C29 -> 359.52047 | D35: =365/D29 -> 493.20851 | E35: =365/E29 -> 385.51993 | F35: =365/F29 -> 293.53037 | G35: =365/G29 -> 269.77194 | H35: =365/H29 -> 309.04488 | I35: =365/I29 -> 296.78108 | J35: =365/J29 -> 249.0671 | ... L35: =365/L29 -> 234.55347 | N35: =AVERAGE(D35:L35) -> 306.80013 | O35: =MEDIAN(D35:L35) -> 293.53037
B37: CFO/Sales | C37: ='Historical FS'!C71/'Historical FS'!C6 -> 0.14866482 | D37: ='Historical FS'!D71/'Historical FS'!D6 -> 0.16603215 | E37: ='Historical FS'!E71/'Historical FS'!E6 -> 0.1418603 | F37: ='Historical FS'!F71/'Historical FS'!F6 -> 0.1720907 | G37: ='Historical FS'!G71/'Historical FS'!G6 -> 0.17264651 | H37: ='Historical FS'!H71/'Historical FS'!H6 -> 0.17435834 | I37: ='Historical FS'!I71/'Historical FS'!I6 -> 0.23533611 | J37: ='Historical FS'!J71/'Historical FS'!J6 -> 0.17947544 | ... L37: ='Historical FS'!L71/'Historical FS'!L6 -> 0.069014777 | N37: =AVERAGE(D37:L37) -> 0.16126091 | O37: =MEDIAN(D37:L37) -> 0.1720907
B38: CFO/Total Asset | C38: ='Historical FS'!C71/'Historical FS'!C56 -> 0.091939793 | D38: ='Historical FS'!D71/'Historical FS'!D56 -> 0.084217569 | E38: ='Historical FS'!E71/'Historical FS'!E56 -> 0.089631271 | F38: ='Historical FS'!F71/'Historical FS'!F56 -> 0.13459824 | G38: ='Historical FS'!G71/'Historical FS'!G56 -> 0.12746849 | H38: ='Historical FS'!H71/'Historical FS'!H56 -> 0.096988317 | I38: ='Historical FS'!I71/'Historical FS'!I56 -> 0.12668136 | J38: ='Historical FS'!J71/'Historical FS'!J56 -> 0.13369977 | ... L38: ='Historical FS'!L71/'Historical FS'!L56 -> 0.052997394 | N38: =AVERAGE(D38:L38) -> 0.10634 | O38: =MEDIAN(D38:L38) -> 0.11077758
B39: CFO/Total Debt | C39: ='Historical FS'!C71/'Historical FS'!C41 -> 0.20320347 | D39: ='Historical FS'!D71/'Historical FS'!D41 -> 0.16344411 | E39: ='Historical FS'!E71/'Historical FS'!E41 -> 0.18202797 | F39: ='Historical FS'!F71/'Historical FS'!F41 -> 0.31424365 | G39: ='Historical FS'!G71/'Historical FS'!G41 -> 0.30873913 | H39: ='Historical FS'!H71/'Historical FS'!H41 -> 0.20814679 | I39: ='Historical FS'!I71/'Historical FS'!I41 -> 0.30114438 | J39: ='Historical FS'!J71/'Historical FS'!J41 -> 0.36366405 | ... L39: ='Historical FS'!L71/'Historical FS'!L41 -> 0.13727496 | N39: =AVERAGE(D39:L39) -> 0.2519052 | O39: =MEDIAN(D39:L39) -> 0.28846178

Sheet Common Size Statement
B2: ="Common Size Statement "&" "& " - "&'Data Sheet'!$B$1 -> Common Size Statement - JSW STEEL LTD
B4: Particular | C4: ='Historical FS'!C3 -> 42094 | D4: ='Historical FS'!D3 -> 42460 | E4: ='Historical FS'!E3 -> 42825 | F4: ='Historical FS'!F3 -> 43190 | G4: ='Historical FS'!G3 -> 43555 | H4: ='Historical FS'!H3 -> 43921 | I4: ='Historical FS'!I3 -> 44286 | J4: ='Historical FS'!J3 -> 44651 | ... L4: ='Historical FS'!L3 -> 45382
B5: ='Data Sheet'!A17 -> Sales | C5: ='Data Sheet'!B17/'Data Sheet'!B$17 -> 1 | D5: ='Data Sheet'!C17/'Data Sheet'!C$17 -> 1 | E5: ='Data Sheet'!D17/'Data Sheet'!D$17 -> 1 | F5: ='Data Sheet'!E17/'Data Sheet'!E$17 -> 1 | G5: ='Data Sheet'!F17/'Data Sheet'!F$17 -> 1 | H5: ='Data Sheet'!G17/'Data Sheet'!G$17 -> 1 | I5: ='Data Sheet'!H17/'Data Sheet'!H$17 -> 1 | J5: ='Data Sheet'!I17/'Data Sheet'!I$17 -> 1 | ... L5: ='Data Sheet'!K17/'Data Sheet'!K$17 -> 1
B6: ='Data Sheet'!A18 -> Raw Material Cost | C6: ='Data Sheet'!B18/'Data Sheet'!B$17 -> 0.5878711 | D6: ='Data Sheet'!C18/'Data Sheet'!C$17 -> 0.50981884 | E6: ='Data Sheet'!D18/'Data Sheet'!D$17 -> 0.53501547 | F6: ='Data Sheet'!E18/'Data Sheet'!E$17 -> 0.53912669 | G6: ='Data Sheet'!F18/'Data Sheet'!F$17 -> 0.51672428 | H6: ='Data Sheet'!G18/'Data Sheet'!G$17 -> 0.53187137 | I6: ='Data Sheet'!H18/'Data Sheet'!H$17 -> 0.4115282 | J6: ='Data Sheet'!I18/'Data Sheet'!I$17 -> 0.42953181 | ... L6: ='Data Sheet'!K18/'Data Sheet'!K$17 -> 0.54143287
B7: ='Data Sheet'!A19 -> Change in Inventory | C7: ='Data Sheet'!B19/'Data Sheet'!B$17 -> 0.028094536 | D7: ='Data Sheet'!C19/'Data Sheet'!C$17 -> -0.032873307 | E7: ='Data Sheet'!D19/'Data Sheet'!D$17 -> 0.026724696 | F7: ='Data Sheet'!E19/'Data Sheet'!E$17 -> -0.0033920454 | G7: ='Data Sheet'!F19/'Data Sheet'!F$17 -> 0.006961077 | H7: ='Data Sheet'!G19/'Data Sheet'!G$17 -> 0.0036821864 | I7: ='Data Sheet'!H19/'Data Sheet'!H$17 -> 0.004358772 | J7: ='Data Sheet'!I19/'Data Sheet'!I$17 -> 0.024601868 | ... L7: ='Data Sheet'!K19/'Data Sheet'!K$17 -> 0.017639395
B8: ='Data Sheet'!A20 -> Power and Fuel | C8: ='Data Sheet'!B20/'Data Sheet'!B$17 -> 0.07783618 | D8: ='Data Sheet'!C20/'Data Sheet'!C$17 -> 0.088043735 | E8: ='Data Sheet'!D20/'Data Sheet'!D$17 -> 0.087817423 | F8: ='Data Sheet'!E20/'Data Sheet'!E$17 -> 0.079198699 | G8: ='Data Sheet'!F20/'Data Sheet'!F$17 -> 0.083214366 | H8: ='Data Sheet'!G20/'Data Sheet'!G$17 -> 0.085535826 | I8: ='Data Sheet'!H20/'Data Sheet'!H$17 -> 0.074963364 | J8: ='Data Sheet'!I20/'Data Sheet'!I$17 -> 0.077125933 | ... L8: ='Data Sheet'!K20/'Data Sheet'!K$17 -> 0.086437036
B9: ='Data Sheet'!A21 -> Other Mfr. Exp | C9: ='Data Sheet'!B21/'Data Sheet'!B$17 -> 0.12770582 | D9: ='Data Sheet'!C21/'Data Sheet'!C$17 -> 0.1382811 | E9: ='Data Sheet'!D21/'Data Sheet'!D$17 -> 0.123858 | F9: ='Data Sheet'!E21/'Data Sheet'!E$17 -> 0.1211266 | G9: ='Data Sheet'!F21/'Data Sheet'!F$17 -> 0.11984851 | H9: ='Data Sheet'!G21/'Data Sheet'!G$17 -> 0.13969124 | I9: ='Data Sheet'!H21/'Data Sheet'!H$17 -> 0.20349704 | J9: ='Data Sheet'!I21/'Data Sheet'!I$17 -> 0.20308668 | ... L9: ='Data Sheet'!K21/'Data Sheet'!K$17 -> 0.16979989
B10: ='Data Sheet'!A22 -> Employee Cost | C10: ='Data Sheet'!B22/'Data Sheet'!B$17 -> 0.028937064 | D10: ='Data Sheet'!C22/'Data Sheet'!C$17 -> 0.036553791 | E10: ='Data Sheet'!D22/'Data Sheet'!D$17 -> 0.03057334 | F10: ='Data Sheet'!E22/'Data Sheet'!E$17 -> 0.025621064 | G10: ='Data Sheet'!F22/'Data Sheet'!F$17 -> 0.029366306 | H10: ='Data Sheet'!G22/'Data Sheet'!G$17 -> 0.038717508 | I10: ='Data Sheet'!H22/'Data Sheet'!H$17 -> 0.031388169 | J10: ='Data Sheet'!I22/'Data Sheet'!I$17 -> 0.023864017 | ... L10: ='Data Sheet'!K22/'Data Sheet'!K$17 -> 0.026233386
B11: ='Data Sheet'!A23 -> Selling and admin | C11: ='Data Sheet'!B23/'Data Sheet'!B$17 -> 0.0070349137 | D11: ='Data Sheet'!C23/'Data Sheet'!C$17 -> 0.0080108467 | E11: ='Data Sheet'!D23/'Data Sheet'!D$17 -> 0.0058089346 | F11: ='Data Sheet'!E23/'Data Sheet'!E$17 -> 0.0038508056 | G11: ='Data Sheet'!F23/'Data Sheet'!F$17 -> 0.0071026582 | H11: ='Data Sheet'!G23/'Data Sheet'!G$17 -> 0.0061369773 | I11: ='Data Sheet'!H23/'Data Sheet'!H$17 -> 0.0050601836 | J11: ='Data Sheet'!I23/'Data Sheet'!I$17 -> 0.0038053986 | ... L11: ='Data Sheet'!K23/'Data Sheet'!K$17 -> 0.0051083963
B12: ='Data Sheet'!A24 -> Other Expenses | C12: ='Data Sheet'!B24/'Data Sheet'!B$17 -> 0.02193783 | D12: ='Data Sheet'!C24/'Data Sheet'!C$17 -> 0.031835907 | E12: ='Data Sheet'!D24/'Data Sheet'!D$17 -> 0.022300554 | F12: ='Data Sheet'!E24/'Data Sheet'!E$17 -> 0.020324469 | G12: ='Data Sheet'!F24/'Data Sheet'!F$17 -> 0.027360572 | H12: ='Data Sheet'!G24/'Data Sheet'!G$17 -> 0.04062679 | I12: ='Data Sheet'!H24/'Data Sheet'!H$17 -> 0.025188191 | J12: ='Data Sheet'!I24/'Data Sheet'!I$17 -> 0.019962971 | ... L12: ='Data Sheet'!K24/'Data Sheet'!K$17 -> 0.027736192
B13: ='Data Sheet'!A25 -> Other Income | C13: ='Data Sheet'!B25/'Data Sheet'!B$17 -> 0.0019400995 | D13: ='Data Sheet'!C25/'Data Sheet'!C$17 -> -0.047326384 | E13: ='Data Sheet'!D25/'Data Sheet'!D$17 -> 0.00032371772 | F13: ='Data Sheet'!E25/'Data Sheet'!E$17 -> -0.0024606231 | G13: ='Data Sheet'!F25/'Data Sheet'!F$17 -> 0.0023124934 | H13: ='Data Sheet'!G25/'Data Sheet'!G$17 -> -0.0039413032 | I13: ='Data Sheet'!H25/'Data Sheet'!H$17 -> 0.0059244229 | J13: ='Data Sheet'!I25/'Data Sheet'!I$17 -> 0.010931127 | ... L13: ='Data Sheet'!K25/'Data Sheet'!K$17 -> 0.0085711347
B14: ='Data Sheet'!A26 -> Depreciation | C14: ='Data Sheet'!B26/'Data Sheet'!B$17 -> 0.064836551 | D14: ='Data Sheet'!C26/'Data Sheet'!C$17 -> 0.079972715 | E14: ='Data Sheet'!D26/'Data Sheet'!D$17 -> 0.06168621 | F14: ='Data Sheet'!E26/'Data Sheet'!E$17 -> 0.047085482 | G14: ='Data Sheet'!F26/'Data Sheet'!F$17 -> 0.047677478 | H14: ='Data Sheet'!G26/'Data Sheet'!G$17 -> 0.057905791 | I14: ='Data Sheet'!H26/'Data Sheet'!H$17 -> 0.058605443 | J14: ='Data Sheet'!I26/'Data Sheet'!I$17 -> 0.040998558 | ... L14: ='Data Sheet'!K26/'Data Sheet'!K$17 -> 0.046695542
B15: ='Data Sheet'!A27 -> Interest | C15: ='Data Sheet'!B27/'Data Sheet'!B$17 -> 0.065941673 | D15: ='Data Sheet'!C27/'Data Sheet'!C$17 -> 0.086678989 | E15: ='Data Sheet'!D27/'Data Sheet'!D$17 -> 0.067764909 | F15: ='Data Sheet'!E27/'Data Sheet'!E$17 -> 0.051450655 | G15: ='Data Sheet'!F27/'Data Sheet'!F$17 -> 0.046214472 | H15: ='Data Sheet'!G27/'Data Sheet'!G$17 -> 0.058164907 | I15: ='Data Sheet'!H27/'Data Sheet'!H$17 -> 0.049562244 | J15: ='Data Sheet'!I27/'Data Sheet'!I$17 -> 0.03394115 | ... L15: ='Data Sheet'!K27/'Data Sheet'!K$17 -> 0.046312698
B16: ='Data Sheet'!A28 -> Profit before tax | C16: ='Data Sheet'!B28/'Data Sheet'!B$17 -> 0.047933502 | D16: ='Data Sheet'!C28/'Data Sheet'!C$17 -> -0.059395607 | E16: ='Data Sheet'!D28/'Data Sheet'!D$17 -> 0.092223581 | F16: ='Data Sheet'!E28/'Data Sheet'!E$17 -> 0.10636287 | G16: ='Data Sheet'!F28/'Data Sheet'!F$17 -> 0.13176493 | H16: ='Data Sheet'!G28/'Data Sheet'!G$17 -> 0.041090473 | I16: ='Data Sheet'!H28/'Data Sheet'!H$17 -> 0.15049036 | J16: ='Data Sheet'!I28/'Data Sheet'!I$17 -> 0.20321648 | ... L16: ='Data Sheet'!K28/'Data Sheet'!K$17 -> 0.076454522
... B18: ='Data Sheet'!A30 -> Net profit | C18: ='Data Sheet'!B30/'Data Sheet'!B$17 -> 0.033915779 | D18: ='Data Sheet'!C30/'Data Sheet'!C$17 -> -0.0080736684 | E18: ='Data Sheet'!D30/'Data Sheet'!D$17 -> 0.063358751 | F18: ='Data Sheet'!E30/'Data Sheet'!E$17 -> 0.086385942 | G18: ='Data Sheet'!F30/'Data Sheet'!F$17 -> 0.090128249 | H18: ='Data Sheet'!G30/'Data Sheet'!G$17 -> 0.054960041 | I18: ='Data Sheet'!H30/'Data Sheet'!H$17 -> 0.099086912 | J18: ='Data Sheet'!I30/'Data Sheet'!I$17 -> 0.14118234 | ... L18: ='Data Sheet'!K30/'Data Sheet'!K$17 -> 0.050352559
B19: ='Data Sheet'!A32 -> EBITDA | C19: ='Data Sheet'!B32/'Data Sheet'!B$17 -> 0.17677163 | D19: ='Data Sheet'!C32/'Data Sheet'!C$17 -> 0.15458248 | E19: ='Data Sheet'!D32/'Data Sheet'!D$17 -> 0.22135098 | F19: ='Data Sheet'!E32/'Data Sheet'!E$17 -> 0.20735963 | G19: ='Data Sheet'!F32/'Data Sheet'!F$17 -> 0.22334438 | H19: ='Data Sheet'!G32/'Data Sheet'!G$17 -> 0.16110247 | I19: ='Data Sheet'!H32/'Data Sheet'!H$17 -> 0.25273363 | J19: ='Data Sheet'!I32/'Data Sheet'!I$17 -> 0.26722507 | ... L19: ='Data Sheet'!K32/'Data Sheet'!K$17 -> 0.16089163
B21: ="Common Size Balance Sheet "&" "& " - "&'Data Sheet'!$B$1 -> Common Size Balance Sheet - JSW STEEL LTD
B23: Total Liabilites | C23: ='Data Sheet'!B61/'Data Sheet'!B$61 -> 1 | D23: ='Data Sheet'!C61/'Data Sheet'!C$61 -> 1 | E23: ='Data Sheet'!D61/'Data Sheet'!D$61 -> 1 | F23: ='Data Sheet'!E61/'Data Sheet'!E$61 -> 1 | G23: ='Data Sheet'!F61/'Data Sheet'!F$61 -> 1 | H23: ='Data Sheet'!G61/'Data Sheet'!G$61 -> 1 | I23: ='Data Sheet'!H61/'Data Sheet'!H$61 -> 1 | J23: ='Data Sheet'!I61/'Data Sheet'!I$61 -> 1 | ... L23: ='Data Sheet'!K61/'Data Sheet'!K$61 -> 1
B24: ='Data Sheet'!A57 -> Equity Share Capital | C24: ='Data Sheet'!B57/'Data Sheet'!B$61 -> 0.0035345743 | D24: ='Data Sheet'!C57/'Data Sheet'!C$61 -> 0.0036736832 | E24: ='Data Sheet'!D57/'Data Sheet'!D$61 -> 0.0034202602 | F24: ='Data Sheet'!E57/'Data Sheet'!E$61 -> 0.0032836795 | G24: ='Data Sheet'!F57/'Data Sheet'!F$61 -> 0.0026220197 | H24: ='Data Sheet'!G57/'Data Sheet'!G$61 -> 0.0022834168 | I24: ='Data Sheet'!H57/'Data Sheet'!H$61 -> 0.0020361793 | J24: ='Data Sheet'!I57/'Data Sheet'!I$61 -> 0.0015319236 | ... L24: ='Data Sheet'!K57/'Data Sheet'!K$61 -> 0.001338318
B25: ='Data Sheet'!A58 -> Reserves | C25: ='Data Sheet'!B58/'Data Sheet'!B$61 -> 0.25669462 | D25: ='Data Sheet'!C58/'Data Sheet'!C$61 -> 0.22787519 | E25: ='Data Sheet'!D58/'Data Sheet'!D$61 -> 0.25391739 | F25: ='Data Sheet'!E58/'Data Sheet'!E$61 -> 0.30114168 | G25: ='Data Sheet'!F58/'Data Sheet'!F$61 -> 0.30047824 | H25: ='Data Sheet'!G58/'Data Sheet'!G$61 -> 0.27536034 | I25: ='Data Sheet'!H58/'Data Sheet'!H$61 -> 0.31326146 | J25: ='Data Sheet'!I58/'Data Sheet'!I$61 -> 0.34097259 | ... L25: ='Data Sheet'!K58/'Data Sheet'!K$61 -> 0.33946766
B26: ='Data Sheet'!A59 -> Borrowings | C26: ='Data Sheet'!B59/'Data Sheet'!B$61 -> 0.45245189 | D26: ='Data Sheet'!C59/'Data Sheet'!C$61 -> 0.51526831 | E26: ='Data Sheet'!D59/'Data Sheet'!D$61 -> 0.49240384 | F26: ='Data Sheet'!E59/'Data Sheet'!E$61 -> 0.42832445 | G26: ='Data Sheet'!F59/'Data Sheet'!F$61 -> 0.41286793 | H26: ='Data Sheet'!G59/'Data Sheet'!G$61 -> 0.46596116 | I26: ='Data Sheet'!H59/'Data Sheet'!H$61 -> 0.42066655 | J26: ='Data Sheet'!I59/'Data Sheet'!I$61 -> 0.36764639 | ... L26: ='Data Sheet'!K59/'Data Sheet'!K$61 -> 0.38606745
B27: ='Data Sheet'!A60 -> Other Liabilities | C27: ='Data Sheet'!B60/'Data Sheet'!B$61 -> 0.28731892 | D27: ='Data Sheet'!C60/'Data Sheet'!C$61 -> 0.25318282 | E27: ='Data Sheet'!D60/'Data Sheet'!D$61 -> 0.25025851 | F27: ='Data Sheet'!E60/'Data Sheet'!E$61 -> 0.26725019 | G27: ='Data Sheet'!F60/'Data Sheet'!F$61 -> 0.28403181 | H27: ='Data Sheet'!G60/'Data Sheet'!G$61 -> 0.25639508 | I27: ='Data Sheet'!H60/'Data Sheet'!H$61 -> 0.26403582 | J27: ='Data Sheet'!I60/'Data Sheet'!I$61 -> 0.2898491 | ... L27: ='Data Sheet'!K60/'Data Sheet'!K$61 -> 0.27312657
B29: Total Asset | C29: ='Data Sheet'!B66/'Data Sheet'!B$66 -> 1 | D29: ='Data Sheet'!C66/'Data Sheet'!C$66 -> 1 | E29: ='Data Sheet'!D66/'Data Sheet'!D$66 -> 1 | F29: ='Data Sheet'!E66/'Data Sheet'!E$66 -> 1 | G29: ='Data Sheet'!F66/'Data Sheet'!F$66 -> 1 | H29: ='Data Sheet'!G66/'Data Sheet'!G$66 -> 1 | I29: ='Data Sheet'!H66/'Data Sheet'!H$66 -> 1 | J29: ='Data Sheet'!I66/'Data Sheet'!I$66 -> 1 | ... L29: ='Data Sheet'!K66/'Data Sheet'!K$66 -> 1
B30: ='Data Sheet'!A62 -> Net Block | C30: ='Data Sheet'!B62/'Data Sheet'!B$66 -> 0.60915256 | D30: ='Data Sheet'!C62/'Data Sheet'!C$66 -> 0.68540648 | E30: ='Data Sheet'!D62/'Data Sheet'!D$66 -> 0.66734845 | F30: ='Data Sheet'!E62/'Data Sheet'!E$66 -> 0.62898771 | G30: ='Data Sheet'!F62/'Data Sheet'!F$66 -> 0.5456937 | H30: ='Data Sheet'!G62/'Data Sheet'!G$66 -> 0.47098316 | I30: ='Data Sheet'!H62/'Data Sheet'!H$66 -> 0.43769089 | J30: ='Data Sheet'!I62/'Data Sheet'!I$66 -> 0.50833397 | ... L30: ='Data Sheet'!K62/'Data Sheet'!K$66 -> 0.49347076
B31: ='Data Sheet'!A63 -> Capital Work in Progress | C31: ='Data Sheet'!B63/'Data Sheet'!B$66 -> 0.096496154 | D31: ='Data Sheet'!C63/'Data Sheet'!C$66 -> 0.088769689 | E31: ='Data Sheet'!D63/'Data Sheet'!D$66 -> 0.049576729 | F31: ='Data Sheet'!E63/'Data Sheet'!E$66 -> 0.064695009 | G31: ='Data Sheet'!F63/'Data Sheet'!F$66 -> 0.10356542 | H31: ='Data Sheet'!G63/'Data Sheet'!G$66 -> 0.20627371 | I31: ='Data Sheet'!H63/'Data Sheet'!H$66 -> 0.21957024 | J31: ='Data Sheet'!I63/'Data Sheet'!I$66 -> 0.086037102 | ... L31: ='Data Sheet'!K63/'Data Sheet'!K$66 -> 0.13021615
B32: ='Data Sheet'!A64 -> Investments | C32: ='Data Sheet'!B64/'Data Sheet'!B$66 -> 0.0069961804 | D32: ='Data Sheet'!C64/'Data Sheet'!C$66 -> 0.014584974 | E32: ='Data Sheet'!D64/'Data Sheet'!D$66 -> 0.015521845 | F32: ='Data Sheet'!E64/'Data Sheet'!E$66 -> 0.0159726 | G32: ='Data Sheet'!F64/'Data Sheet'!F$66 -> 0.016498689 | H32: ='Data Sheet'!G64/'Data Sheet'!G$66 -> 0.0095509027 | I32: ='Data Sheet'!H64/'Data Sheet'!H$66 -> 0.057855809 | J32: ='Data Sheet'!I64/'Data Sheet'!I$66 -> 0.025141868 | ... L32: ='Data Sheet'!K64/'Data Sheet'!K$66 -> 0.031794926
B33: ='Data Sheet'!A65 -> Other Assets | C33: ='Data Sheet'!B74/'Data Sheet'!B$66 -> 0.10730442 | D33: ='Data Sheet'!C74/'Data Sheet'!C$66 -> 0.063889245 | E33: ='Data Sheet'!D74/'Data Sheet'!D$66 -> 0.074052611 | F33: ='Data Sheet'!E74/'Data Sheet'!E$66 -> 0.09070349 | G33: ='Data Sheet'!F74/'Data Sheet'!F$66 -> 0.091248029 | H33: ='Data Sheet'!G74/'Data Sheet'!G$66 -> 0.083477469 | I33: ='Data Sheet'!H74/'Data Sheet'!H$66 -> 0.072176487 | J33: ='Data Sheet'!I74/'Data Sheet'!I$66 -> 0.082108049 | ... L33: ='Data Sheet'!K74/'Data Sheet'!K$66 -> 0.091286453
B34: ='Data Sheet'!A67 -> Receivables | C34: ='Data Sheet'!B67/'Data Sheet'!B$66 -> 0.029184317 | D34: ='Data Sheet'!C67/'Data Sheet'!C$66 -> 0.033298416 | E34: ='Data Sheet'!D67/'Data Sheet'!D$66 -> 0.047145049 | F34: ='Data Sheet'!E67/'Data Sheet'!E$66 -> 0.051147113 | G34: ='Data Sheet'!F67/'Data Sheet'!F$66 -> 0.062370968 | H34: ='Data Sheet'!G67/'Data Sheet'!G$66 -> 0.034175391 | I34: ='Data Sheet'!H67/'Data Sheet'!H$66 -> 0.030246027 | J34: ='Data Sheet'!I67/'Data Sheet'!I$66 -> 0.037952007 | ... L34: ='Data Sheet'!K67/'Data Sheet'!K$66 -> 0.03312008
B35: ='Data Sheet'!A68 -> Inventory | C35: ='Data Sheet'!B68/'Data Sheet'!B$66 -> 0.12852938 | D35: ='Data Sheet'!C68/'Data Sheet'!C$66 -> 0.10159315 | E35: ='Data Sheet'!D68/'Data Sheet'!D$66 -> 0.12948128 | F35: ='Data Sheet'!E68/'Data Sheet'!E$66 -> 0.13693596 | G35: ='Data Sheet'!F68/'Data Sheet'!F$66 -> 0.12672805 | H35: ='Data Sheet'!G68/'Data Sheet'!G$66 -> 0.10448339 | I35: ='Data Sheet'!H68/'Data Sheet'!H$66 -> 0.096071253 | J35: ='Data Sheet'!I68/'Data Sheet'!I$66 -> 0.17195715 | ... L35: ='Data Sheet'!K68/'Data Sheet'!K$66 -> 0.16592949
B36: ='Data Sheet'!A69 -> Cash & Bank | C36: ='Data Sheet'!B69/'Data Sheet'!B$66 -> 0.022336992 | D36: ='Data Sheet'!C69/'Data Sheet'!C$66 -> 0.012458047 | E36: ='Data Sheet'!D69/'Data Sheet'!D$66 -> 0.016874041 | F36: ='Data Sheet'!E69/'Data Sheet'!E$66 -> 0.011558117 | G36: ='Data Sheet'!F69/'Data Sheet'!F$66 -> 0.053895137 | H36: ='Data Sheet'!G69/'Data Sheet'!G$66 -> 0.091055985 | I36: ='Data Sheet'!H69/'Data Sheet'!H$66 -> 0.086389288 | J36: ='Data Sheet'!I69/'Data Sheet'!I$66 -> 0.088469858 | ... L36: ='Data Sheet'!K69/'Data Sheet'!K$66 -> 0.054182134

Sheet Forcasting
B2: ='Data Sheet'!B1&"- "&'Data Sheet'!A17 -> JSW STEEL LTD- Sales | G2: ='Data Sheet'!B1&"-"&'Historical FS'!B17 -> JSW STEEL LTD-Operating Profit(EBITDA) | L2: ='Data Sheet'!B1&"-"&'Historical FS'!B31 -> JSW STEEL LTD-EPS
B3: Year Weight | C3: Year | D3: Sales | E3: Sales growth | G3: Year Weight | H3: Year | I3: EBITDA | J3: EBITDA growth | L3: Year Weight | M3: Year | N3: EPS | O3: EPS growth
B4: 1 | C4: ='Data Sheet'!B16 -> 42094 | D4: {=TRANSPOSE('Data Sheet'!B17:K17)} -> 52971.51 | G4: =B4 -> 1 | H4: =C4 -> 42094 | I4: {=TRANSPOSE('Historical FS'!C17:L17)} -> 9363.86 | L4: =G4 -> 1 | M4: =H4 -> 42094 | N4: {=TRANSPOSE('Historical FS'!C31:L31)} -> 6.6892686
B5: =B4+1 -> 2 | C5: =C4+365 -> 42459 | D5: 41546.17 | E5: =D5/D4-1 -> -0.2156884 | G5: =B5 -> 2 | H5: =C5 -> 42459 | I5: 6422.31 | J5: =I5/I4-1 -> -0.31413861 | L5: =G5 -> 2 | M5: =H5 -> 42459 | N5: 6.0598213 | O5: =N5/N4-1 -> -0.094098075
B6: =B5+1 -> 3 | C6: =C5+365 -> 42824 | D6: 55604 | E6: =D6/D5-1 -> 0.33836645 | G6: =B6 -> 3 | H6: =C6 -> 42824 | I6: 12308 | J6: =I6/I5-1 -> 0.91644439 | L6: =G6 -> 3 | M6: =H6 -> 42824 | N6: 14.214794 | O6: =N6/N5-1 -> 1.3457448
B7: =B6+1 -> 4 | C7: =C6+365 -> 43189 | D7: 71933 | E7: =D7/D6-1 -> 0.29366592 | G7: =B7 -> 4 | H7: =C7 -> 43189 | I7: 14916 | J7: =I7/I6-1 -> 0.2118947 | L7: =G7 -> 4 | M7: =H7 -> 43189 | N7: 26.021843 | O7: =N7/N6-1 -> 0.830617
B8: =B7+1 -> 5 | C8: =C7+365 -> 43554 | D8: 84757 | E8: =D8/D7-1 -> 0.17827701 | G8: =B8 -> 5 | H8: =C8 -> 43554 | I8: 18930 | J8: =I8/I7-1 -> 0.269107 | L8: =G8 -> 5 | M8: =H8 -> 43554 | N8: 30.316068 | O8: =N8/N7-1 -> 0.16502385
B9: =B8+1 -> 6 | C9: =C8+365 -> 43919 | D9: 73326 | E9: =D9/D8-1 -> -0.13486792 | G9: =B9 -> 6 | H9: =C9 -> 43919 | I9: 11813 | J9: =I9/I8-1 -> -0.37596408 | L9: =G9 -> 6 | M9: =H9 -> 43919 | N9: 17.408572 | O9: =N9/N8-1 -> -0.42576419
B10: =B9+1 -> 7 | C10: =C9+365 -> 44284 | D10: 79839 | E10: =D10/D9-1 -> 0.088822519 | G10: =B10 -> 7 | H10: =C10 -> 44284 | I10: 20178 | J10: =I10/I9-1 -> 0.70811817 | L10: =G10 -> 7 | M10: =H10 -> 44284 | N10: 30.613933 | O10: =N10/N9-1 -> 0.75855513
B11: =B10+1 -> 8 | C11: =C10+365 -> 44649 | D11: 146371 | E11: =D11/D10-1 -> 0.83332707 | G11: =B11 -> 8 | H11: =C11 -> 44649 | I11: 39114 | J11: =I11/I10-1 -> 0.93844781 | L11: =G11 -> 8 | M11: =H11 -> 44649 | N11: 80.001655 | O11: =N11/N10-1 -> 1.6132432
B12: =B11+1 -> 9 | C12: =C11+365 -> 45014 | D12: 165960 | E12: =D12/D11-1 -> 0.13383116 | G12: =B12 -> 9 | H12: =C12 -> 45014 | I12: 18470 | J12: =I12/I11-1 -> -0.52779056 | L12: =G12 -> 9 | M12: =H12 -> 45014 | N12: 10.665233 | O12: =N12/N11-1 -> -0.86668735
B13: =B12+1 -> 10 | C13: =C12+365 -> 45379 | D13: 175006 | E13: =D13/D12-1 -> 0.05450711 | G13: =B13 -> 10 | H13: =C13 -> 45379 | I13: 28157 | J13: =I13/I12-1 -> 0.52447212 | L13: =G13 -> 10 | M13: =H13 -> 45379 | N13: 30.558168 | O13: =N13/N12-1 -> 1.8652135
B14: =B13+1 -> 11 | C14: =C13+365 -> 45744 | D14: =FORECAST(B14,$D$4:$D$13,$B$4:$B$13) -> 175909.01 | E14: =D14/D13-1 -> 0.0051598726 | G14: =B14 -> 11 | H14: =C14 -> 45744 | I14: =FORECAST(G14,$I$4:$I$13,$G$4:$G$13) -> 31172.92 | J14: =I14/I13-1 -> 0.10711084 | L14: =G14 -> 11 | M14: =H14 -> 45744 | N14: =FORECAST(L14,$N$4:$N$13,$L$4:$L$13) -> 44.483637 | O14: =N14/N13-1 -> 0.45570367
B15: =B14+1 -> 12 | C15: =C14+365 -> 46109 | D15: =FORECAST(B15,$D$4:$D$13,$B$4:$B$13) -> 190668.58 | E15: =D15/D14-1 -> 0.083904577 | G15: =B15 -> 12 | H15: =C15 -> 46109 | I15: =FORECAST(G15,$I$4:$I$13,$G$4:$G$13) -> 33573.957 | J15: =I15/I14-1 -> 0.077023163 | L15: =G15 -> 12 | M15: =H15 -> 46109 | N15: =FORECAST(L15,$N$4:$N$13,$L$4:$L$13) -> 47.979765 | O15: =N15/N14-1 -> 0.078593564
B16: =B15+1 -> 13 | C16: =C15+365 -> 46474 | D16: =FORECAST(B16,$D$4:$D$13,$B$4:$B$13) -> 205428.15 | E16: =D16/D15-1 -> 0.077409561 | G16: =B16 -> 13 | H16: =C16 -> 46474 | I16: =FORECAST(G16,$I$4:$I$13,$G$4:$G$13) -> 35974.994 | J16: =I16/I15-1 -> 0.071514862 | L16: =G16 -> 13 | M16: =H16 -> 46474 | N16: =FORECAST(L16,$N$4:$N$13,$L$4:$L$13) -> 51.475893 | O16: =N16/N15-1 -> 0.072866709
B17: =B16+1 -> 14 | C17: =C16+365 -> 46839 | D17: =FORECAST(B17,$D$4:$D$13,$B$4:$B$13) -> 220187.72 | E17: =D17/D16-1 -> 0.07184785 | G17: =B17 -> 14 | H17: =C17 -> 46839 | I17: =FORECAST(G17,$I$4:$I$13,$G$4:$G$13) -> 38376.031 | J17: =I17/I16-1 -> 0.06674183 | L17: =G17 -> 14 | M17: =H17 -> 46839 | N17: =FORECAST(L17,$N$4:$N$13,$L$4:$L$13) -> 54.97202 | O17: =N17/N16-1 -> 0.067917765
B18: =B17+1 -> 15 | C18: =C17+365 -> 47204 | D18: =FORECAST(B18,$D$4:$D$13,$B$4:$B$13) -> 234947.29 | E18: =D18/D17-1 -> 0.067031762 | G18: =B18 -> 15 | H18: =C18 -> 47204 | I18: =FORECAST(G18,$I$4:$I$13,$G$4:$G$13) -> 40777.068 | J18: =I18/I17-1 -> 0.062566057 | L18: =G18 -> 15 | M18: =H18 -> 47204 | N18: =FORECAST(L18,$N$4:$N$13,$L$4:$L$13) -> 58.468148 | O18: =N18/N17-1 -> 0.06359831

Sheet DCF>
B2: Calculation OF PV Of FCFF | E2: ='Data Sheet'!K16 -> 45382 | F2: =E2+365 -> 45747 | G2: =F2+365 -> 46112 | H2: =G2+365 -> 46477 | I2: =H2+365 -> 46842 | J2: =I2+365 -> 47207
B4: EBIT | E4: ='Intrinsic Growth'!K35 -> 19985 | F4: =E4*(1+$C$14) -> 24428.616 | G4: =F4*(1+$C$14) -> 29860.26 | H4: =G4*(1+$C$14) -> 36499.616 | I4: =H4*(1+$C$14) -> 44615.218 | J4: =I4*(1+$C$14) -> 54535.303
B5: Tax Rate | E5: ='Intrinsic Growth'!K45 -> 0.25 | F5: =E5 -> 0.25 | G5: =F5 -> 0.25 | H5: =G5 -> 0.25 | I5: =H5 -> 0.25 | J5: =I5 -> 0.25
B6: EBIT(1-TaxRate) | E6: =E4*(1-E5) -> 14988.75 | F6: =F4*(1-F5) -> 18321.462 | G6: =G4*(1-G5) -> 22395.195 | H6: =H4*(1-H5) -> 27374.712 | I6: =I4*(1-I5) -> 33461.413 | J6: =J4*(1-J5) -> 40901.478
B7: Less:Reinvestment Rate | E7: =70.3% -> 0.703 | F7: =E7 -> 0.703 | G7: =F7 -> 0.703 | H7: =G7 -> 0.703 | I7: =H7 -> 0.703 | J7: =I7 -> 0.703
B8: Free Cash Flow to Firm(FCFF) | E8: =E6*(1-E7) -> 4451.6588 | F8: =F6*(1-F7) -> 5441.4743 | G8: =G6*(1-G7) -> 6651.3729 | H8: =H6*(1-H7) -> 8130.2896 | I8: =I6*(1-I7) -> 9938.0398 | J8: =J6*(1-J7) -> 12147.739
B9: Mid Year Conversion | F9: 0.5 | G9: =F9+1 -> 1.5 | H9: =G9+1 -> 2.5 | I9: =H9+1 -> 3.5 | J9: =I9+1 -> 4.5
B10: Discounting Factor | F10: =1/(1+$C$16)^F9 -> 0.9286661 | G10: =1/(1+$C$16)^G9 -> 0.8009009 | H10: =1/(1+$C$16)^H9 -> 0.69071354 | I10: =1/(1+$C$16)^I9 -> 0.59568567 | J10: =1/(1+$C$16)^J9 -> 0.51373167
B12: PV of FCFF | F12: =F8*F10 -> 5053.3127 | G12: =G8*G10 -> 5327.0905 | H12: =H8*H10 -> 5615.7011 | I12: =I8*I10 -> 5919.9479 | J12: =J8*J10 -> 6240.6782
B14: Expected Growth | C14: ='Intrinsic Growth'!K64 -> 0.22234758
B15: Terminal Growth | C15: 0.064
B16: WACC | C16: =Wacc!M40 -> 0.15952686
B18: Calculation of Terminal Value | F18: Sensitivity Analysis
F19: =C36 -> 423.596 | G19: 0.12 | H19: 0.14 | I19: 0.1595 | J19: 0.17
B20: FCFF(n+1) | C20: =J8*(1+C14) -> 14848.759 | F20: 0.04 | G20: 546.96062 | H20: 395.16386 | I20: 296.08313 | J20: 255.04377
B21: WACC | C21: =C16 -> 0.15952686 | F21: 0.05 | G21: 655.38688 | H21: 462.62909 | I21: 342.48553 | J21: 293.96602
B22: Terminal Growth | C22: =C15 -> 0.064 | F22: 0.064 | G22: 872.23939 | H22: 586.90713 | I22: 423.77477 | J22: 360.79478
G23: 293.96602 | H23: 221.68185 | I23: 168.65835 | J23: 145.14566
B24: Terminal Value | C24: =C20/(C21-C22) -> 155440.67 | F24: 0.08 | G24: 1305.9444 | H24: 799.95522 | I24: 551.7341 | J24: 462.62909
F25: 0.1 | G25: 2823.912 | H25: 1305.9444 | I25: 808.45924 | J25: 655.38688
B26: Calculation of Equity Value Per Share
B28: PV of FCFF | C28: =SUM(F12:J12) -> 28156.73
B29: Terminal Value | C29: =C24 -> 155440.67
B30: Operating Asset | C30: =SUM(C28:C29) -> 183597.4
B32: Add: Cash | C32: ='Data Sheet'!K69 -> 12348
B33: Less:Debt | C33: =SUM('Raw FS'!O7:O8) -> 92355
B34: Value OF Equity | C34: =C30+C32-C33 -> 103590.4
B35: No of Shares | C35: ='Data Sheet'!K93 -> 244.55
B36: Equity Value Per Share | C36: =C34/C35 -> 423.596
B38: Share Price | C38: =1058 -> 1058
B39: Discount/Premium | C39: =C38/C36-1 -> 1.4976629

Sheet Wacc
B2: Weighted Average Cost Of Capital
B4: All Figures are In INR as Stated Below
B6: PeerComps
J7: Debt/ | K7: Debt/ | L7: Levered | M7: Unlevered
B8: Name Of Comps | F8: Country | G8: Total Debt | H8: Total Equity | I8: Tax Rate | J8: Equity | K8: Capital | L8: Beta | M8: Beta
B9: ='Peer Comps'!C3 -> JSW Steel | F9: India | G9: ='Peer Comps'!F3 -> 95258 | H9: ='Peer Comps'!E3 -> 258459.99 | I9: 0.3 | J9: =G9/H9 -> 0.36855995 | K9: =G9/(H9+G9) -> 0.26930493 | L9: =Beta!O5 -> 1.2946664 | M9: =L9/(1+(1-I9)*J9) -> 1.0291532
B10: ='Peer Comps'!C4 -> Tata Steel | F10: India | G10: ='Peer Comps'!F4 -> 99391.76 | H10: ='Peer Comps'!E4 -> 197551.76 | I10: 0.3 | J10: =G10/H10 -> 0.50311756 | K10: =G10/(H10+G10) -> 0.33471604 | L10: 1.24 | M10: =L10/(1+(1-I10)*J10) -> 0.91703612
B11: ='Peer Comps'!C5 -> Jindal Steel | F11: India | G11: ='Peer Comps'!F5 -> 17266.45 | H11: ='Peer Comps'!E5 -> 93730.79 | I11: 0.3 | J11: =G11/H11 -> 0.18421321 | K11: =G11/(H11+G11) -> 0.15555747 | L11: 1.34 | M11: =L11/(1+(1-I11)*J11) -> 1.1869444
B12: ='Peer Comps'!C6 -> S A I L | F12: India | G12: ='Peer Comps'!F6 -> 41265.03 | H12: ='Peer Comps'!E6 -> 47480.37 | I12: 0.3 | J12: =G12/H12 -> 0.86909664 | K12: =G12/(H12+G12) -> 0.46498218 | L12: 1.65 | M12: =L12/(1+(1-I12)*J12) -> 1.0258848
H14: Average | I14: =I11 -> 0.3 | J14: =AVERAGE(J9:J12) -> 0.48124684 | K14: =AVERAGE(K9:K12) -> 0.30614016 | L14: =AVERAGE(L9:L12) -> 1.3811666 | M14: =AVERAGE(M9:M12) -> 1.0397546
H15: Median | I15: =I12 -> 0.3 | J15: =MEDIAN(J9:J12) -> 0.43583875 | K15: =MEDIAN(K9:K12) -> 0.30201049 | L15: =MEDIAN(L9:L12) -> 1.3173332 | M15: =MEDIAN(M9:M12) -> 1.027519
B18: Cost Of Debt | J18: Cost Of Equity
B20: Pre Tax Cost of Debt | F20: ='Historical FS'!M19/Wacc!G9 -> 0.087971614 | J20: Risk Free Rate | M20: =6.73% -> 0.0673
B21: Tax Rate | F21: =I14 -> 0.3 | J21: Equity Risk Premium | M21: =Rm!G6-Wacc!M20 -> 0.100548
B22: Post Tax Cost Of Debt | F22: =F20*(1-F21) -> 0.06158013 | J22: Levered Beta | M22: =M30 -> 1.3387344
J23: Cost of Equity | M23: =M20+(M21*M22) -> 0.20190707
B25: Capital Structure | J25: Levered Beta
E27: Current | F27: Target | J27: Comps Median Unlevered Beta | M27: =M15 -> 1.027519
B28: Debt | D28: =G9 -> 95258 | E28: =D28/D30 -> 0.26930493 | F28: =K15 -> 0.30201049 | J28: Target Debt/Equity | M28: =F32 -> 0.43268628
B29: Market Capatiliazation | D29: =H9 -> 258459.99 | E29: =D29/D30 -> 0.73069507 | F29: =F30-F28 -> 0.69798951 | J29: Tax Rate | M29: =I14 -> 0.3
B30: Total Capital | D30: =SUM(D28:D29) -> 353717.99 | E30: =SUM(E28:E29) -> 1 | F30: =E30 -> 1 | J30: Levered Beta | M30: =M27*(1+(1-M29)*M28) -> 1.3387344
B32: Debt /Equity | E32: =E28/E29 -> 0.36855995 | F32: =F28/F29 -> 0.43268628 | J32: Weighted Average Cost of Capital
J34: Costof Debt | M34: =F22 -> 0.06158013
B35: NOTE | J35: Weight Of Debt | M35: =F28 -> 0.30201049
A36: 1 | B36: Tax Rate is Considerd as Marginal tax rate for the country
A37: 2 | B37: Levered Beta is Based on 2 Year weekly data | J37: Cost Of Equity | M37: =M23 -> 0.20190707
A38: 3 | B38: Unlevered Beta = Levered Beta/(1+(1-TAX RATE)*DEBT/EQUITY) | J38: Weight of Equity | M38: =F29 -> 0.69798951
A39: 4 | B39: Levered Beta=Unlevered Beat*(1+(1-TAX RATE)*DEBT/EQUITY)
J40: WACC | M40: =(M34*M35)+(M37*M38) -> 0.15952686

Sheet Relative valuation
B2: Amounts in Crores
B3: Comparabel Companies Valuation
D5: Market Data | K5: Financial | O5: Valuation
B6: Companies | C6: Ticker | D6: Share price | E6: Share Outstanding | F6: Equity Value | G6: Net Debt | H6: Enterprise Value | K6: Revenue | L6: EBITDA | M6: Net Income | O6: EV/Revenue | P6: EV/EBITDA | Q6: P/E
B8: =Data2!C3 -> JSW Steel | C8: JSWSTELL | D8: =Data2!D3 -> 1058.7 | E8: =Data2!E3 -> 244.55 | F8: =D8*E8 -> 258905.09 | G8: =Data2!I3 -> 82910 | H8: =Data2!N3 -> 341815.09 | K8: =Data2!L3 -> 170274 | L8: =Data2!O3 -> 22986.892 | M8: =Data2!M3 -> 3312 | O8: =$H8/K8 -> 2.0074414 | P8: =$H8/L8 -> 14.87 | Q8: =F8/M8 -> 78.171825
B9: =Data2!C4 -> Tata Steel | C9: TATASTELL | D9: =Data2!D4 -> 157.28 | E9: =Data2!E4 -> 1248.35 | F9: =D9*E9 -> 196340.49 | G9: =Data2!I4 -> 90714.04 | H9: =Data2!N4 -> 287054.53 | K9: =Data2!L4 -> 221011.71 | L9: =Data2!O4 -> 26852.622 | M9: =Data2!M4 -> 2527.46 | O9: =$H9/K9 -> 1.2988204 | P9: =$H9/L9 -> 10.69 | Q9: =F9/M9 -> 77.682926
B10: =Data2!C5 -> Jindal Steel | C10: JINDALSTEL | D10: =Data2!D5 -> 914.3 | E10: =Data2!E5 -> 102.01 | F10: =D10*E10 -> 93267.743 | G10: =Data2!I5 -> 13242.32 | H10: =Data2!N5 -> 106510.06 | K10: =Data2!L5 -> 50068.78 | L10: =Data2!O5 -> 9753.6688 | M10: =Data2!M5 -> 4082.73 | O10: =$H10/K10 -> 2.127275 | P10: =$H10/L10 -> 10.92 | Q10: =F10/M10 -> 22.844455
B11: =Data2!C6 -> Tube Investments | C11: TIINDIA | D11: =Data2!D6 -> 2872.15 | E11: =Data2!E6 -> 19.35 | F11: =D11*E11 -> 55576.103 | G11: =Data2!I6 -> -528.48 | H11: =Data2!N6 -> 55047.623 | K11: =Data2!L6 -> 18804.8 | L11: =Data2!O6 -> 2269.0694 | M11: =Data2!M6 -> 1167.41 | O11: =$H11/K11 -> 2.9273176 | P11: =$H11/L11 -> 24.26 | Q11: =F11/M11 -> 47.606327
B12: =Data2!C7 -> Jindal Stain. | C12: JSL | D12: =Data2!D7 -> 625.7 | E12: =Data2!E7 -> 82.38 | F12: =D12*E12 -> 51545.166 | G12: =Data2!I7 -> 4484.97 | H12: =Data2!N7 -> 56030.136 | K12: =Data2!L7 -> 38567.91 | L12: =Data2!O7 -> 4889.1916 | M12: =Data2!M7 -> 2410.41 | O12: =$H12/K12 -> 1.4527657 | P12: =$H12/L12 -> 11.46 | Q12: =F12/M12 -> 21.384398
B13: =Data2!C8 -> S A I L | C13: SAIL | D13: =Data2!D8 -> 115.3 | E13: =Data2!E8 -> 413.05 | F13: =D13*E13 -> 47624.665 | G13: =Data2!I8 -> 40592.08 | H13: =Data2!N8 -> 88216.745 | K13: =Data2!L8 -> 101121.44 | L13: =Data2!O8 -> 12084.486 | M13: =Data2!M8 -> 2246.5 | O13: =$H13/K13 -> 0.87238418 | P13: =$H13/L13 -> 7.3 | Q13: =F13/M13 -> 21.199495
B14: =Data2!C9 -> APL Apollo Tubes | C14: APLAPOLLO | D14: =Data2!D9 -> 1511.55 | E14: =Data2!E9 -> 27.75 | F14: =D14*E14 -> 41945.512 | G14: =Data2!I9 -> 674.99 | H14: =Data2!N9 -> 42620.502 | K14: =Data2!L9 -> 19946.68 | L14: =Data2!O9 -> 1141.4168 | M14: =Data2!M9 -> 634.39 | O14: =$H14/K14 -> 2.1367216 | P14: =$H14/L14 -> 37.34 | Q14: =F14/M14 -> 66.119442
B16: High | O16: =MAX(O8:O14) -> 2.9273176 | P16: =MAX(P8:P14) -> 37.34 | Q16: =MAX(Q8:Q14) -> 78.171825
B17: 75th Percentile | O17: =_xlfn.QUARTILE.EXC(O8:O14,3) -> 2.1367216 | P17: =_xlfn.QUARTILE.EXC(P8:P14,3) -> 24.26 | Q17: =_xlfn.QUARTILE.EXC(Q8:Q14,3) -> 77.682926
B18: Average | O18: =AVERAGE(O8:O14) -> 1.831818 | P18: =AVERAGE(P8:P14) -> 16.691429 | Q18: =AVERAGE(Q8:Q14) -> 47.85841
B19: Median | O19: =MEDIAN(O8:O14) -> 2.0074414 | P19: =MEDIAN(P8:P14) -> 11.46 | Q19: =MEDIAN(Q8:Q14) -> 47.606327
