Workbook
Name UPDATE: 'Data Sheet'!$E$1

Sheet Input Sheet
C4: Company Discription | D4: ITC Limited is an Indian conglomerate, headquartered in Kolkata.[9] It has a presence across six business segments, namely FMCG, agribusiness, information technology, paper products, and packaging.[10] It generates a plurality of its revenue from tobacco products.[11]

Sheet Teaser
B1: ROHIT KUMAR ROUTH
B2: ='Data Sheet'!B1&" - One Page Profile" -> ITC LTD - One Page Profile
C4: ='Input Sheet'!D4 -> ITC Limited is an Indian conglomerate, headquartered in Kolkata.[9] It has a presence across six business segments, namely FMCG, agribusiness, information technology, paper products, and packaging.[10] It generates a plurality of its revenue from tobacco products.[11]
B5: INR (Crs)
B6: Key Financial Metrics | C6: ='Data Sheet'!G16 -> 43921 | D6: ='Data Sheet'!H16 -> 44286 | E6: ='Data Sheet'!I16 -> 44651 | F6: ='Data Sheet'!J16 -> 45016 | G6: ='Data Sheet'!K16 -> 45382 | I6: Share Price-5 Y
B8: Total Sales | C8: ='Data Sheet'!G17 -> 49387.7 | D8: ='Data Sheet'!H17 -> 49257.45 | E8: ='Data Sheet'!I17 -> 60644.54 | F8: ='Data Sheet'!J17 -> 70919.03 | G8: ='Data Sheet'!K17 -> 70866.22
B9: Sales Growth (y-o-y) | C9: ='Profit & Loss'!G28 -> 0.021682439 | D9: ='Profit & Loss'!H28 -> -0.0026372963 | E9: ='Profit & Loss'!I28 -> 0.23117498 | F9: ='Profit & Loss'!J28 -> 0.16942152 | G9: ='Profit & Loss'!K28 -> -0.00074465203
B10: Gross Profit Margin (%) | C10: ='Profit & Loss'!G31 -> 0.5658662 | D10: ='Profit & Loss'!H31 -> 0.51867748 | E10: ='Profit & Loss'!I31 -> 0.49650026 | F10: ='Profit & Loss'!J31 -> 0.53068887 | G10: ='Profit & Loss'!K31 -> 0.5476193
B11: EBITDA Margins (%) | C11: ='Profit & Loss'!G32 -> 0.39166716 | D11: ='Profit & Loss'!H32 -> 0.34644059 | E11: ='Profit & Loss'!I32 -> 0.34006606 | F11: ='Profit & Loss'!J32 -> 0.36244517 | G11: ='Profit & Loss'!K32 -> 0.37017016
B12: EBIT Margins (%) | C12: ='Profit & Loss'!G33 -> 0.35836109 | D12: ='Profit & Loss'!H33 -> 0.31303265 | E12: ='Profit & Loss'!I33 -> 0.31149944 | F12: ='Profit & Loss'!J33 -> 0.33693707 | G12: ='Profit & Loss'!K33 -> 0.34453891
B13: Net Profit Margins (%) | C13: ='Profit & Loss'!G34 -> 0.30991988 | D13: ='Profit & Loss'!H34 -> 0.26719187 | E13: ='Profit & Loss'!I34 -> 0.25134431 | F13: ='Profit & Loss'!J34 -> 0.27061368 | G13: ='Profit & Loss'!K34 -> 0.2886958
B14: Earning Per Share(In Rs) | C14: ='Profit & Loss'!G13 -> 12.451986 | D14: ='Profit & Loss'!H13 -> 10.692505 | E14: ='Profit & Loss'!I13 -> 12.368976 | F14: ='Profit & Loss'!J13 -> 15.442276 | G14: ='Profit & Loss'!K13 -> 16.387082
B15: EPS Growth (y-o-y) (%) | C15: ='Profit & Loss'!G35 -> 0.21219753 | D15: ='Profit & Loss'!H35 -> -0.14130126 | E15: ='Profit & Loss'!I35 -> 0.15678939 | F15: ='Profit & Loss'!J35 -> 0.2484684 | G15: ='Profit & Loss'!K35 -> 0.0611831
B16: Divident Per Share | C16: ='Profit & Loss'!G36 -> 10.149998 | D16: ='Profit & Loss'!H36 -> 10.75 | E16: ='Profit & Loss'!I36 -> 11.500004 | F16: ='Profit & Loss'!J36 -> 15.5 | G16: ='Profit & Loss'!K36 -> 13.749998
B17: DPS Growth (y-o-y) (%) | C17: ='Profit & Loss'!G37 -> 0.76521571 | D17: ='Profit & Loss'!H37 -> 0.059113555 | E17: ='Profit & Loss'!I37 -> 0.069767819 | F17: ='Profit & Loss'!J37 -> 0.34782561 | G17: ='Profit & Loss'!K37 -> -0.11290335
B19: Key Financial Ratio | C19: =C6 -> 43921 | D19: =D6 -> 44286 | E19: =E6 -> 44651 | F19: =F6 -> 45016 | G19: =G6 -> 45382 | I19: Volume - 5 Y
B21: Price to Eanings | C21: ='Profit & Loss'!G14 -> 12.925649 | D21: ='Profit & Loss'!H14 -> 19.155475 | E21: ='Profit & Loss'!I14 -> 18.995914 | F21: ='Profit & Loss'!J14 -> 23.2796 | G21: ='Profit & Loss'!K14 -> 24.502837 | H21: ='Profit & Loss'!L14 -> 24.69281
B22: EV/EBITDA | C22: ='Profit & Loss'!G44 -> 9.8659847 | D22: ='Profit & Loss'!H44 -> 14.516487 | E22: ='Profit & Loss'!I44 -> 13.826369 | F22: ='Profit & Loss'!J44 -> 17.203375 | G22: ='Profit & Loss'!K44 -> 18.846194 | H22: ='Profit & Loss'!L44 -> 0
B23: EV/Sales | C23: ='Profit & Loss'!G45 -> 3.8641822 | D23: ='Profit & Loss'!H45 -> 5.0291002 | E23: ='Profit & Loss'!I45 -> 4.7018788 | F23: ='Profit & Loss'!J45 -> 6.2352802 | G23: ='Profit & Loss'!K45 -> 6.9762986
B24: Price to Book Value | C24: ='Profit & Loss'!G47 -> 3.0309955 | D24: ='Profit & Loss'!H47 -> 4.1776297 | E24: ='Profit & Loss'!I47 -> 4.6360678 | F24: ='Profit & Loss'!J47 -> 6.460451 | G24: ='Profit & Loss'!K47 -> 6.7282022
B25: Return On Equity | C25: ='Balance Sheet'!G23 -> 0.23449465 | D25: ='Balance Sheet'!H23 -> 0.21809064 | E25: ='Balance Sheet'!I23 -> 0.24405605 | F25: ='Balance Sheet'!J23 -> 0.27751555 | G25: ='Balance Sheet'!K23 -> 0.2745887
B26: Return on Capital Employed | C26: ='Balance Sheet'!G24 -> 0.32261652 | D26: ='Balance Sheet'!H24 -> 0.28527066 | E26: ='Balance Sheet'!I24 -> 0.33733253 | F26: ='Balance Sheet'!J24 -> 0.39333609 | G26: ='Balance Sheet'!K24 -> 0.37734267
B28: Top 10 Shareholders | C28: ='Share Price'!R8 -> N.Shares(in Crs) | E28: ='Share Price'!S8 -> % Holding | F28: ='Share Price'!T8 -> Market Value(in Crs) | I28: Share Holder Pattern
B29: ='Share Price'!Q9 -> British American Tobacco plc | C29: ='Share Price'!R9 -> 318.27627 | E29: ='Share Price'!S9 -> 0.2544 | F29: ='Share Price'!T9 -> 130334.13
B30: ='Share Price'!Q10 -> Life Insurance Corporation of India (Investment Portfolio) | C30: ='Share Price'!R10 -> 189.68613 | E30: ='Share Price'!S10 -> 0.1516 | F30: ='Share Price'!T10 -> 77676.47
B31: ='Share Price'!Q11 -> The Specified Undertaking of the Unit Trust of India | C31: ='Share Price'!R11 -> 97.453143 | E31: ='Share Price'!S11 -> 0.07789 | F31: ='Share Price'!T11 -> 39907.062
B32: ='Share Price'!Q12 -> SBI Funds Management Ltd. | C32: ='Share Price'!R12 -> 40.665415 | E32: ='Share Price'!S12 -> 0.0325 | F32: ='Share Price'!T12 -> 16652.487
B33: ='Share Price'!Q13 -> General Insurance Corp. of India (Invt Port) | C33: ='Share Price'!R13 -> 21.699551 | E33: ='Share Price'!S13 -> 0.01734 | F33: ='Share Price'!T13 -> 8885.9661
B34: ='Share Price'!Q14 -> The New India Assurance Co. Ltd. (Investment Portfolio) | C34: ='Share Price'!R14 -> 18.444745 | E34: ='Share Price'!S14 -> 0.01474 | F34: ='Share Price'!T14 -> 7553.1231
B35: ='Share Price'!Q15 -> Government of Singapore | C35: ='Share Price'!R15 -> 18.005723 | E35: ='Share Price'!S15 -> 0.01439 | F35: ='Share Price'!T15 -> 7373.3437
B36: ='Share Price'!Q16 -> HDFC Asset Management Co. Ltd. (Invt Mgmt) | C36: ='Share Price'!R16 -> 14.687889 | E36: ='Share Price'!S16 -> 0.01174 | F36: ='Share Price'!T16 -> 6014.6907
B37: ='Share Price'!Q17 -> UTI Asset Management Co. Ltd. (Investment Management) | C37: ='Share Price'!R17 -> 14.108448 | E37: ='Share Price'!S17 -> 0.01128 | F37: ='Share Price'!T17 -> 5777.4095
B38: ='Share Price'!Q18 -> PPFAS Asset Management Private Ltd. | C38: ='Share Price'!R18 -> 10.636832 | E38: ='Share Price'!S18 -> 0.008502 | F38: ='Share Price'!T18 -> 4355.7827
B40: Marginal Remuration | C40: Designation | E40: Remuniration | F40: X of Median Salary | I40: Capital Structure
B42: Mr.Sanjeev Puri | C42: CMD | E42: 25.7 | F42: 400:1 | I42: Share Price as PerXXX | K42: ='Data Sheet'!B8 -> 397.45
B43: Mr.Supritam Dutta | C43: ED&CFO | E43: 5.66 | F43: 116:1 | I43: No of Shares | K43: ='Data Sheet'!B6 -> 1251.248
B44: Mr.Sumant Bhargavan | C44: ED | E44: 11.91 | F44: 191:1 | I44: Market Capitalization | K44: =K42*K43 -> 497308.5
B45: Mr.Hemant Malik | C45: ED | E45: 2.49 | F45: 43:1 | I45: Less: Cash& Equivalent | K45: =-'Data Sheet'!K69 -> -7217.68
I46: Add: Total Debt | K46: ='Data Sheet'!K59 -> 303.43
I47: Add: Minority Intrest | K47: =292.58 -> 292.58
...

Sheet Profit & Loss
A1: ='Data Sheet'!B1 -> ITC LTD | H1: =UPDATE | M1: SCREENER.IN
A3: Narration | B3: ='Data Sheet'!B16 -> 42094 | C3: ='Data Sheet'!C16 -> 42460 | D3: ='Data Sheet'!D16 -> 42825 | E3: ='Data Sheet'!E16 -> 43190 | F3: ='Data Sheet'!F16 -> 43555 | G3: ='Data Sheet'!G16 -> 43921 | H3: ='Data Sheet'!H16 -> 44286 | I3: ='Data Sheet'!I16 -> 44651 | ... K3: ='Data Sheet'!K16 -> 45382 | L3: Trailing | M3: Best Case | N3: Worst Case
A4: Sales | B4: ='Data Sheet'!B17 -> 38817.15 | C4: ='Data Sheet'!C17 -> 39192.1 | D4: ='Data Sheet'!D17 -> 42767.6 | E4: ='Data Sheet'!E17 -> 43448.94 | F4: ='Data Sheet'!F17 -> 48339.58 | G4: ='Data Sheet'!G17 -> 49387.7 | H4: ='Data Sheet'!H17 -> 49257.45 | I4: ='Data Sheet'!I17 -> 60644.54 | ... K4: ='Data Sheet'!K17 -> 70866.22 | L4: =SUM(Quarters!H4:K4) -> 75160.56 | M4: =$K4+M23*K4 -> 80000.932 | N4: =$K4+N23*L4 -> 75420.788
A5: Expenses | B5: =SUM('Data Sheet'!B18,'Data Sheet'!B20:B24, -1*'Data Sheet'!B19) -> 24565.53 | C5: =SUM('Data Sheet'!C18,'Data Sheet'!C20:C24, -1*'Data Sheet'!C19) -> 24660.61 | D5: =SUM('Data Sheet'!D18,'Data Sheet'!D20:D24, -1*'Data Sheet'!D19) -> 27298.09 | E5: =SUM('Data Sheet'!E18,'Data Sheet'!E20:E24, -1*'Data Sheet'!E19) -> 26928.35 | F5: =SUM('Data Sheet'!F18,'Data Sheet'!F20:F24, -1*'Data Sheet'!F19) -> 29802.19 | G5: =SUM('Data Sheet'!G18,'Data Sheet'!G20:G24, -1*'Data Sheet'!G19) -> 30044.16 | H5: =SUM('Data Sheet'!H18,'Data Sheet'!H20:H24, -1*'Data Sheet'!H19) -> 32192.67 | I5: =SUM('Data Sheet'!I18,'Data Sheet'!I20:I24, -1*'Data Sheet'!I19) -> 40021.39 | ... K5: =SUM('Data Sheet'!K18,'Data Sheet'!K20:K24, -1*'Data Sheet'!K19) -> 44633.66 | L5: =SUM(Quarters!H5:K5) -> 48871.95 | M5: =M4-M6 -> 51324.989 | N5: =N4-N6 -> 49041.159
A6: Operating Profit | B6: =B4-B5 -> 14251.62 | C6: =C4-C5 -> 14531.49 | D6: =D4-D5 -> 15469.51 | E6: =E4-E5 -> 16520.59 | F6: =F4-F5 -> 18537.39 | G6: =G4-G5 -> 19343.54 | H6: =H4-H5 -> 17064.78 | I6: =I4-I5 -> 20623.15 | ... K6: =K4-K5 -> 26232.56 | L6: =SUM(Quarters!H6:K6) -> 26288.61 | M6: =M4*M24 -> 28675.944 | N6: =N4*N24 -> 26379.629
A7: Other Income | B7: ='Data Sheet'!B25 -> 1229.35 | C7: ='Data Sheet'!C25 -> 1483.11 | D7: ='Data Sheet'!D25 -> 1758.63 | E7: ='Data Sheet'!E25 -> 2239.81 | F7: ='Data Sheet'!F25 -> 2080.44 | G7: ='Data Sheet'!G25 -> 2417.32 | H7: ='Data Sheet'!H25 -> 2576.95 | I7: ='Data Sheet'!I25 -> 1909.72 | ... K7: ='Data Sheet'!K25 -> 2803.77 | L7: =SUM(Quarters!H7:K7) -> 2874.95 | M7: 0 | N7: 0
A8: Depreciation | B8: ='Data Sheet'!B26 -> 1027.96 | C8: ='Data Sheet'!C26 -> 1077.4 | D8: ='Data Sheet'!D26 -> 1152.79 | E8: ='Data Sheet'!E26 -> 1236.28 | F8: ='Data Sheet'!F26 -> 1396.61 | G8: ='Data Sheet'!G26 -> 1644.91 | H8: ='Data Sheet'!H26 -> 1645.59 | I8: ='Data Sheet'!I26 -> 1732.41 | ... K8: ='Data Sheet'!K26 -> 1816.39 | L8: =SUM(Quarters!H8:K8) -> 1792.17 | M8: =+$L8 -> 1792.17 | N8: =+$L8 -> 1792.17
A9: Interest | B9: ='Data Sheet'!B27 -> 90.96 | C9: ='Data Sheet'!C27 -> 78.13 | D9: ='Data Sheet'!D27 -> 49.03 | E9: ='Data Sheet'!E27 -> 115.01 | F9: ='Data Sheet'!F27 -> 71.4 | G9: ='Data Sheet'!G27 -> 81.38 | H9: ='Data Sheet'!H27 -> 57.97 | I9: ='Data Sheet'!I27 -> 59.99 | ... K9: ='Data Sheet'!K27 -> 80.06 | L9: =SUM(Quarters!H9:K9) -> 48.39 | M9: =+$L9 -> 48.39 | N9: =+$L9 -> 48.39
A10: Profit before tax | B10: ='Data Sheet'!B28 -> 14362.05 | C10: ='Data Sheet'!C28 -> 14859.07 | D10: ='Data Sheet'!D28 -> 16026.32 | E10: ='Data Sheet'!E28 -> 17409.11 | F10: ='Data Sheet'!F28 -> 19149.82 | G10: ='Data Sheet'!G28 -> 20034.57 | H10: ='Data Sheet'!H28 -> 17938.17 | I10: ='Data Sheet'!I28 -> 20740.47 | ... K10: ='Data Sheet'!K28 -> 27139.88 | L10: =SUM(Quarters!H10:K10) -> 27323 | M10: =M6+M7-SUM(M8:M9) -> 26835.384 | N10: =N6+N7-SUM(N8:N9) -> 24539.069
A11: Tax | B11: ='Data Sheet'!B29 -> 4596.42 | C11: ='Data Sheet'!C29 -> 5358.21 | D11: ='Data Sheet'!D29 -> 5549.09 | E11: ='Data Sheet'!E29 -> 5916.43 | F11: ='Data Sheet'!F29 -> 6313.92 | G11: ='Data Sheet'!G29 -> 4441.79 | H11: ='Data Sheet'!H29 -> 4555.29 | I11: ='Data Sheet'!I29 -> 5237.34 | ... K11: ='Data Sheet'!K29 -> 6388.52 | L11: =SUM(Quarters!H11:K11) -> 6891.18 | M11: =IF($L10>0,$L11/$L10,0) -> 0.25221169 | N11: =IF($L10>0,$L11/$L10,0) -> 0.25221169
A12: Net profit | B12: ='Data Sheet'!B30 -> 9663.17 | C12: ='Data Sheet'!C30 -> 9344.45 | D12: ='Data Sheet'!D30 -> 10289.44 | E12: ='Data Sheet'!E30 -> 11271.2 | F12: ='Data Sheet'!F30 -> 12592.33 | G12: ='Data Sheet'!G30 -> 15306.23 | H12: ='Data Sheet'!H30 -> 13161.19 | I12: ='Data Sheet'!I30 -> 15242.66 | ... K12: ='Data Sheet'!K30 -> 20458.78 | L12: =SUM(Quarters!H12:K12) -> 20139.81 | M12: =M10-M11*M10 -> 20067.186 | N12: =N10-N11*N10 -> 18350.029
A13: EPS | B13: =IF('Data Sheet'!B93>0,B12/'Data Sheet'!B93,0) -> 8.0370364 | C13: =IF('Data Sheet'!C93>0,C12/'Data Sheet'!C93,0) -> 7.7413676 | D13: =IF('Data Sheet'!D93>0,D12/'Data Sheet'!D93,0) -> 8.4704875 | E13: =IF('Data Sheet'!E93>0,E12/'Data Sheet'!E93,0) -> 9.2354334 | F13: =IF('Data Sheet'!F93>0,F12/'Data Sheet'!F93,0) -> 10.272242 | G13: =IF('Data Sheet'!G93>0,G12/'Data Sheet'!G93,0) -> 12.451986 | H13: =IF('Data Sheet'!H93>0,H12/'Data Sheet'!H93,0) -> 10.692505 | I13: =IF('Data Sheet'!I93>0,I12/'Data Sheet'!I93,0) -> 12.368976 | ... K13: =IF('Data Sheet'!K93>0,K12/'Data Sheet'!K93,0) -> 16.387082 | L13: =IF('Data Sheet'!$B6>0,'Profit & Loss'!L12/'Data Sheet'!$B6,0) -> 16.095779 | M13: =IF('Data Sheet'!$B6>0,'Profit & Loss'!M12/'Data Sheet'!$B6,0) -> 16.037737 | N13: =IF('Data Sheet'!$B6>0,'Profit & Loss'!N12/'Data Sheet'!$B6,0) -> 14.665382
A14: Price to earning | B14: =IF(B15>0,B15/B13,"") -> 25.336454 | C14: =IF(C15>0,C15/C13,"") -> 26.497902 | D14: =IF(D15>0,D15/D13,"") -> 31.019466 | E14: =IF(E15>0,E15/E13,"") -> 25.93273 | F14: =IF(F15>0,F15/F13,"") -> 27.12553 | G14: =IF(G15>0,G15/G13,"") -> 12.925649 | H14: =IF(H15>0,H15/H13,"") -> 19.155475 | I14: =IF(I15>0,I15/I13,"") -> 18.995914 | ... K14: =IF(K15>0,K15/K13,"") -> 24.502837 | L14: =IF(L13>0,L15/L13,0) -> 24.69281 | M14: =M25 -> 24.69281 | N14: =N25 -> 20.592048
A15: Price | B15: ='Data Sheet'!B90 -> 203.63 | C15: ='Data Sheet'!C90 -> 205.13 | D15: ='Data Sheet'!D90 -> 262.75 | E15: ='Data Sheet'!E90 -> 239.5 | F15: ='Data Sheet'!F90 -> 278.64 | G15: ='Data Sheet'!G90 -> 160.95 | H15: ='Data Sheet'!H90 -> 204.82 | I15: ='Data Sheet'!I90 -> 234.96 | ... K15: ='Data Sheet'!K90 -> 401.53 | L15: ='Data Sheet'!B8 -> 397.45 | M15: =M13*M14 -> 396.0168 | N15: =N13*N14 -> 301.99024
A17: RATIOS:
A18: Dividend Payout | B18: =IF('Data Sheet'!B30>0, 'Data Sheet'!B31/'Data Sheet'!B30, 0) -> 0.51843132 | C18: =IF('Data Sheet'!C30>0, 'Data Sheet'!C31/'Data Sheet'!C30, 0) -> 0.73199814 | D18: =IF('Data Sheet'!D30>0, 'Data Sheet'!D31/'Data Sheet'!D30, 0) -> 0.56077104 | E18: =IF('Data Sheet'!E30>0, 'Data Sheet'!E31/'Data Sheet'!E30, 0) -> 0.5576345 | F18: =IF('Data Sheet'!F30>0, 'Data Sheet'!F31/'Data Sheet'!F30, 0) -> 0.55976138 | G18: =IF('Data Sheet'!G30>0, 'Data Sheet'!G31/'Data Sheet'!G30, 0) -> 0.81513083 | H18: =IF('Data Sheet'!H30>0, 'Data Sheet'!H31/'Data Sheet'!H30, 0) -> 1.0053772 | I18: =IF('Data Sheet'!I30>0, 'Data Sheet'!I31/'Data Sheet'!I30, 0) -> 0.92974586 | ... K18: =IF('Data Sheet'!K30>0, 'Data Sheet'!K31/'Data Sheet'!K30, 0) -> 0.83907545
A19: OPM | B19: =IF(B6>0,B6/B4,0) -> 0.36714751 | C19: =IF(C6>0,C6/C4,0) -> 0.370776 | D19: =IF(D6>0,D6/D4,0) -> 0.36171097 | E19: =IF(E6>0,E6/E4,0) -> 0.38022999 | F19: =IF(F6>0,F6/F4,0) -> 0.38348265 | G19: =IF(G6>0,G6/G4,0) -> 0.39166716 | H19: =IF(H6>0,H6/H4,0) -> 0.34644059 | I19: =IF(I6>0,I6/I4,0) -> 0.34006606 | ... L19: =IF(L6>0,L6/L4,0) -> 0.34976602
G22: TRENDS: | H22: 10 YEARS | I22: 7 YEARS | J22: 5 YEARS | K22: 3 YEARS | L22: RECENT | M22: BEST | N22: WORST
G23: Sales Growth | H23: =IF(B4=0,"",POWER($K4/B4,1/9)-1) -> 0.069168562 | I23: =IF(D4=0,"",POWER($K4/D4,1/7)-1) -> 0.074810884 | J23: =IF(F4=0,"",POWER($K4/F4,1/5)-1) -> 0.079511515 | K23: =IF(H4=0,"",POWER($K4/H4, 1/3)-1) -> 0.1289008 | L23: =IF(ISERROR(MAX(IF(J4=0,"",(K4-J4)/J4),IF(K4=0,"",(L4-K4)/K4))),"",MAX(IF(J4=0,"",(K4-J4)/J4),IF(K4=0,"",(L4-K4)/K4))) -> 0.060597842 | M23: =MAX(K23:L23) -> 0.1289008 | N23: =MIN(H23:L23) -> 0.060597842
G24: OPM | H24: =IF(SUM(B4:$K$4)=0,"",SUMPRODUCT(B19:$K$19,B4:$K$4)/SUM(B4:$K$4)) -> 0.36655785 | I24: =IF(SUM(E4:$K$4)=0,"",SUMPRODUCT(E19:$K$19,E4:$K$4)/SUM(E4:$K$4)) -> 0.36660643 | J24: =IF(SUM(G4:$K$4)=0,"",SUMPRODUCT(G19:$K$19,G4:$K$4)/SUM(G4:$K$4)) -> 0.36193079 | K24: =IF(SUM(I4:$K$4)=0, "", SUMPRODUCT(I19:$K$19,I4:$K$4)/SUM(I4:$K$4)) -> 0.35844512 | L24: =L19 -> 0.34976602 | M24: =MAX(K24:L24) -> 0.35844512 | N24: =MIN(H24:L24) -> 0.34976602
G25: Price to Earning | H25: =IF(ISERROR(AVERAGEIF(B14:$L14,">0")),"",AVERAGEIF(B14:$L14,">0")) -> 23.58767 | I25: =IF(ISERROR(AVERAGEIF(E14:$L14,">0")),"",AVERAGEIF(E14:$L14,">0")) -> 22.076318 | J25: =IF(ISERROR(AVERAGEIF(G14:$L14,">0")),"",AVERAGEIF(G14:$L14,">0")) -> 20.592048 | K25: =IF(ISERROR(AVERAGEIF(I14:$L14,">0")),"",AVERAGEIF(I14:$L14,">0")) -> 22.86779 | L25: =L14 -> 24.69281 | M25: =MAX(K25:L25) -> 24.69281 | N25: =MIN(H25:L25) -> 20.592048
A28: Sales Growth | C28: =C4/B4-1 -> 0.0096593902 | D28: =D4/C4-1 -> 0.09123012 | E28: =E4/D4-1 -> 0.015931219 | F28: =F4/E4-1 -> 0.11256063 | G28: =G4/F4-1 -> 0.021682439 | H28: =H4/G4-1 -> -0.0026372963 | I28: =I4/H4-1 -> 0.23117498 | J28: =J4/I4-1 -> 0.16942152 | K28: =K4/J4-1 -> -0.00074465203
A30: Gross Profit | B30: ='Data Sheet'!B17-SUM('Data Sheet'!B18:B21) -> 21429.61 | C30: ='Data Sheet'!C17-SUM('Data Sheet'!C18:C21) -> 23079.37 | D30: ='Data Sheet'!D17-SUM('Data Sheet'!D18:D21) -> 25635.35 | E30: ='Data Sheet'!E17-SUM('Data Sheet'!E18:E21) -> 27297.86 | F30: ='Data Sheet'!F17-SUM('Data Sheet'!F18:F21) -> 27895.13 | G30: ='Data Sheet'!G17-SUM('Data Sheet'!G18:G21) -> 27946.83 | H30: ='Data Sheet'!H17-SUM('Data Sheet'!H18:H21) -> 25548.73 | I30: ='Data Sheet'!I17-SUM('Data Sheet'!I18:I21) -> 30110.03 | ... K30: ='Data Sheet'!K17-SUM('Data Sheet'!K18:K21) -> 38807.71
A31: GPM | B31: =B30/B4 -> 0.55206552 | C31: =C30/C4 -> 0.58887812 | D31: =D30/D4 -> 0.59941054 | E31: =E30/E4 -> 0.62827448 | F31: =F30/F4 -> 0.57706604 | G31: =G30/G4 -> 0.5658662 | H31: =H30/H4 -> 0.51867748 | I31: =I30/I4 -> 0.49650026 | ... K31: =K30/K4 -> 0.5476193
A32: Ebitda Margin | B32: =B6/B4 -> 0.36714751 | C32: =C6/C4 -> 0.370776 | D32: =D6/D4 -> 0.36171097 | E32: =E6/E4 -> 0.38022999 | F32: =F6/F4 -> 0.38348265 | G32: =G6/G4 -> 0.39166716 | H32: =H6/H4 -> 0.34644059 | I32: =I6/I4 -> 0.34006606 | ... K32: =K6/K4 -> 0.37017016
A33: EBIT Margin | B33: =(B6-B8)/B4 -> 0.3406654 | C33: =(C6-C8)/C4 -> 0.34328576 | D33: =(D6-D8)/D4 -> 0.33475622 | E33: =(E6-E8)/E4 -> 0.35177636 | F33: =(F6-F8)/F4 -> 0.354591 | G33: =(G6-G8)/G4 -> 0.35836109 | H33: =(H6-H8)/H4 -> 0.31303265 | I33: =(I6-I8)/I4 -> 0.31149944 | ... K33: =(K6-K8)/K4 -> 0.34453891
A34: Net Profit Margin | B34: =B12/B4 -> 0.24894074 | C34: =C12/C4 -> 0.23842688 | D34: =D12/D4 -> 0.24058961 | E34: =E12/E4 -> 0.25941254 | F34: =F12/F4 -> 0.2604973 | G34: =G12/G4 -> 0.30991988 | H34: =H12/H4 -> 0.26719187 | I34: =I12/I4 -> 0.25134431 | ... K34: =K12/K4 -> 0.2886958
A35: EPS Growth | C35: =C13/B13-1 -> -0.03678829 | D35: =D13/C13-1 -> 0.094184898 | E35: =E13/D13-1 -> 0.090307187 | F35: =F13/E13-1 -> 0.11226415 | G35: =G13/F13-1 -> 0.21219753 | H35: =H13/G13-1 -> -0.14130126 | I35: =I13/H13-1 -> 0.15678939 | J35: =J13/I13-1 -> 0.2484684 | K35: =K13/J13-1 -> 0.0611831
A36: Divident Per Share | B36: =B13*B18 -> 4.1666514 | C36: =C13*C18 -> 5.6666667 | D36: =D13*D18 -> 4.7500041 | E36: =E13*E18 -> 5.1499963 | F36: =F13*F18 -> 5.7500041 | G36: =G13*G18 -> 10.149998 | H36: =H13*H18 -> 10.75 | I36: =I13*I18 -> 11.500004 | ... K36: =K13*K18 -> 13.749998
A37: Divident Growth | C37: =C36/B36-1 -> 0.36000498 | D37: =D36/C36-1 -> -0.16176398 | E37: =E36/D36-1 -> 0.084208811 | F37: =F36/E36-1 -> 0.11650645 | G37: =G36/F36-1 -> 0.76521571 | H37: =H36/G36-1 -> 0.059113555 | I37: =I36/H36-1 -> 0.069767819 | J37: =J36/I36-1 -> 0.34782561 | K37: =K36/J36-1 -> -0.11290335
A39: Market Capitaliztion | B39: ='Data Sheet'!B90*'Data Sheet'!B93 -> 244830.46 | C39: ='Data Sheet'!C90*'Data Sheet'!C93 -> 247608.32 | D39: ='Data Sheet'!D90*'Data Sheet'!D93 -> 319172.93 | E39: ='Data Sheet'!E90*'Data Sheet'!E93 -> 292292.99 | F39: ='Data Sheet'!F90*'Data Sheet'!F93 -> 341573.63 | G39: ='Data Sheet'!G90*'Data Sheet'!G93 -> 197842.96 | H39: ='Data Sheet'!H90*'Data Sheet'!H93 -> 252108.84 | I39: ='Data Sheet'!I90*'Data Sheet'!I93 -> 289548.26 | ... K39: ='Data Sheet'!K90*'Data Sheet'!K93 -> 501298.16
A40: Debt | B40: ='Balance Sheet'!B6 -> 268.8 | C40: ='Balance Sheet'!C6 -> 83.78 | D40: ='Balance Sheet'!D6 -> 45.72 | E40: ='Balance Sheet'!E6 -> 35.92 | F40: ='Balance Sheet'!F6 -> 13.44 | G40: ='Balance Sheet'!G6 -> 277.45 | H40: ='Balance Sheet'!H6 -> 270.83 | I40: ='Balance Sheet'!I6 -> 249.44 | ... K40: ='Balance Sheet'!K6 -> 303.43
A41: Cash | B41: ='Data Sheet'!B69 -> 7896.22 | C41: ='Data Sheet'!C69 -> 6063.3 | D41: ='Data Sheet'!D69 -> 2967.4 | E41: ='Data Sheet'!E69 -> 2899.6 | F41: ='Data Sheet'!F69 -> 4152.03 | G41: ='Data Sheet'!G69 -> 7277.34 | H41: ='Data Sheet'!H69 -> 4659.02 | I41: ='Data Sheet'!I69 -> 4654.42 | ... K41: ='Data Sheet'!K69 -> 7217.68
A42: ev | B42: =SUM(B39:B40)-B41 -> 237203.04 | C42: =SUM(C39:C40)-C41 -> 241628.8 | D42: =SUM(D39:D40)-D41 -> 316251.25 | E42: =SUM(E39:E40)-E41 -> 289429.31 | F42: =SUM(F39:F40)-F41 -> 337435.04 | G42: =SUM(G39:G40)-G41 -> 190843.07 | H42: =SUM(H39:H40)-H41 -> 247720.65 | I42: =SUM(I39:I40)-I41 -> 285143.28 | ... K42: =SUM(K39:K40)-K41 -> 494383.91
A44: EV EBITDA | B44: =B42/SUM('Profit & Loss'!B6) -> 16.643935 | C44: =C42/SUM('Profit & Loss'!C6) -> 16.627944 | D44: =D42/SUM('Profit & Loss'!D6) -> 20.443521 | E44: =E42/SUM('Profit & Loss'!E6) -> 17.519308 | F44: =F42/SUM('Profit & Loss'!F6) -> 18.202942 | G44: =G42/SUM('Profit & Loss'!G6) -> 9.8659847 | H44: =H42/SUM('Profit & Loss'!H6) -> 14.516487 | I44: =I42/SUM('Profit & Loss'!I6) -> 13.826369 | ... K44: =K42/SUM('Profit & Loss'!K6) -> 18.846194
A45: EV SALES | B45: =B42/B4 -> 6.1107793 | C45: =C42/C4 -> 6.1652425 | D45: =D42/D4 -> 7.3946458 | E45: =E42/E4 -> 6.6613663 | F45: =F42/F4 -> 6.9805125 | G45: =G42/G4 -> 3.8641822 | H45: =H42/H4 -> 5.0291002 | I45: =I42/I4 -> 4.7018788 | ... K45: =K42/K4 -> 6.9762986
A47: P/B | B47: =B39/SUM('Balance Sheet'!B4:B5) -> 7.7147212 | C47: =C39/SUM('Balance Sheet'!C4:C5) -> 5.8015723 | D47: =D39/SUM('Balance Sheet'!D4:D5) -> 6.8768107 | E47: =E39/SUM('Balance Sheet'!E4:E5) -> 5.5664135 | F47: =F39/SUM('Balance Sheet'!F4:F5) -> 5.7755936 | G47: =G39/SUM('Balance Sheet'!G4:G5) -> 3.0309955 | H47: =H39/SUM('Balance Sheet'!H4:H5) -> 4.1776297 | I47: =I39/SUM('Balance Sheet'!I4:I5) -> 4.6360678 | ... K47: =K39/SUM('Balance Sheet'!K4:K5) -> 6.7282022

Sheet Quarters
A1: ='Profit & Loss'!A1 -> ITC LTD | E1: =UPDATE | J1: SCREENER.IN
A3: Narration | B3: ='Data Sheet'!B41 -> 44834 | C3: ='Data Sheet'!C41 -> 44926 | D3: ='Data Sheet'!D41 -> 45016 | E3: ='Data Sheet'!E41 -> 45107 | F3: ='Data Sheet'!F41 -> 45199 | G3: ='Data Sheet'!G41 -> 45291 | H3: ='Data Sheet'!H41 -> 45382 | I3: ='Data Sheet'!I41 -> 45473 | ... K3: ='Data Sheet'!K41 -> 45657
A4: Sales | B4: ='Data Sheet'!B42 -> 17107.99 | C4: ='Data Sheet'!C42 -> 17704.52 | D4: ='Data Sheet'!D42 -> 17634.89 | E4: ='Data Sheet'!E42 -> 17164.46 | F4: ='Data Sheet'!F42 -> 17774.47 | G4: ='Data Sheet'!G42 -> 17195.24 | H4: ='Data Sheet'!H42 -> 17922.7 | I4: ='Data Sheet'!I42 -> 18457.33 | ... K4: ='Data Sheet'!K42 -> 18790.17
A5: Expenses | B5: ='Data Sheet'!B43 -> 10848.89 | C5: ='Data Sheet'!C43 -> 10999.82 | D5: ='Data Sheet'!D43 -> 11010.89 | E5: ='Data Sheet'!E43 -> 10494.39 | F5: ='Data Sheet'!F43 -> 11320.23 | G5: ='Data Sheet'!G43 -> 10985.01 | H5: ='Data Sheet'!H43 -> 11296.48 | I5: ='Data Sheet'!I43 -> 11708.92 | ... K5: ='Data Sheet'!K43 -> 12428.27
A6: Operating Profit | B6: ='Data Sheet'!B50 -> 6259.1 | C6: ='Data Sheet'!C50 -> 6704.7 | D6: ='Data Sheet'!D50 -> 6624 | E6: ='Data Sheet'!E50 -> 6670.07 | F6: ='Data Sheet'!F50 -> 6454.24 | G6: ='Data Sheet'!G50 -> 6210.23 | H6: ='Data Sheet'!H50 -> 6626.22 | I6: ='Data Sheet'!I50 -> 6748.41 | ... K6: ='Data Sheet'!K50 -> 6361.9
A7: Other Income | B7: ='Data Sheet'!B44 -> 454.68 | C7: ='Data Sheet'!C44 -> 595.43 | D7: ='Data Sheet'!D44 -> 682.52 | E7: ='Data Sheet'!E44 -> 722.3 | F7: ='Data Sheet'!F44 -> 673.5 | G7: ='Data Sheet'!G44 -> 820.26 | H7: ='Data Sheet'!H44 -> 681.78 | I7: ='Data Sheet'!I44 -> 699.46 | ... K7: ='Data Sheet'!K44 -> 803.4
A8: Depreciation | B8: ='Data Sheet'!B45 -> 462.38 | C8: ='Data Sheet'!C45 -> 447.11 | D8: ='Data Sheet'!D45 -> 461.4 | E8: ='Data Sheet'!E45 -> 442.46 | F8: ='Data Sheet'!F45 -> 453.04 | G8: ='Data Sheet'!G45 -> 384.04 | H8: ='Data Sheet'!H45 -> 461.44 | I8: ='Data Sheet'!I45 -> 498.57 | ... K8: ='Data Sheet'!K45 -> 415.98
A9: Interest | B9: ='Data Sheet'!B46 -> 12.59 | C9: ='Data Sheet'!C46 -> 9.21 | D9: ='Data Sheet'!D46 -> 12.15 | E9: ='Data Sheet'!E46 -> 9.9 | F9: ='Data Sheet'!F46 -> 9.87 | G9: ='Data Sheet'!G46 -> 11.94 | H9: ='Data Sheet'!H46 -> 12.59 | I9: ='Data Sheet'!I46 -> 11.25 | ... K9: ='Data Sheet'!K46 -> 9.82
A10: Profit before tax | B10: ='Data Sheet'!B47 -> 6238.81 | C10: ='Data Sheet'!C47 -> 6843.81 | D10: ='Data Sheet'!D47 -> 6832.97 | E10: ='Data Sheet'!E47 -> 6940.01 | F10: ='Data Sheet'!F47 -> 6664.83 | G10: ='Data Sheet'!G47 -> 6634.51 | H10: ='Data Sheet'!H47 -> 6833.97 | I10: ='Data Sheet'!I47 -> 6938.05 | ... K10: ='Data Sheet'!K47 -> 6739.5
A11: Tax | B11: ='Data Sheet'!B48 -> 1568.49 | C11: ='Data Sheet'!C48 -> 1773.72 | D11: ='Data Sheet'!D48 -> 1607.95 | E11: ='Data Sheet'!E48 -> 1759.89 | F11: ='Data Sheet'!F48 -> 1700.31 | G11: ='Data Sheet'!G48 -> 1227.99 | H11: ='Data Sheet'!H48 -> 1646.75 | I11: ='Data Sheet'!I48 -> 1761.06 | ... K11: ='Data Sheet'!K48 -> 1726.32
A12: Net profit | B12: ='Data Sheet'!B49 -> 4619.77 | C12: ='Data Sheet'!C49 -> 5006.65 | D12: ='Data Sheet'!D49 -> 5175.48 | E12: ='Data Sheet'!E49 -> 5104.93 | F12: ='Data Sheet'!F49 -> 4898.07 | G12: ='Data Sheet'!G49 -> 5335.23 | H12: ='Data Sheet'!H49 -> 5120.55 | I12: ='Data Sheet'!I49 -> 5091.59 | ... K12: ='Data Sheet'!K49 -> 4934.8
A14: OPM | B14: =IF(B4>0,B6/B4,"") -> 0.36585829 | C14: =IF(C4>0,C6/C4,"") -> 0.3786999 | D14: =IF(D4>0,D6/D4,"") -> 0.37561901 | E14: =IF(E4>0,E6/E4,"") -> 0.38859772 | F14: =IF(F4>0,F6/F4,"") -> 0.36311856 | G14: =IF(G4>0,G6/G4,"") -> 0.36115983 | H14: =IF(H4>0,H6/H4,"") -> 0.36971104 | I14: =IF(I4>0,I6/I4,"") -> 0.36562222 | ... K14: =IF(K4>0,K6/K4,"") -> 0.33857597

Sheet Balance Sheet
A1: ='Profit & Loss'!A1 -> ITC LTD | E1: =UPDATE | J1: SCREENER.IN
A3: Narration | B3: ='Data Sheet'!B56 -> 42094 | C3: ='Data Sheet'!C56 -> 42460 | D3: ='Data Sheet'!D56 -> 42825 | E3: ='Data Sheet'!E56 -> 43190 | F3: ='Data Sheet'!F56 -> 43555 | G3: ='Data Sheet'!G56 -> 43921 | H3: ='Data Sheet'!H56 -> 44286 | I3: ='Data Sheet'!I56 -> 44651 | ... K3: ='Data Sheet'!K56 -> 45382
A4: Equity Share Capital | B4: ='Data Sheet'!B57 -> 801.55 | C4: ='Data Sheet'!C57 -> 804.72 | D4: ='Data Sheet'!D57 -> 1214.74 | E4: ='Data Sheet'!E57 -> 1220.43 | F4: ='Data Sheet'!F57 -> 1225.86 | G4: ='Data Sheet'!G57 -> 1229.22 | H4: ='Data Sheet'!H57 -> 1230.88 | I4: ='Data Sheet'!I57 -> 1232.33 | ... K4: ='Data Sheet'!K57 -> 1248.47
A5: Reserves | B5: ='Data Sheet'!B58 -> 30933.94 | C5: ='Data Sheet'!C58 -> 41874.8 | D5: ='Data Sheet'!D58 -> 45198.19 | E5: ='Data Sheet'!E58 -> 51289.68 | F5: ='Data Sheet'!F58 -> 57915.01 | G5: ='Data Sheet'!G58 -> 64044.04 | H5: ='Data Sheet'!H58 -> 59116.46 | I5: ='Data Sheet'!I58 -> 61223.24 | ... K5: ='Data Sheet'!K58 -> 73258.53
A6: Borrowings | B6: ='Data Sheet'!B59 -> 268.8 | C6: ='Data Sheet'!C59 -> 83.78 | D6: ='Data Sheet'!D59 -> 45.72 | E6: ='Data Sheet'!E59 -> 35.92 | F6: ='Data Sheet'!F59 -> 13.44 | G6: ='Data Sheet'!G59 -> 277.45 | H6: ='Data Sheet'!H59 -> 270.83 | I6: ='Data Sheet'!I59 -> 249.44 | ... K6: ='Data Sheet'!K59 -> 303.43
A7: Other Liabilities | B7: ='Data Sheet'!B60 -> 13947.93 | C7: ='Data Sheet'!C60 -> 8888.04 | D7: ='Data Sheet'!D60 -> 9439.67 | E7: ='Data Sheet'!E60 -> 11694.85 | F7: ='Data Sheet'!F60 -> 12584.73 | G7: ='Data Sheet'!G60 -> 11760.04 | H7: ='Data Sheet'!H60 -> 13142.59 | I7: ='Data Sheet'!I60 -> 14491.01 | ... K7: ='Data Sheet'!K60 -> 16943.54
A8: Total | B8: ='Data Sheet'!B61 -> 45952.22 | C8: ='Data Sheet'!C61 -> 51651.34 | D8: ='Data Sheet'!D61 -> 55898.32 | E8: ='Data Sheet'!E61 -> 64240.88 | F8: ='Data Sheet'!F61 -> 71739.04 | G8: ='Data Sheet'!G61 -> 77310.75 | H8: ='Data Sheet'!H61 -> 73760.76 | I8: ='Data Sheet'!I61 -> 77196.02 | ... K8: ='Data Sheet'!K61 -> 91753.97
A10: Net Block | B10: ='Data Sheet'!B62 -> 15303.28 | C10: ='Data Sheet'!C62 -> 15106.63 | D10: ='Data Sheet'!D62 -> 15893.48 | E10: ='Data Sheet'!E62 -> 16523.96 | F10: ='Data Sheet'!F62 -> 19374.19 | G10: ='Data Sheet'!G62 -> 21713.34 | H10: ='Data Sheet'!H62 -> 23298.48 | I10: ='Data Sheet'!I62 -> 24231.59 | ... K10: ='Data Sheet'!K62 -> 27820.22
A11: Capital Work in Progress | B11: ='Data Sheet'!B63 -> 2700.2 | C11: ='Data Sheet'!C63 -> 2559.72 | D11: ='Data Sheet'!D63 -> 3729.89 | E11: ='Data Sheet'!E63 -> 5508.33 | F11: ='Data Sheet'!F63 -> 4136.42 | G11: ='Data Sheet'!G63 -> 3256.46 | H11: ='Data Sheet'!H63 -> 4011.29 | I11: ='Data Sheet'!I63 -> 3225.54 | ... K11: ='Data Sheet'!K63 -> 2860.78
A12: Investments | B12: ='Data Sheet'!B64 -> 6942.77 | C12: ='Data Sheet'!C64 -> 11747.59 | D12: ='Data Sheet'!D64 -> 17581.38 | E12: ='Data Sheet'!E64 -> 22052.86 | F12: ='Data Sheet'!F64 -> 25043.49 | G12: ='Data Sheet'!G64 -> 28663.35 | H12: ='Data Sheet'!H64 -> 24870.87 | I12: ='Data Sheet'!I64 -> 24841.01 | ... K12: ='Data Sheet'!K64 -> 31114.02
A13: Other Assets | B13: ='Data Sheet'!B65 -> 21005.97 | C13: ='Data Sheet'!C65 -> 22237.4 | D13: ='Data Sheet'!D65 -> 18693.57 | E13: ='Data Sheet'!E65 -> 20155.73 | F13: ='Data Sheet'!F65 -> 23184.94 | G13: ='Data Sheet'!G65 -> 23677.6 | H13: ='Data Sheet'!H65 -> 21580.12 | I13: ='Data Sheet'!I65 -> 24897.88 | ... K13: ='Data Sheet'!K65 -> 29958.95
A14: Total | B14: ='Data Sheet'!B66 -> 45952.22 | C14: ='Data Sheet'!C66 -> 51651.34 | D14: ='Data Sheet'!D66 -> 55898.32 | E14: ='Data Sheet'!E66 -> 64240.88 | F14: ='Data Sheet'!F66 -> 71739.04 | G14: ='Data Sheet'!G66 -> 77310.75 | H14: ='Data Sheet'!H66 -> 73760.76 | I14: ='Data Sheet'!I66 -> 77196.02 | ... K14: ='Data Sheet'!K66 -> 91753.97
A16: Working Capital | B16: =B13-B7 -> 7058.04 | C16: =C13-C7 -> 13349.36 | D16: =D13-D7 -> 9253.9 | E16: =E13-E7 -> 8460.88 | F16: =F13-F7 -> 10600.21 | G16: =G13-G7 -> 11917.56 | H16: =H13-H7 -> 8437.53 | I16: =I13-I7 -> 10406.87 | ... K16: =K13-K7 -> 13015.41
A17: Debtors | B17: ='Data Sheet'!B67 -> 1982.07 | C17: ='Data Sheet'!C67 -> 1917.18 | D17: ='Data Sheet'!D67 -> 2474.29 | E17: ='Data Sheet'!E67 -> 2682.29 | F17: ='Data Sheet'!F67 -> 4035.28 | G17: ='Data Sheet'!G67 -> 2562.48 | H17: ='Data Sheet'!H67 -> 2501.7 | I17: ='Data Sheet'!I67 -> 2461.9 | ... K17: ='Data Sheet'!K67 -> 4025.82
A18: Inventory | B18: ='Data Sheet'!B68 -> 8586.87 | C18: ='Data Sheet'!C68 -> 9062.1 | D18: ='Data Sheet'!D68 -> 8116.1 | E18: ='Data Sheet'!E68 -> 7495.09 | F18: ='Data Sheet'!F68 -> 7859.56 | G18: ='Data Sheet'!G68 -> 8879.33 | H18: ='Data Sheet'!H68 -> 10397.16 | I18: ='Data Sheet'!I68 -> 10864.15 | ... K18: ='Data Sheet'!K68 -> 14152.88
A20: Debtor Days | B20: =IF('Profit & Loss'!B4>0,'Balance Sheet'!B17/('Profit & Loss'!B4/365),0) -> 18.637524 | C20: =IF('Profit & Loss'!C4>0,'Balance Sheet'!C17/('Profit & Loss'!C4/365),0) -> 17.854892 | D20: =IF('Profit & Loss'!D4>0,'Balance Sheet'!D17/('Profit & Loss'!D4/365),0) -> 21.116823 | E20: =IF('Profit & Loss'!E4>0,'Balance Sheet'!E17/('Profit & Loss'!E4/365),0) -> 22.53302 | F20: =IF('Profit & Loss'!F4>0,'Balance Sheet'!F17/('Profit & Loss'!F4/365),0) -> 30.469383 | G20: =IF('Profit & Loss'!G4>0,'Balance Sheet'!G17/('Profit & Loss'!G4/365),0) -> 18.938019 | H20: =IF('Profit & Loss'!H4>0,'Balance Sheet'!H17/('Profit & Loss'!H4/365),0) -> 18.537714 | I20: =IF('Profit & Loss'!I4>0,'Balance Sheet'!I17/('Profit & Loss'!I4/365),0) -> 14.817385 | ... K20: =IF('Profit & Loss'!K4>0,'Balance Sheet'!K17/('Profit & Loss'!K4/365),0) -> 20.735187
A21: Inventory Turnover | B21: =IF('Balance Sheet'!B18>0,'Profit & Loss'!B4/'Balance Sheet'!B18,0) -> 4.5205238 | C21: =IF('Balance Sheet'!C18>0,'Profit & Loss'!C4/'Balance Sheet'!C18,0) -> 4.3248364 | D21: =IF('Balance Sheet'!D18>0,'Profit & Loss'!D4/'Balance Sheet'!D18,0) -> 5.2694767 | E21: =IF('Balance Sheet'!E18>0,'Profit & Loss'!E4/'Balance Sheet'!E18,0) -> 5.7969871 | F21: =IF('Balance Sheet'!F18>0,'Profit & Loss'!F4/'Balance Sheet'!F18,0) -> 6.1504181 | G21: =IF('Balance Sheet'!G18>0,'Profit & Loss'!G4/'Balance Sheet'!G18,0) -> 5.5620976 | H21: =IF('Balance Sheet'!H18>0,'Profit & Loss'!H4/'Balance Sheet'!H18,0) -> 4.737587 | I21: =IF('Balance Sheet'!I18>0,'Profit & Loss'!I4/'Balance Sheet'!I18,0) -> 5.5820787 | ... K21: =IF('Balance Sheet'!K18>0,'Profit & Loss'!K4/'Balance Sheet'!K18,0) -> 5.0071943
A23: Return on Equity | B23: =IF(SUM('Balance Sheet'!B4:B5)>0,'Profit & Loss'!B12/SUM('Balance Sheet'!B4:B5),"") -> 0.30449097 | C23: =IF(SUM('Balance Sheet'!C4:C5)>0,'Profit & Loss'!C12/SUM('Balance Sheet'!C4:C5),"") -> 0.21894459 | D23: =IF(SUM('Balance Sheet'!D4:D5)>0,'Profit & Loss'!D12/SUM('Balance Sheet'!D4:D5),"") -> 0.22169339 | E23: =IF(SUM('Balance Sheet'!E4:E5)>0,'Profit & Loss'!E12/SUM('Balance Sheet'!E4:E5),"") -> 0.21464819 | F23: =IF(SUM('Balance Sheet'!F4:F5)>0,'Profit & Loss'!F12/SUM('Balance Sheet'!F4:F5),"") -> 0.21292095 | G23: =IF(SUM('Balance Sheet'!G4:G5)>0,'Profit & Loss'!G12/SUM('Balance Sheet'!G4:G5),"") -> 0.23449465 | H23: =IF(SUM('Balance Sheet'!H4:H5)>0,'Profit & Loss'!H12/SUM('Balance Sheet'!H4:H5),"") -> 0.21809064 | I23: =IF(SUM('Balance Sheet'!I4:I5)>0,'Profit & Loss'!I12/SUM('Balance Sheet'!I4:I5),"") -> 0.24405605 | ... K23: =IF(SUM('Balance Sheet'!K4:K5)>0,'Profit & Loss'!K12/SUM('Balance Sheet'!K4:K5),"") -> 0.2745887
A24: Return on Capital Emp | C24: =IF((B4+B5+B6+C4+C5+C6)>0,('Profit & Loss'!C10+'Profit & Loss'!C9)*2/(B4+B5+B6+C4+C5+C6),"") -> 0.3995635 | D24: =IF((C4+C5+C6+D4+D5+D6)>0,('Profit & Loss'!D10+'Profit & Loss'!D9)*2/(C4+C5+C6+D4+D5+D6),"") -> 0.36034518 | E24: =IF((D4+D5+D6+E4+E5+E6)>0,('Profit & Loss'!E10+'Profit & Loss'!E9)*2/(D4+D5+D6+E4+E5+E6),"") -> 0.35400589 | F24: =IF((E4+E5+E6+F4+F5+F6)>0,('Profit & Loss'!F10+'Profit & Loss'!F9)*2/(E4+E5+E6+F4+F5+F6),"") -> 0.34415688 | G24: =IF((F4+F5+F6+G4+G5+G6)>0,('Profit & Loss'!G10+'Profit & Loss'!G9)*2/(F4+F5+F6+G4+G5+G6),"") -> 0.32261652 | H24: =IF((G4+G5+G6+H4+H5+H6)>0,('Profit & Loss'!H10+'Profit & Loss'!H9)*2/(G4+G5+G6+H4+H5+H6),"") -> 0.28527066 | I24: =IF((H4+H5+H6+I4+I5+I6)>0,('Profit & Loss'!I10+'Profit & Loss'!I9)*2/(H4+H5+H6+I4+I5+I6),"") -> 0.33733253 | J24: =IF((I4+I5+I6+J4+J5+J6)>0,('Profit & Loss'!J10+'Profit & Loss'!J9)*2/(I4+I5+I6+J4+J5+J6),"") -> 0.39333609 | K24: =IF((J4+J5+J6+K4+K5+K6)>0,('Profit & Loss'!K10+'Profit & Loss'!K9)*2/(J4+J5+J6+K4+K5+K6),"") -> 0.37734267

Sheet Cash Flow
A1: ='Balance Sheet'!A1 -> ITC LTD | E1: =UPDATE | J1: SCREENER.IN
A3: Narration | B3: ='Data Sheet'!B81 -> 42094 | C3: ='Data Sheet'!C81 -> 42460 | D3: ='Data Sheet'!D81 -> 42825 | E3: ='Data Sheet'!E81 -> 43190 | F3: ='Data Sheet'!F81 -> 43555 | G3: ='Data Sheet'!G81 -> 43921 | H3: ='Data Sheet'!H81 -> 44286 | I3: ='Data Sheet'!I81 -> 44651 | ... K3: ='Data Sheet'!K81 -> 45382
A4: Cash from Operating Activity | B4: ='Data Sheet'!B82 -> 9843.2 | C4: ='Data Sheet'!C82 -> 9799.04 | D4: ='Data Sheet'!D82 -> 10627.31 | E4: ='Data Sheet'!E82 -> 13169.4 | F4: ='Data Sheet'!F82 -> 12583.41 | G4: ='Data Sheet'!G82 -> 14689.66 | H4: ='Data Sheet'!H82 -> 12526.97 | I4: ='Data Sheet'!I82 -> 15775.51 | ... K4: ='Data Sheet'!K82 -> 17178.86
A5: Cash from Investing Activity | B5: ='Data Sheet'!B83 -> -5275.43 | C5: ='Data Sheet'!C83 -> -3920.73 | D5: ='Data Sheet'!D83 -> -3250.93 | E5: ='Data Sheet'!E83 -> -7113.89 | F5: ='Data Sheet'!F83 -> -5545.68 | G5: ='Data Sheet'!G83 -> -6174.02 | H5: ='Data Sheet'!H83 -> 5739.98 | I5: ='Data Sheet'!I83 -> -2238.49 | ... K5: ='Data Sheet'!K83 -> 1562.77
A6: Cash from Financing Activity | B6: ='Data Sheet'!B84 -> -4661.03 | C6: ='Data Sheet'!C84 -> -5612.52 | D6: ='Data Sheet'!D84 -> -7301.03 | E6: ='Data Sheet'!E84 -> -6221.13 | F6: ='Data Sheet'!F84 -> -6868.64 | G6: ='Data Sheet'!G84 -> -8181.48 | H6: ='Data Sheet'!H84 -> -18633.83 | I6: ='Data Sheet'!I84 -> -13580.5 | ... K6: ='Data Sheet'!K84 -> -18550.96
A7: Net Cash Flow | B7: ='Data Sheet'!B85 -> -93.26 | C7: ='Data Sheet'!C85 -> 265.79 | D7: ='Data Sheet'!D85 -> 75.35 | E7: ='Data Sheet'!E85 -> -165.62 | F7: ='Data Sheet'!F85 -> 169.09 | G7: ='Data Sheet'!G85 -> 334.16 | H7: ='Data Sheet'!H85 -> -366.88 | I7: ='Data Sheet'!I85 -> -43.48 | ... K7: ='Data Sheet'!K85 -> 190.67

Sheet Customization
A1: How to use it?
A3: You can customize this workbook as you want.
B4: You can add custom formating, add conditional formating, add your own formulas… do ANYTHING.
B5: Please don't edit the "Data Sheet" only.
A7: After customization, you can upload this back on Screener.
B8: Upload on: | C8: https://www.screener.in/excel/
A10: Download your customized workbooks now onwards.
B11: Now whenever you will "Export to excel" from Screener, it will export your customized file.
A14: TESTING:
B15: This is a testing feature currently.
B16: You can report any formula errors on the worksheet at: support@screener.in

Sheet Data Sheet
A1: COMPANY NAME | B1: ITC LTD | E1: =IF(B2<>B3, "A NEW VERSION OF THE WORKSHEET IS AVAILABLE", "")
A2: LATEST VERSION | B2: 2.1 | E2: PLEASE DO NOT MAKE ANY CHANGES TO THIS SHEET
A3: CURRENT VERSION | B3: 2.1
A5: META
A6: Number of shares | B6: =IF(B9>0, B9/B8, 0) -> 1251.248
A7: Face Value | B7: 1
A8: Current Price | B8: 397.45
A9: Market Capitalization | B9: 497308.5
A15: PROFIT & LOSS
A16: Report Date | B16: 42094 | C16: 42460 | D16: 42825 | E16: 43190 | F16: 43555 | G16: 43921 | H16: 44286 | I16: 44651 | J16: 45016 | K16: 45382
A17: Sales | B17: 38817.15 | C17: 39192.1 | D17: 42767.6 | E17: 43448.94 | F17: 48339.58 | G17: 49387.7 | H17: 49257.45 | I17: 60644.54 | J17: 70919.03 | K17: 70866.22
A18: Raw Material Cost | B18: 15007.9 | C18: 13763.88 | D18: 15456.59 | E18: 14827.72 | F18: 17623.52 | G18: 18048.6 | H18: 20776.71 | I18: 27071.07 | J18: 29364.36 | K18: 27835.9
A19: Change in Inventory | B19: 235.72 | C19: 195.38 | D19: -592.57 | E19: -1027.76 | F19: 203.19 | G19: 703.13 | H19: 645.27 | I19: 686 | J19: 358.59 | K19: 588.69
A20: Power and Fuel | B20: 610.67 | C20: 571.88 | D20: 584.33 | E20: 653.5 | F20: 746.73 | G20: 780.85 | H20: 699.56 | I20: 889.77 | J20: 1232.34 | K20: 1120.25
A21: Other Mfr. Exp | B21: 1533.25 | C21: 1581.59 | D21: 1683.9 | E21: 1697.62 | F21: 1871.01 | G21: 1908.29 | H21: 1587.18 | I21: 1887.67 | J21: 2327.8 | K21: 2513.67
A22: Employee Cost | B22: 2772.28 | C22: 3440.97 | D22: 3631.73 | E22: 3760.9 | F22: 4177.88 | G22: 4295.79 | H22: 4463.33 | I22: 4890.55 | J22: 5736.22 | K22: 6134.35
A23: Selling and admin | B23: 3876.19 | C23: 4261.78 | D23: 4179.74 | E23: 3954.87 | F23: 4546.39 | G23: 4488.63 | H23: 4236.77 | I23: 4858.38 | J23: 5604.08 | K23: 6178.63
A24: Other Expenses | B24: 1000.96 | C24: 1235.89 | D24: 1169.23 | E24: 1005.98 | F24: 1039.85 | G24: 1225.13 | H24: 1074.39 | I24: 1109.95 | J24: 1308.56 | K24: 1439.55
A25: Other Income | B25: 1229.35 | C25: 1483.11 | D25: 1758.63 | E25: 2239.81 | F25: 2080.44 | G25: 2417.32 | H25: 2576.95 | I25: 1909.72 | J25: 2097.64 | K25: 2803.77
A26: Depreciation | B26: 1027.96 | C26: 1077.4 | D26: 1152.79 | E26: 1236.28 | F26: 1396.61 | G26: 1644.91 | H26: 1645.59 | I26: 1732.41 | J26: 1809.01 | K26: 1816.39
A27: Interest | B27: 90.96 | C27: 78.13 | D27: 49.03 | E27: 115.01 | F27: 71.4 | G27: 81.38 | H27: 57.97 | I27: 59.99 | J27: 77.77 | K27: 80.06
... A31: Dividend Amount | B31: 5009.69 | C31: 6840.12 | D31: 5770.02 | E31: 6285.21 | F31: 7048.7 | G31: 12476.58 | H31: 13231.96 | I31: 14171.8 | J31: 19263.4 | K31: 17166.46
A40: Quarters
A41: Report Date | B41: 44834 | C41: 44926 | D41: 45016 | E41: 45107 | F41: 45199 | G41: 45291 | H41: 45382 | I41: 45473 | J41: 45565 | K41: 45657
A42: Sales | B42: 17107.99 | C42: 17704.52 | D42: 17634.89 | E42: 17164.46 | F42: 17774.47 | G42: 17195.24 | H42: 17922.7 | I42: 18457.33 | J42: 19990.36 | K42: 18790.17
A43: Expenses | B43: 10848.89 | C43: 10999.82 | D43: 11010.89 | E43: 10494.39 | F43: 11320.23 | G43: 10985.01 | H43: 11296.48 | I43: 11708.92 | J43: 13438.28 | K43: 12428.27
A44: Other Income | B44: 454.68 | C44: 595.43 | D44: 682.52 | E44: 722.3 | F44: 673.5 | G44: 820.26 | H44: 681.78 | I44: 699.46 | J44: 690.31 | K44: 803.4
A45: Depreciation | B45: 462.38 | C45: 447.11 | D45: 461.4 | E45: 442.46 | F45: 453.04 | G45: 384.04 | H45: 461.44 | I45: 498.57 | J45: 416.18 | K45: 415.98
A46: Interest | B46: 12.59 | C46: 9.21 | D46: 12.15 | E46: 9.9 | F46: 9.87 | G46: 11.94 | H46: 12.59 | I46: 11.25 | J46: 14.73 | K46: 9.82
A47: Profit before tax | B47: 6238.81 | C47: 6843.81 | D47: 6832.97 | E47: 6940.01 | F47: 6664.83 | G47: 6634.51 | H47: 6833.97 | I47: 6938.05 | J47: 6811.48 | K47: 6739.5
A48: Tax | B48: 1568.49 | C48: 1773.72 | D48: 1607.95 | E48: 1759.89 | F48: 1700.31 | G48: 1227.99 | H48: 1646.75 | I48: 1761.06 | J48: 1757.05 | K48: 1726.32
A49: Net profit | B49: 4619.77 | C49: 5006.65 | D49: 5175.48 | E49: 5104.93 | F49: 4898.07 | G49: 5335.23 | H49: 5120.55 | I49: 5091.59 | J49: 4992.87 | K49: 4934.8
A50: Operating Profit | B50: 6259.1 | C50: 6704.7 | D50: 6624 | E50: 6670.07 | F50: 6454.24 | G50: 6210.23 | H50: 6626.22 | I50: 6748.41 | J50: 6552.08 | K50: 6361.9
A55: BALANCE SHEET
A56: Report Date | B56: 42094 | C56: 42460 | D56: 42825 | E56: 43190 | F56: 43555 | G56: 43921 | H56: 44286 | I56: 44651 | J56: 45016 | K56: 45382
A57: Equity Share Capital | B57: 801.55 | C57: 804.72 | D57: 1214.74 | E57: 1220.43 | F57: 1225.86 | G57: 1229.22 | H57: 1230.88 | I57: 1232.33 | J57: 1242.8 | K57: 1248.47
A58: Reserves | B58: 30933.94 | C58: 41874.8 | D58: 45198.19 | E58: 51289.68 | F58: 57915.01 | G58: 64044.04 | H58: 59116.46 | I58: 61223.24 | J58: 67912.46 | K58: 73258.53
A59: Borrowings | B59: 268.8 | C59: 83.78 | D59: 45.72 | E59: 35.92 | F59: 13.44 | G59: 277.45 | H59: 270.83 | I59: 249.44 | J59: 306.04 | K59: 303.43
A60: Other Liabilities | B60: 13947.93 | C60: 8888.04 | D60: 9439.67 | E60: 11694.85 | F60: 12584.73 | G60: 11760.04 | H60: 13142.59 | I60: 14491.01 | J60: 16369.66 | K60: 16943.54
A61: Total | B61: 45952.22 | C61: 51651.34 | D61: 55898.32 | E61: 64240.88 | F61: 71739.04 | G61: 77310.75 | H61: 73760.76 | I61: 77196.02 | J61: 85830.96 | K61: 91753.97
...

Sheet Share Price
B2: Date | C2: Share Price | D2: volume
B3: Apr 11, 2025 | C3: 421.55 | D3: 8936353 | S3: 10000000
B4: Apr 9, 2025 | C4: 416.3 | D4: 21785572
B5: Apr 8, 2025 | C5: 412.55 | D5: 18600796
B6: Apr 7, 2025 | C6: 406.05 | D6: 26762866
B7: Apr 4, 2025 | C7: 409.7 | D7: 18627592 | M7: 3182762693 | N7: 0.2544 | O7: 16 445 M ₹
B8: Apr 3, 2025 | C8: 409.4 | D8: 7059566 | L8: British American Tobacco plc | Q8: Share Holder Name | R8: N.Shares(in Crs) | S8: % Holding | T8: Market Value(in Crs)
B9: Apr 2, 2025 | C9: 409.05 | D9: 8001323 | L9: Life Insurance Corporation of India (Investment Portfolio) | M9: 1896861285 | N9: 0.1516 | O9: 9 801 M ₹ | Q9: British American Tobacco plc | R9: 318.27627 | S9: 0.2544 | T9: =R9*409.5 -> 130334.13
B10: Apr 1, 2025 | C10: 406.65 | D10: 15206240 | L10: The Specified Undertaking of the Unit Trust of India | M10: 974531427 | N10: 0.07789 | O10: 5 035 M ₹ | Q10: Life Insurance Corporation of India (Investment Portfolio) | R10: 189.68613 | S10: 0.1516 | T10: =R10*409.5 -> 77676.47
B11: Mar 28, 2025 | C11: 409.75 | D11: 12981873 | L11: SBI Funds Management Ltd. | M11: 406654150 | N11: 0.0325 | O11: 2 101 M ₹ | Q11: The Specified Undertaking of the Unit Trust of India | R11: 97.453143 | S11: 0.07789 | T11: =R11*409.5 -> 39907.062
B12: Mar 27, 2025 | C12: 409.45 | D12: 18642328 | L12: General Insurance Corp. of India (Invt Port) | M12: 216995508 | N12: 0.01734 | O12: 1 121 M ₹ | Q12: SBI Funds Management Ltd. | R12: 40.665415 | S12: 0.0325 | T12: =R12*409.5 -> 16652.487
B13: Mar 26, 2025 | C13: 407.35 | D13: 13891436 | L13: The New India Assurance Co. Ltd. (Investment Portfolio) | M13: 184447450 | N13: 0.01474 | O13: 953 M ₹ | Q13: General Insurance Corp. of India (Invt Port) | R13: 21.699551 | S13: 0.01734 | T13: =R13*409.5 -> 8885.9661
B14: Mar 25, 2025 | C14: 409.8 | D14: 20338110 | L14: Government of Singapore | M14: 180057232 | N14: 0.01439 | O14: 930 M ₹ | Q14: The New India Assurance Co. Ltd. (Investment Portfolio) | R14: 18.444745 | S14: 0.01474 | T14: =R14*409.5 -> 7553.1231
B15: Mar 24, 2025 | C15: 410.9 | D15: 14362572 | L15: HDFC Asset Management Co. Ltd. (Invt Mgmt) | M15: 146878894 | N15: 0.01174 | O15: 759 M ₹ | Q15: Government of Singapore | R15: 18.005723 | S15: 0.01439 | T15: =R15*409.5 -> 7373.3437
B16: Mar 21, 2025 | C16: 405.55 | D16: 25302035 | L16: UTI Asset Management Co. Ltd. (Investment Management) | M16: 141084481 | N16: 0.01128 | O16: 729 M ₹ | Q16: HDFC Asset Management Co. Ltd. (Invt Mgmt) | R16: 14.687889 | S16: 0.01174 | T16: =R16*409.5 -> 6014.6907
B17: Mar 20, 2025 | C17: 403.95 | D17: 16994037 | L17: PPFAS Asset Management Private Ltd. | M17: 106368320 | N17: 0.008502 | O17: 550 M ₹ | Q17: UTI Asset Management Co. Ltd. (Investment Management) | R17: 14.108448 | S17: 0.01128 | T17: =R17*409.5 -> 5777.4095
B18: Mar 19, 2025 | C18: 403.05 | D18: 12830387 | Q18: PPFAS Asset Management Private Ltd. | R18: 10.636832 | S18: 0.008502 | T18: =R18*409.5 -> 4355.7827
B19: Mar 18, 2025 | C19: 407.95 | D19: -
B20: Mar 17, 2025 | C20: 407.95 | D20: 5257805
B21: Mar 13, 2025 | C21: 412.05 | D21: 8196569 | R21: DIIs | S21: =44.91% -> 0.4491
B22: Mar 12, 2025 | C22: 412.4 | D22: 13844306 | R22: FIIs | S22: =40.17% -> 0.4017
B23: Mar 11, 2025 | C23: 406.2 | D23: 11099475 | R23: Public & Government | S23: =14.88%+0.04% -> 0.1492
B24: Mar 10, 2025 | C24: 405 | D24: 9785018
B25: Mar 7, 2025 | C25: 403.9 | D25: 11180761
B26: Mar 6, 2025 | C26: 405.7 | D26: 17869996 | R26: S Puri Chairman & Managing Director 401 : 1 50
B27: Mar 5, 2025 | C27: 405.05 | D27: 15665018 | R27: S Dutta Executive Director & Chief Financial Officer 116 : 1 60
B28: Mar 4, 2025 | C28: 394.85 | D28: 13404774 | R28: B Sumant Executive Director 191 : 1 52
B29: Mar 3, 2025 | C29: 397.45 | D29: 10702826 | R29: H Malik 1 Executive Director 43 : 1
B30: Feb 28, 2025 | C30: 395 | D30: 31954776
B31: Feb 27, 2025 | C31: 401.6 | D31: 19051003
B32: Feb 25, 2025 | C32: 404.85 | D32: 15760891
B33: Feb 24, 2025 | C33: 401.9 | D33: 7037625
B34: Feb 21, 2025 | C34: 400.9 | D34: 8240986
B35: Feb 20, 2025 | C35: 402.05 | D35: 15355585
B36: Feb 19, 2025 | C36: 406.4 | D36: 7079032
B37: Feb 18, 2025 | C37: 405.25 | D37: 12998403
B38: Feb 17, 2025 | C38: 408.6 | D38: 11975265
B39: Feb 14, 2025 | C39: 410.25 | D39: 14124236
B40: Feb 13, 2025 | C40: 409.7 | D40: 12989029
B41: Feb 12, 2025 | C41: 409.9 | D41: 13884574
...

Sheet Sheet1
