Workbook
Name UPDATE: 'Data Sheet'!$E$1

Sheet Financial>

Sheet Histoirical FC
B2: ="Historical Financial Satement-"&'Data Sheet'!B1 -> Historical Financial Satement-TATA STEEL LTD
B3: Year | C3: ='Data Sheet'!B16 -> 42094 | D3: ='Data Sheet'!C16 -> 42460 | E3: ='Data Sheet'!D16 -> 42825 | F3: ='Data Sheet'!E16 -> 43190 | G3: ='Data Sheet'!F16 -> 43555 | H3: ='Data Sheet'!G16 -> 43921 | I3: ='Data Sheet'!H16 -> 44286 | J3: ='Data Sheet'!I16 -> 44651 | ... L3: ='Data Sheet'!K16 -> 45382 | M3: LTM
A5: # | B5: Income Statement
B6: Sales | C6: ='Data Sheet'!B17 -> 139503.73 | D6: ='Data Sheet'!C17 -> 101964.72 | E6: ='Data Sheet'!D17 -> 112299.42 | F6: ='Data Sheet'!E17 -> 123249.07 | G6: ='Data Sheet'!F17 -> 157668.99 | H6: ='Data Sheet'!G17 -> 139816.65 | I6: ='Data Sheet'!H17 -> 156294.18 | J6: ='Data Sheet'!I17 -> 243959.17 | ... L6: ='Data Sheet'!K17 -> 229170.78 | M6: =SUM('Data Sheet'!H42:K42) -> 221011.71
B7: Sales Growth(%) | D7: =D6/C6-1 -> -0.26908965 | E7: =E6/D6-1 -> 0.10135565 | F7: =F6/E6-1 -> 0.097504065 | G7: =G6/F6-1 -> 0.27927124 | H7: =H6/G6-1 -> -0.1132267 | I7: =I6/H6-1 -> 0.11785099 | J7: =J6/I6-1 -> 0.56089734 | K7: =K6/J6-1 -> -0.0024859898 | ... M7: =M6/L6-1 -> -0.035602576
B9: COGS | C9: =IFERROR(SUM('Data Sheet'!B18,'Data Sheet'!B20:B22)-1*'Data Sheet'!B19,0) -> 104290.94 | D9: =IFERROR(SUM('Data Sheet'!C18,'Data Sheet'!C20:C22)-1*'Data Sheet'!C19,0) -> 79237.26 | E9: =IFERROR(SUM('Data Sheet'!D18,'Data Sheet'!D20:D22)-1*'Data Sheet'!D19,0) -> 77577.09 | F9: =IFERROR(SUM('Data Sheet'!E18,'Data Sheet'!E20:E22)-1*'Data Sheet'!E19,0) -> 84710.05 | G9: =IFERROR(SUM('Data Sheet'!F18,'Data Sheet'!F20:F22)-1*'Data Sheet'!F19,0) -> 105590.05 | H9: =IFERROR(SUM('Data Sheet'!G18,'Data Sheet'!G20:G22)-1*'Data Sheet'!G19,0) -> 102560.94 | I9: =IFERROR(SUM('Data Sheet'!H18,'Data Sheet'!H20:H22)-1*'Data Sheet'!H19,0) -> 103382.36 | J9: =IFERROR(SUM('Data Sheet'!I18,'Data Sheet'!I20:I22)-1*'Data Sheet'!I19,0) -> 143605.19 | ... M9: =IFERROR(SUM('Data Sheet'!L18,'Data Sheet'!L20:L22)-1*'Data Sheet'!L19,0) -> 0
B10: (COGS %of Sale) | C10: =C9/C6 -> 0.74758532 | D10: =D9/D6 -> 0.77710467 | E10: =E9/E6 -> 0.69080579 | F10: =F9/F6 -> 0.68730782 | G10: =G9/G6 -> 0.66969447 | H10: =H9/H6 -> 0.73353882 | I10: =I9/I6 -> 0.66146007 | J10: =J9/J6 -> 0.58864436 | ... M10: =M9/M6 -> 0
B12: Gross Profit | C12: =C6-C9 -> 35212.79 | D12: =D6-D9 -> 22727.46 | E12: =E6-E9 -> 34722.33 | F12: =F6-F9 -> 38539.02 | G12: =G6-G9 -> 52078.94 | H12: =H6-H9 -> 37255.71 | I12: =I6-I9 -> 52911.82 | J12: =J6-J9 -> 100353.98 | ... M12: =M6-M9 -> 221011.71
B13: (Gross Margin) | C13: =C12/C6 -> 0.25241468 | D13: =D12/D6 -> 0.22289533 | E13: =E12/E6 -> 0.30919421 | F13: =F12/F6 -> 0.31269218 | G13: =G12/G6 -> 0.33030553 | H13: =H12/H6 -> 0.26646118 | I13: =I12/I6 -> 0.33853993 | J13: =J12/J6 -> 0.41135564 | ... M13: =M12/M6 -> 1
B15: Selling&General Expense | C15: =SUM('Data Sheet'!B23:B24) -> 31803.91 | D15: =SUM('Data Sheet'!C23:C24) -> 23352.7 | E15: =SUM('Data Sheet'!D23:D24) -> 21578.7 | F15: =SUM('Data Sheet'!E23:E24) -> 17105.83 | G15: =SUM('Data Sheet'!F23:F24) -> 22760.72 | H15: =SUM('Data Sheet'!G23:G24) -> 19792.65 | I15: =SUM('Data Sheet'!H23:H24) -> 22407.56 | J15: =SUM('Data Sheet'!I23:I24) -> 36864.03 | ... L15: =SUM('Data Sheet'!K23:K24) -> 36162.59 | M15: =SUM('Data Sheet'!H43:K43) -> 195697.33
B16: (S&G EXP %of Sale) | C16: =C15/C6 -> 0.22797892 | D16: =D15/D6 -> 0.22902726 | E16: =E15/E6 -> 0.19215326 | F16: =F15/F6 -> 0.13879074 | G16: =G15/G6 -> 0.14435762 | H16: =H15/H6 -> 0.14156147 | I16: =I15/I6 -> 0.14336785 | J16: =J15/J6 -> 0.15110738 | ... M16: =M15/M6 -> 0.88546136
B18: Operating Income(EBITDA) | C18: =C12-C15 -> 3408.88 | D18: =D12-D15 -> -625.24 | E18: =E12-E15 -> 13143.63 | F18: =F12-F15 -> 21433.19 | G18: =G12-G15 -> 29318.22 | H18: =H12-H15 -> 17463.06 | I18: =I12-I15 -> 30504.26 | J18: =J12-J15 -> 63489.95 | ... M18: =M12-M15 -> 25314.38
B19: (Operating Margin) | C19: =C18/C6 -> 0.024435762 | D19: =D18/D6 -> -0.0061319248 | E19: =E18/E6 -> 0.11704094 | F19: =F18/F6 -> 0.17390143 | G19: =G18/G6 -> 0.18594792 | H19: =H18/H6 -> 0.12489972 | I19: =I18/I6 -> 0.19517208 | J19: =J18/J6 -> 0.26024826 | ... M19: =M18/M6 -> 0.11453864
B21: ='Data Sheet'!A26 -> Depreciation | C21: ='Data Sheet'!B26 -> 5943.6 | D21: ='Data Sheet'!C26 -> 5306.35 | E21: ='Data Sheet'!D26 -> 5672.88 | F21: ='Data Sheet'!E26 -> 5741.7 | G21: ='Data Sheet'!F26 -> 7341.83 | H21: ='Data Sheet'!G26 -> 8440.73 | I21: ='Data Sheet'!H26 -> 9233.64 | ... L21: ='Data Sheet'!K26 -> 9882.16 | M21: =SUM('Data Sheet'!H45:K45) -> 10269.31
B22: (DEP % of Sale) | C22: =C21/C6 -> 0.042605312 | D22: =D21/D6 -> 0.052041039 | E22: =E21/E6 -> 0.050515666 | F22: =F21/F6 -> 0.046586153 | G22: =G21/G6 -> 0.046564832 | H22: =H21/H6 -> 0.060369992 | I22: =I21/I6 -> 0.059078591 | J22: =J21/J6 -> 0.03730489 | ... M22: =M21/M6 -> 0.046465004
B24: EBIT | C24: =C18-C21 -> -2534.72 | D24: =D18-D21 -> -5931.59 | E24: =E18-E21 -> 7470.75 | F24: =F18-F21 -> 15691.49 | G24: =G18-G21 -> 21976.39 | H24: =H18-H21 -> 9022.33 | I24: =I18-I21 -> 21270.62 | J24: =J18-J21 -> 54389.08 | ... M24: =M18-M21 -> 15045.07
B25: (EBIT Margin) | C25: =C24/C6 -> -0.01816955 | D25: =D24/D6 -> -0.058172964 | E25: =E24/E6 -> 0.066525277 | F25: =F24/F6 -> 0.12731528 | G25: =G24/G6 -> 0.13938308 | H25: =H24/H6 -> 0.064529725 | I25: =I24/I6 -> 0.13609349 | J25: =J24/J6 -> 0.22294337 | ... M25: =M24/M6 -> 0.068073633
B27: Intrest | C27: ='Data Sheet'!B27 -> 4847.75 | D27: ='Data Sheet'!C27 -> 4221.41 | E27: ='Data Sheet'!D27 -> 5072.2 | F27: ='Data Sheet'!E27 -> 5454.74 | G27: ='Data Sheet'!F27 -> 7660.1 | H27: ='Data Sheet'!G27 -> 7533.46 | I27: ='Data Sheet'!H27 -> 7606.71 | J27: ='Data Sheet'!I27 -> 5462.2 | ... L27: ='Data Sheet'!K27 -> 7507.57 | M27: =SUM('Data Sheet'!H46:K46) -> 7394.45
B28: (Intrest % of Sale) | C28: =C27/C6 -> 0.034749967 | D28: =D27/D6 -> 0.041400692 | E28: =E27/E6 -> 0.045166752 | F28: =F27/F6 -> 0.044257859 | G28: =G27/G6 -> 0.048583428 | H28: =H27/H6 -> 0.053880993 | I28: =I27/I6 -> 0.048669183 | J28: =J27/J6 -> 0.022389812 | ... M28: =M27/M6 -> 0.033457277
B30: Profit Before Tax | C30: =C24-C27 -> -7382.47 | D30: =D24-D27 -> -10153 | E30: =E24-E27 -> 2398.55 | F30: =F24-F27 -> 10236.75 | G30: =G24-G27 -> 14316.29 | H30: =H24-H27 -> 1488.87 | I30: =I24-I27 -> 13663.91 | J30: =J24-J27 -> 48926.88 | ... M30: =M24-M27 -> 7650.62
B31: (PBT % of Sale) | C31: =C30/C6 -> -0.052919517 | D31: =D30/D6 -> -0.099573656 | E31: =E30/E6 -> 0.021358525 | F31: =F30/F6 -> 0.083057422 | G31: =G30/G6 -> 0.090799656 | H31: =H30/H6 -> 0.010648732 | I31: =I30/I6 -> 0.087424305 | J31: =J30/J6 -> 0.20055356 | ... M31: =M30/M6 -> 0.034616356
B33: Tax | C33: ='Data Sheet'!B29 -> 2567.41 | D33: ='Data Sheet'!C29 -> 689.96 | E33: ='Data Sheet'!D29 -> 2778.01 | F33: ='Data Sheet'!E29 -> 3392.33 | G33: ='Data Sheet'!F29 -> 6718.43 | H33: ='Data Sheet'!G29 -> -2568.41 | I33: ='Data Sheet'!H29 -> 5653.9 | J33: ='Data Sheet'!I29 -> 8477.55 | ... L33: ='Data Sheet'!K29 -> 3762.57 | M33: =SUM('Data Sheet'!H48:K48) -> 5494.59
B34: (Effective tax Rate) | C34: =C33/C30 -> -0.34777114 | D34: =D33/D30 -> -0.067956269 | E34: =E33/E30 -> 1.1582039 | F34: =F33/F30 -> 0.3313874 | G34: =G33/G30 -> 0.46928569 | H34: =H33/H30 -> -1.7250734 | I34: =I33/I30 -> 0.41378346 | J34: =J33/J30 -> 0.17326979 | ... M34: =M33/M30 -> 0.71818885
B36: Net Profit | C36: =C30-C33 -> -9949.88 | D36: =D30-D33 -> -10842.96 | E36: =E30-E33 -> -379.46 | F36: =F30-F33 -> 6844.42 | G36: =G30-G33 -> 7597.86 | H36: =H30-H33 -> 4057.28 | I36: =I30-I33 -> 8010.01 | J36: =J30-J33 -> 40449.33 | ... M36: =M30-M33 -> 2156.03
B37: (Net Margin) | C37: =C36/C6 -> -0.071323398 | D37: =D36/D6 -> -0.10634031 | E37: =E36/E6 -> -0.0033790023 | F37: =F36/F6 -> 0.055533239 | G37: =G36/G6 -> 0.048188677 | H37: =H36/H6 -> 0.029018575 | I37: =I36/I6 -> 0.051249573 | J37: =J36/J6 -> 0.16580369 | ... M37: =M36/M6 -> 0.009755275
B39: No Of Equity Share | C39: ='Data Sheet'!B93 -> 1126.62 | D39: ='Data Sheet'!C93 -> 1126.62 | E39: ='Data Sheet'!D93 -> 1126.62 | F39: ='Data Sheet'!E93 -> 1126.48 | G39: ='Data Sheet'!F93 -> 1126.49 | H39: ='Data Sheet'!G93 -> 1126.49 | I39: ='Data Sheet'!H93 -> 1196.59 | J39: ='Data Sheet'!I93 -> 1221.3 | ... L39: ='Data Sheet'!K93 -> 1248.35 | M39: =L39 -> 1248.35
B41: EPS | C41: =C36/C39 -> -8.8316202 | D41: =D36/D39 -> -9.6243276 | E41: =E36/E39 -> -0.33681277 | F41: =F36/F39 -> 6.0759357 | G41: =G36/G39 -> 6.7447203 | H41: =H36/H39 -> 3.6017009 | I41: =I36/I39 -> 6.6940305 | J41: =J36/J39 -> 33.119897 | ... M41: =M36/M39 -> 1.7271038
B42: Earning Per Growth | D42: =D41/C41-1 -> 0.089757866 | E42: =E41/D41-1 -> -0.96500402 | F42: =F41/E41-1 -> -19.039505 | G42: =G41/F41-1 -> 0.11007106 | H42: =H41/G41-1 -> -0.465997 | I42: =I41/H41-1 -> 0.85857482 | J42: =J41/I41-1 -> 3.9476764 | K42: =K41/J41-1 -> -0.83925655 | ... M42: =M41/L41-1 -> 0.96786295
B44: Divident Per Share | C44: ='Data Sheet'!B31/'Histoirical FC'!C39 -> 0.68978893 | D44: ='Data Sheet'!C31/'Histoirical FC'!D39 -> 0.68895457 | E44: ='Data Sheet'!D31/'Histoirical FC'!E39 -> 0.86119543 | F44: ='Data Sheet'!E31/'Histoirical FC'!F39 -> 1.0163962 | G44: ='Data Sheet'!F31/'Histoirical FC'!G39 -> 1.32129 | H44: ='Data Sheet'!G31/'Histoirical FC'!H39 -> 1.0163872 | I44: ='Data Sheet'!H31/'Histoirical FC'!I39 -> 2.5021269 | J44: ='Data Sheet'!I31/'Histoirical FC'!J39 -> 5.0996234 | ... M44: ='Data Sheet'!L31/'Histoirical FC'!M39 -> 0
B45: (Divident Payout Ratio) | C45: =C44/C41 -> -0.07810446 | D45: =D44/D41 -> -0.071584696 | E45: =E44/E41 -> -2.5568966 | F45: =F44/F41 -> 0.16728225 | G45: =G44/G41 -> 0.1958999 | H45: =H44/H41 -> 0.28219645 | I45: =I44/I41 -> 0.3737848 | J45: =J44/J41 -> 0.15397461 | ... M45: =M44/M41 -> 0
B47: Retained Earning | C47: =C41-C44 -> -9.5214092 | D47: =D41-D44 -> -10.313282 | E47: =E41-E44 -> -1.1980082 | F47: =F41-F44 -> 5.0595395 | G47: =G41-G44 -> 5.4234303 | H47: =H41-H44 -> 2.5853137 | I47: =I41-I44 -> 4.1919037 | J47: =J41-J44 -> 28.020273 | ... M47: =M41-M44 -> 1.7271038
B48: Retained Earning% | C48: =C47/C41 -> 1.0781045 | D48: =D47/D41 -> 1.0715847 | E48: =E47/E41 -> 3.5568966 | F48: =F47/F41 -> 0.83271775 | G48: =G47/G41 -> 0.8041001 | H48: =H47/H41 -> 0.71780355 | I48: =I47/I41 -> 0.6262152 | J48: =J47/J41 -> 0.84602539 | ... M48: =M47/M41 -> 1
A50: # | B50: Balance Sheet
B52: ='Data Sheet'!A57 -> Equity Share Capital | C52: ='Data Sheet'!B57 -> 971.41 | D52: ='Data Sheet'!C57 -> 970.24 | E52: ='Data Sheet'!D57 -> 970.24 | F52: ='Data Sheet'!E57 -> 1144.95 | G52: ='Data Sheet'!F57 -> 1144.94 | H52: ='Data Sheet'!G57 -> 1144.95 | I52: ='Data Sheet'!H57 -> 1197.61 | ... L52: ='Data Sheet'!K57 -> 1247.44
B53: ='Data Sheet'!A58 -> Reserves | C53: ='Data Sheet'!B58 -> 30378 | D53: ='Data Sheet'!C58 -> 42762.31 | E53: ='Data Sheet'!D58 -> 36849.08 | F53: ='Data Sheet'!E58 -> 59725.67 | G53: ='Data Sheet'!F58 -> 67780.14 | H53: ='Data Sheet'!G58 -> 72431.35 | I53: ='Data Sheet'!H58 -> 73041.16 | ... L53: ='Data Sheet'!K58 -> 90788.32
B54: ='Data Sheet'!A59 -> Borrowings | C54: ='Data Sheet'!B59 -> 80701.29 | D54: ='Data Sheet'!C59 -> 81986.93 | E54: ='Data Sheet'!D59 -> 83014.49 | F54: ='Data Sheet'!E59 -> 92147.05 | G54: ='Data Sheet'!F59 -> 100816.22 | H54: ='Data Sheet'!G59 -> 116328.2 | I54: ='Data Sheet'!H59 -> 88501.41 | ... L54: ='Data Sheet'!K59 -> 87082.12
B55: ='Data Sheet'!A60 -> Other Liabilities | C55: ='Data Sheet'!B60 -> 47058.6 | D55: ='Data Sheet'!C60 -> 51164.51 | E55: ='Data Sheet'!D60 -> 51613.56 | F55: ='Data Sheet'!E60 -> 55704.47 | G55: ='Data Sheet'!F60 -> 63032.14 | H55: ='Data Sheet'!G60 -> 59244.62 | I55: ='Data Sheet'!H60 -> 81169.01 | ... L55: ='Data Sheet'!K60 -> 90194.54
B56: Total Liabilites | C56: =SUM(C52:C55) -> 159109.3 | D56: =SUM(D52:D55) -> 176883.99 | E56: =SUM(E52:E55) -> 172447.37 | F56: =SUM(F52:F55) -> 208722.14 | G56: =SUM(G52:G55) -> 232773.44 | H56: =SUM(H52:H55) -> 249149.12 | I56: =SUM(I52:I55) -> 243909.19 | J56: =SUM(J52:J55) -> 282421.67 | ... L56: =SUM(L52:L55) -> 269312.42
B58: ='Data Sheet'!A62 -> Net Block | C58: ='Data Sheet'!B62 -> 68100.33 | D58: ='Data Sheet'!C62 -> 72199.76 | E58: ='Data Sheet'!D62 -> 92006.55 | F58: ='Data Sheet'!E62 -> 96104.89 | G58: ='Data Sheet'!F62 -> 124441.91 | H58: ='Data Sheet'!G62 -> 134550.66 | I58: ='Data Sheet'!H62 -> 135775.18 | ... L58: ='Data Sheet'!K62 -> 148814.38
B59: ='Data Sheet'!A63 -> Capital Work in Progress | C59: ='Data Sheet'!B63 -> 28678.12 | D59: ='Data Sheet'!C63 -> 35996.09 | E59: ='Data Sheet'!D63 -> 15784.13 | F59: ='Data Sheet'!E63 -> 16614.41 | G59: ='Data Sheet'!F63 -> 18641.21 | H59: ='Data Sheet'!G63 -> 19496.83 | I59: ='Data Sheet'!H63 -> 19007.4 | ... L59: ='Data Sheet'!K63 -> 34355.53
...

Sheet Ratio Analysis
B2: ="Ratio Analysis-"&'Data Sheet'!B1 -> Ratio Analysis-TATA STEEL LTD
B3: Year | C3: ='Data Sheet'!B16 -> 42094 | D3: ='Data Sheet'!C16 -> 42460 | E3: ='Data Sheet'!D16 -> 42825 | F3: ='Data Sheet'!E16 -> 43190 | G3: ='Data Sheet'!F16 -> 43555 | H3: ='Data Sheet'!G16 -> 43921 | I3: ='Data Sheet'!H16 -> 44286 | J3: ='Data Sheet'!I16 -> 44651 | ... L3: ='Data Sheet'!K16 -> 45382 | M3: Trend | N3: Mean | O3: Median
B5: Sales Growth | D5: ='Histoirical FC'!D6/'Histoirical FC'!C6-1 -> -0.26908965 | E5: ='Histoirical FC'!E6/'Histoirical FC'!D6-1 -> 0.10135565 | F5: ='Histoirical FC'!F6/'Histoirical FC'!E6-1 -> 0.097504065 | G5: ='Histoirical FC'!G6/'Histoirical FC'!F6-1 -> 0.27927124 | H5: ='Histoirical FC'!H6/'Histoirical FC'!G6-1 -> -0.1132267 | I5: ='Histoirical FC'!I6/'Histoirical FC'!H6-1 -> 0.11785099 | J5: ='Histoirical FC'!J6/'Histoirical FC'!I6-1 -> 0.56089734 | K5: ='Histoirical FC'!K6/'Histoirical FC'!J6-1 -> -0.0024859898 | L5: ='Histoirical FC'!L6/'Histoirical FC'!K6-1 -> -0.058277186 | N5: =AVERAGE(D5:L5) -> 0.079311082 | O5: =MEDIAN(D5:L5) -> 0.097504065
B6: EBITDA Growth | D6: ='Histoirical FC'!D18/'Histoirical FC'!C18-1 -> -1.1834151 | E6: ='Histoirical FC'!E18/'Histoirical FC'!D18-1 -> -22.021736 | F6: ='Histoirical FC'!F18/'Histoirical FC'!E18-1 -> 0.6306903 | G6: ='Histoirical FC'!G18/'Histoirical FC'!F18-1 -> 0.36788877 | H6: ='Histoirical FC'!H18/'Histoirical FC'!G18-1 -> -0.40436152 | I6: ='Histoirical FC'!I18/'Histoirical FC'!H18-1 -> 0.74678779 | J6: ='Histoirical FC'!J18/'Histoirical FC'!I18-1 -> 1.081347 | K6: ='Histoirical FC'!K18/'Histoirical FC'!J18-1 -> -0.49125555 | L6: ='Histoirical FC'!L18/'Histoirical FC'!K18-1 -> -0.31121332 | N6: =AVERAGE(D6:L6) -> -2.398363 | O6: =MEDIAN(D6:L6) -> -0.31121332
B7: EBIT Growth | D7: ='Histoirical FC'!D24/'Histoirical FC'!C24-1 -> 1.3401362 | E7: ='Histoirical FC'!E24/'Histoirical FC'!D24-1 -> -2.2594852 | F7: ='Histoirical FC'!F24/'Histoirical FC'!E24-1 -> 1.1003902 | G7: ='Histoirical FC'!G24/'Histoirical FC'!F24-1 -> 0.4005292 | H7: ='Histoirical FC'!H24/'Histoirical FC'!G24-1 -> -0.5894535 | I7: ='Histoirical FC'!I24/'Histoirical FC'!H24-1 -> 1.3575529 | J7: ='Histoirical FC'!J24/'Histoirical FC'!I24-1 -> 1.5570049 | K7: ='Histoirical FC'!K24/'Histoirical FC'!J24-1 -> -0.57776524 | L7: ='Histoirical FC'!L24/'Histoirical FC'!K24-1 -> -0.46153793 | N7: =AVERAGE(D7:L7) -> 0.20748572 | O7: =MEDIAN(D7:L7) -> 0.4005292
B8: Net Profit Growth | D8: ='Histoirical FC'!D36/'Histoirical FC'!C36-1 -> 0.089757866 | E8: ='Histoirical FC'!E36/'Histoirical FC'!D36-1 -> -0.96500402 | F8: ='Histoirical FC'!F36/'Histoirical FC'!E36-1 -> -19.037263 | G8: ='Histoirical FC'!G36/'Histoirical FC'!F36-1 -> 0.11008091 | H8: ='Histoirical FC'!H36/'Histoirical FC'!G36-1 -> -0.465997 | I8: ='Histoirical FC'!I36/'Histoirical FC'!H36-1 -> 0.9742315 | J8: ='Histoirical FC'!J36/'Histoirical FC'!I36-1 -> 4.0498476 | K8: ='Histoirical FC'!K36/'Histoirical FC'!J36-1 -> -0.83914468 | L8: ='Histoirical FC'!L36/'Histoirical FC'!K36-1 -> -0.83161121 | N8: =AVERAGE(D8:L8) -> -1.8794558 | O8: =MEDIAN(D8:L8) -> -0.465997
B9: Divident Growth | D9: ='Histoirical FC'!D44/'Histoirical FC'!C44-1 -> -0.0012095788 | E9: ='Histoirical FC'!E44/'Histoirical FC'!D44-1 -> 0.25000322 | F9: ='Histoirical FC'!F44/'Histoirical FC'!E44-1 -> 0.18021551 | G9: ='Histoirical FC'!G44/'Histoirical FC'!F44-1 -> 0.29997536 | H9: ='Histoirical FC'!H44/'Histoirical FC'!G44-1 -> -0.23076148 | I9: ='Histoirical FC'!I44/'Histoirical FC'!H44-1 -> 1.4617851 | J9: ='Histoirical FC'!J44/'Histoirical FC'!I44-1 -> 1.0381154 | K9: ='Histoirical FC'!K44/'Histoirical FC'!J44-1 -> -0.29459179 | L9: ='Histoirical FC'!L44/'Histoirical FC'!K44-1 -> 1.5657977e-05 | N9: =AVERAGE(D9:L9) -> 0.30039416 | O9: =MEDIAN(D9:L9) -> 0.18021551
B11: Gross Margin | C11: ='Histoirical FC'!C12/'Histoirical FC'!C6 -> 0.25241468 | D11: ='Histoirical FC'!D12/'Histoirical FC'!D6 -> 0.22289533 | E11: ='Histoirical FC'!E12/'Histoirical FC'!E6 -> 0.30919421 | F11: ='Histoirical FC'!F12/'Histoirical FC'!F6 -> 0.31269218 | G11: ='Histoirical FC'!G12/'Histoirical FC'!G6 -> 0.33030553 | H11: ='Histoirical FC'!H12/'Histoirical FC'!H6 -> 0.26646118 | I11: ='Histoirical FC'!I12/'Histoirical FC'!I6 -> 0.33853993 | J11: ='Histoirical FC'!J12/'Histoirical FC'!J6 -> 0.41135564 | ... L11: ='Histoirical FC'!L12/'Histoirical FC'!L6 -> 0.25487765 | N11: =AVERAGE(D11:L11) -> 0.30150217 | O11: =MEDIAN(D11:L11) -> 0.30919421
B12: EBITDA Margin | C12: ='Histoirical FC'!C18/'Histoirical FC'!C6 -> 0.024435762 | D12: ='Histoirical FC'!D18/'Histoirical FC'!D6 -> -0.0061319248 | E12: ='Histoirical FC'!E18/'Histoirical FC'!E6 -> 0.11704094 | F12: ='Histoirical FC'!F18/'Histoirical FC'!F6 -> 0.17390143 | G12: ='Histoirical FC'!G18/'Histoirical FC'!G6 -> 0.18594792 | H12: ='Histoirical FC'!H18/'Histoirical FC'!H6 -> 0.12489972 | I12: ='Histoirical FC'!I18/'Histoirical FC'!I6 -> 0.19517208 | J12: ='Histoirical FC'!J18/'Histoirical FC'!J6 -> 0.26024826 | ... L12: ='Histoirical FC'!L18/'Histoirical FC'!L6 -> 0.09708009 | N12: =AVERAGE(D12:L12) -> 0.14232093 | O12: =MEDIAN(D12:L12) -> 0.13272983
B13: EBIT Margin | C13: ='Histoirical FC'!C24/'Histoirical FC'!C6 -> -0.01816955 | D13: ='Histoirical FC'!D24/'Histoirical FC'!D6 -> -0.058172964 | E13: ='Histoirical FC'!E24/'Histoirical FC'!E6 -> 0.066525277 | F13: ='Histoirical FC'!F24/'Histoirical FC'!F6 -> 0.12731528 | G13: ='Histoirical FC'!G24/'Histoirical FC'!G6 -> 0.13938308 | H13: ='Histoirical FC'!H24/'Histoirical FC'!H6 -> 0.064529725 | I13: ='Histoirical FC'!I24/'Histoirical FC'!I6 -> 0.13609349 | J13: ='Histoirical FC'!J24/'Histoirical FC'!J6 -> 0.22294337 | ... L13: ='Histoirical FC'!L24/'Histoirical FC'!L6 -> 0.053958711 | N13: =AVERAGE(D13:L13) -> 0.094105002 | O13: =MEDIAN(D13:L13) -> 0.094369041
B14: EBT Margin | C14: ='Histoirical FC'!C30/'Histoirical FC'!C6 -> -0.052919517 | D14: ='Histoirical FC'!D30/'Histoirical FC'!D6 -> -0.099573656 | E14: ='Histoirical FC'!E30/'Histoirical FC'!E6 -> 0.021358525 | F14: ='Histoirical FC'!F30/'Histoirical FC'!F6 -> 0.083057422 | G14: ='Histoirical FC'!G30/'Histoirical FC'!G6 -> 0.090799656 | H14: ='Histoirical FC'!H30/'Histoirical FC'!H6 -> 0.010648732 | I14: ='Histoirical FC'!I30/'Histoirical FC'!I6 -> 0.087424305 | J14: ='Histoirical FC'!J30/'Histoirical FC'!J6 -> 0.20055356 | ... L14: ='Histoirical FC'!L30/'Histoirical FC'!L6 -> 0.021198994 | N14: =AVERAGE(D14:L14) -> 0.053772619 | O14: =MEDIAN(D14:L14) -> 0.068486032
B15: Net Profit Margin | C15: ='Histoirical FC'!C36/'Histoirical FC'!C6 -> -0.071323398 | D15: ='Histoirical FC'!D36/'Histoirical FC'!D6 -> -0.10634031 | E15: ='Histoirical FC'!E36/'Histoirical FC'!E6 -> -0.0033790023 | F15: ='Histoirical FC'!F36/'Histoirical FC'!F6 -> 0.055533239 | G15: ='Histoirical FC'!G36/'Histoirical FC'!G6 -> 0.048188677 | H15: ='Histoirical FC'!H36/'Histoirical FC'!H6 -> 0.029018575 | I15: ='Histoirical FC'!I36/'Histoirical FC'!I6 -> 0.051249573 | J15: ='Histoirical FC'!J36/'Histoirical FC'!J6 -> 0.16580369 | ... L15: ='Histoirical FC'!L36/'Histoirical FC'!L6 -> 0.0047808015 | N15: =AVERAGE(D15:L15) -> 0.030176901 | O15: =MEDIAN(D15:L15) -> 0.029018575
B17: Sales Expense % of Sale | C17: ='Histoirical FC'!C16 -> 0.22797892 | D17: ='Histoirical FC'!D16 -> 0.22902726 | E17: ='Histoirical FC'!E16 -> 0.19215326 | F17: ='Histoirical FC'!F16 -> 0.13879074 | G17: ='Histoirical FC'!G16 -> 0.14435762 | H17: ='Histoirical FC'!H16 -> 0.14156147 | I17: ='Histoirical FC'!I16 -> 0.14336785 | J17: ='Histoirical FC'!J16 -> 0.15110738 | ... L17: ='Histoirical FC'!L16 -> 0.15779756 | N17: =AVERAGE(D17:L17) -> 0.15918125 | O17: =MEDIAN(D17:L17) -> 0.14435762
B18: Depriciation % of Sale | C18: ='Histoirical FC'!C22 -> 0.042605312 | D18: ='Histoirical FC'!D22 -> 0.052041039 | E18: ='Histoirical FC'!E22 -> 0.050515666 | F18: ='Histoirical FC'!F22 -> 0.046586153 | G18: ='Histoirical FC'!G22 -> 0.046564832 | H18: ='Histoirical FC'!H22 -> 0.060369992 | I18: ='Histoirical FC'!I22 -> 0.059078591 | J18: ='Histoirical FC'!J22 -> 0.03730489 | ... L18: ='Histoirical FC'!L22 -> 0.043121379 | N18: =AVERAGE(D18:L18) -> 0.048215925 | O18: =MEDIAN(D18:L18) -> 0.046586153
B20: Debt to Equity Ratio
B21: Debt/Equity | C21: =SUM('Rough Data'!P6:P7)/SUM('Rough Data'!P3:P4) -> 2.4011611 | D21: =SUM('Rough Data'!Q6:Q7)/SUM('Rough Data'!Q3:Q4) -> 1.8429297 | E21: =SUM('Rough Data'!R6:R7)/SUM('Rough Data'!R3:R4) -> 2.1774769 | F21: =SUM('Rough Data'!S6:S7)/SUM('Rough Data'!S3:S4) -> 1.4567528 | G21: =SUM('Rough Data'!T6:T7)/SUM('Rough Data'!T3:T4) -> 1.3223794 | H21: =SUM('Rough Data'!U6:U7)/SUM('Rough Data'!U3:U4) -> 1.5397548 | I21: =SUM('Rough Data'!V6:V7)/SUM('Rough Data'!V3:V4) -> 1.1032072 | J21: =SUM('Rough Data'!W6:W7)/SUM('Rough Data'!W3:W4) -> 0.60142604 | ... L21: =SUM('Rough Data'!Y6:Y7)/SUM('Rough Data'!Y3:Y4) -> 0.88633672 | N21: =AVERAGE(D21:L21) -> 1.2985675 | O21: =MEDIAN(D21:L21) -> 1.3223794
B22: Intrest Coverage Ratio | C22: ='Histoirical FC'!C24/'Data Sheet'!B27 -> -0.52286525 | D22: ='Histoirical FC'!D24/'Data Sheet'!C27 -> -1.4051206 | E22: ='Histoirical FC'!E24/'Data Sheet'!D27 -> 1.4728816 | F22: ='Histoirical FC'!F24/'Data Sheet'!E27 -> 2.8766706 | G22: ='Histoirical FC'!G24/'Data Sheet'!F27 -> 2.868943 | H22: ='Histoirical FC'!H24/'Data Sheet'!G27 -> 1.1976343 | I22: ='Histoirical FC'!I24/'Data Sheet'!H27 -> 2.796297 | J22: ='Histoirical FC'!J24/'Data Sheet'!I27 -> 9.9573578 | ... L22: ='Histoirical FC'!L24/'Data Sheet'!K27 -> 1.6471055 | N22: =AVERAGE(D22:L22) -> 2.7841948 | O22: =MEDIAN(D22:L22) -> 2.796297
B24: Return Ratio
B25: Return on Equity | C25: ='Histoirical FC'!C36/SUM('Data Sheet'!B57:B58) -> -0.31738652 | D25: ='Histoirical FC'!D36/SUM('Data Sheet'!C57:C58) -> -0.24793798 | E25: ='Histoirical FC'!E36/SUM('Data Sheet'!D57:D58) -> -0.010033496 | F25: ='Histoirical FC'!F36/SUM('Data Sheet'!E57:E58) -> 0.11244209 | G25: ='Histoirical FC'!G36/SUM('Data Sheet'!F57:F58) -> 0.1102336 | H25: ='Histoirical FC'!H36/SUM('Data Sheet'!G57:G58) -> 0.055143844 | I25: ='Histoirical FC'!I36/SUM('Data Sheet'!H57:H58) -> 0.10789524 | J25: ='Histoirical FC'!J36/SUM('Data Sheet'!I57:I58) -> 0.35344508 | ... L25: ='Histoirical FC'!L36/SUM('Data Sheet'!K57:K58) -> 0.011904286 | N25: =AVERAGE(D25:L25) -> 0.061801353 | O25: =MEDIAN(D25:L25) -> 0.063119494
B26: Return On Captial Employed | C26: ='Histoirical FC'!C24/SUM('Histoirical FC'!C52:C54) -> -0.022621188 | D26: ='Histoirical FC'!D24/SUM('Histoirical FC'!D52:D54) -> -0.047181153 | E26: ='Histoirical FC'!E24/SUM('Histoirical FC'!E52:E54) -> 0.061826653 | F26: ='Histoirical FC'!F24/SUM('Histoirical FC'!F52:F54) -> 0.10254692 | G26: ='Histoirical FC'!G24/SUM('Histoirical FC'!G52:G54) -> 0.12946991 | H26: ='Histoirical FC'!H24/SUM('Histoirical FC'!H52:H54) -> 0.047509827 | I26: ='Histoirical FC'!I24/SUM('Histoirical FC'!I52:I54) -> 0.13070294 | J26: ='Histoirical FC'!J24/SUM('Histoirical FC'!J52:J54) -> 0.2862517 | ... L26: ='Histoirical FC'!L24/SUM('Histoirical FC'!L52:L54) -> 0.069036994 | N26: =AVERAGE(D26:L26) -> 0.10025933 | O26: =MEDIAN(D26:L26) -> 0.10254692
B27: Retained Earning% | C27: ='Histoirical FC'!C48 -> 1.0781045 | D27: ='Histoirical FC'!D48 -> 1.0715847 | E27: ='Histoirical FC'!E48 -> 3.5568966 | F27: ='Histoirical FC'!F48 -> 0.83271775 | G27: ='Histoirical FC'!G48 -> 0.8041001 | H27: ='Histoirical FC'!H48 -> 0.71780355 | I27: ='Histoirical FC'!I48 -> 0.6262152 | J27: ='Histoirical FC'!J48 -> 0.84602539 | ... L27: ='Histoirical FC'!L48 -> -3.0988481 | N27: =AVERAGE(D27:L27) -> 0.63119904 | O27: =MEDIAN(D27:L27) -> 0.8041001
B28: Selfsustained Growth | C28: =C27*C25 -> -0.34217582 | D28: =D27*D25 -> -0.26568654 | E28: =E27*E25 -> -0.035688109 | F28: =F27*F25 -> 0.093632527 | G28: =G27*G25 -> 0.088638853 | H28: =H27*H25 -> 0.039582447 | I28: =I27*I25 -> 0.06756564 | J28: =J27*J25 -> 0.29902351 | ... L28: =L27*L25 -> -0.036889574 | N28: =AVERAGE(D28:L28) -> 0.030072019 | O28: =MEDIAN(D28:L28) -> 0.039582447
B30: Turnover Ratio
B31: Receivabel Turnover Ratio | C31: ='Histoirical FC'!C6/'Histoirical FC'!C64 -> 10.481224 | D31: ='Histoirical FC'!D6/'Histoirical FC'!D64 -> 8.4504277 | E31: ='Histoirical FC'!E6/'Histoirical FC'!E64 -> 9.6919966 | F31: ='Histoirical FC'!F6/'Histoirical FC'!F64 -> 9.9270163 | G31: ='Histoirical FC'!G6/'Histoirical FC'!G64 -> 13.349335 | H31: ='Histoirical FC'!H6/'Histoirical FC'!H64 -> 17.732181 | I31: ='Histoirical FC'!I6/'Histoirical FC'!I64 -> 16.383313 | J31: ='Histoirical FC'!J6/'Histoirical FC'!J64 -> 19.92084 | ... L31: ='Histoirical FC'!L6/'Histoirical FC'!L64 -> 36.588119 | N31: =AVERAGE(D31:L31) -> 17.946073 | O31: =MEDIAN(D31:L31) -> 16.383313
B32: Payabel Turnover Ratio | C32: ='Histoirical FC'!C6/'Rough Data'!P13 -> 7.2696055 | D32: ='Histoirical FC'!D6/'Rough Data'!Q13 -> 5.4946769 | E32: ='Histoirical FC'!E6/'Rough Data'!R13 -> 6.0460547 | F32: ='Histoirical FC'!F6/'Rough Data'!S13 -> 6.0374777 | G32: ='Histoirical FC'!G6/'Rough Data'!T13 -> 7.2601644 | H32: ='Histoirical FC'!H6/'Rough Data'!U13 -> 6.5392942 | I32: ='Histoirical FC'!I6/'Rough Data'!V13 -> 6.0189541 | J32: ='Histoirical FC'!J6/'Rough Data'!W13 -> 6.6356363 | ... L32: ='Histoirical FC'!L6/'Rough Data'!Y13 -> 6.4673566 | N32: =AVERAGE(D32:L32) -> 6.3257668 | O32: =MEDIAN(D32:L32) -> 6.4322864
B33: Inventory Turnover Ratio | C33: ='Histoirical FC'!C6/'Histoirical FC'!C65 -> 5.5468878 | D33: ='Histoirical FC'!D6/'Histoirical FC'!D65 -> 5.0948403 | E33: ='Histoirical FC'!E6/'Histoirical FC'!E65 -> 4.527505 | F33: ='Histoirical FC'!F6/'Histoirical FC'!F65 -> 4.3503193 | G33: ='Histoirical FC'!G6/'Histoirical FC'!G65 -> 4.9806827 | H33: ='Histoirical FC'!H6/'Histoirical FC'!H65 -> 4.5002385 | I33: ='Histoirical FC'!I6/'Histoirical FC'!I65 -> 4.6968504 | J33: ='Histoirical FC'!J6/'Histoirical FC'!J65 -> 4.996666 | ... L33: ='Histoirical FC'!L6/'Histoirical FC'!L65 -> 4.6619688 | N33: =AVERAGE(D33:L33) -> 4.6979118 | O33: =MEDIAN(D33:L33) -> 4.6619688
B34: Fixed Asset Turnover Ratio | C34: ='Histoirical FC'!C6/'Histoirical FC'!C62 -> 1.2466868 | D34: ='Histoirical FC'!D6/'Histoirical FC'!D62 -> 0.73558013 | E34: ='Histoirical FC'!E6/'Histoirical FC'!E62 -> 0.85636053 | F34: ='Histoirical FC'!F6/'Histoirical FC'!F62 -> 0.77012508 | G34: ='Histoirical FC'!G6/'Histoirical FC'!G62 -> 0.84784242 | H34: ='Histoirical FC'!H6/'Histoirical FC'!H62 -> 0.69167962 | I34: ='Histoirical FC'!I6/'Histoirical FC'!I62 -> 0.80023321 | J34: ='Histoirical FC'!J6/'Histoirical FC'!J62 -> 1.1874271 | ... L34: ='Histoirical FC'!L6/'Histoirical FC'!L62 -> 1.1167423 | N34: =AVERAGE(D34:L34) -> 0.90759135 | O34: =MEDIAN(D34:L34) -> 0.84784242
B35: Capital Turnover Ratio | C35: ='Histoirical FC'!C6/SUM('Histoirical FC'!C52:C53) -> 4.4499635 | D35: ='Histoirical FC'!D6/SUM('Histoirical FC'!D52:D53) -> 2.3315521 | E35: ='Histoirical FC'!E6/SUM('Histoirical FC'!E52:E53) -> 2.9693665 | F35: ='Histoirical FC'!F6/SUM('Histoirical FC'!F52:F53) -> 2.0247711 | G35: ='Histoirical FC'!G6/SUM('Histoirical FC'!G52:G53) -> 2.2875416 | H35: ='Histoirical FC'!H6/SUM('Histoirical FC'!H52:H53) -> 1.9002947 | I35: ='Histoirical FC'!I6/SUM('Histoirical FC'!I52:I53) -> 2.1052905 | J35: ='Histoirical FC'!J6/SUM('Histoirical FC'!J52:J53) -> 2.1317082 | ... L35: ='Histoirical FC'!L6/SUM('Histoirical FC'!L52:L53) -> 2.4900189 | N35: =AVERAGE(D35:L35) -> 2.2890344 | O35: =MEDIAN(D35:L35) -> 2.2875416
B37: WC(Cash Conversion Cycel)
B38: Debtor Day | C38: =365/C31 -> 34.824177 | D38: =365/D31 -> 43.19308 | E38: =365/E31 -> 37.659939 | F38: =365/F31 -> 36.768349 | G38: =365/G31 -> 27.342187 | H38: =365/H31 -> 20.584045 | I38: =365/I31 -> 22.278767 | J38: =365/J31 -> 18.322521 | ... L38: =365/L31 -> 9.975916 | N38: =AVERAGE(D38:L38) -> 25.389964 | O38: =MEDIAN(D38:L38) -> 22.278767
B39: Payabel Day | C39: =365/C32 -> 50.209052 | D39: =365/D32 -> 66.427927 | E39: =365/E32 -> 60.369947 | F39: =365/F32 -> 60.45571 | G39: =365/G32 -> 50.274344 | H39: =365/H32 -> 55.816421 | I39: =365/I32 -> 60.641765 | J39: =365/J32 -> 55.006028 | ... L39: =365/L32 -> 56.437278 | N39: =AVERAGE(D39:L39) -> 58.019378 | O39: =MEDIAN(D39:L39) -> 56.744986
B40: Inventory Day | C40: =365/C33 -> 65.802665 | D40: =365/D33 -> 71.641107 | E40: =365/E33 -> 80.618353 | F40: =365/F33 -> 83.901887 | G40: =365/G33 -> 73.283126 | H40: =365/H33 -> 81.106812 | I40: =365/I33 -> 77.711651 | J40: =365/J33 -> 73.048709 | ... L40: =365/L33 -> 78.293102 | N40: =AVERAGE(D40:L40) -> 77.913472 | O40: =MEDIAN(D40:L40) -> 78.293102
B41: Cash Conversion Cycel | C41: =C38+C40-C39 -> 50.41779 | D41: =D38+D40-D39 -> 48.40626 | E41: =E38+E40-E39 -> 57.908345 | F41: =F38+F40-F39 -> 60.214527 | G41: =G38+G40-G39 -> 50.350969 | H41: =H38+H40-H39 -> 45.874436 | I41: =I38+I40-I39 -> 39.348652 | J41: =J38+J40-J39 -> 36.365201 | ... L41: =L38+L40-L39 -> 31.83174 | N41: =AVERAGE(D41:L41) -> 45.284058 | O41: =MEDIAN(D41:L41) -> 45.874436
B43: CFO/Sales | C43: ='Histoirical FC'!C83/'Histoirical FC'!C6 -> 0.087675075 | D43: ='Histoirical FC'!D83/'Histoirical FC'!D6 -> 0.17282448 | E43: ='Histoirical FC'!E83/'Histoirical FC'!E6 -> 0.052627164 | F43: ='Histoirical FC'!F83/'Histoirical FC'!F6 -> -0.010158292 | G43: ='Histoirical FC'!G83/'Histoirical FC'!G6 -> 0.17712424 | H43: ='Histoirical FC'!H83/'Histoirical FC'!H6 -> 0.17425679 | I43: ='Histoirical FC'!I83/'Histoirical FC'!I6 -> 0.38913157 | J43: ='Histoirical FC'!J83/'Histoirical FC'!J6 -> 0.14249106 | ... L43: ='Histoirical FC'!L83/'Histoirical FC'!L6 -> 0.10335087 | N43: =AVERAGE(D43:L43) -> 0.14172445 | O43: =MEDIAN(D43:L43) -> 0.14249106
B44: CFO/Total Asset | C44: ='Histoirical FC'!C83/'Histoirical FC'!C69 -> 0.076871685 | D44: ='Histoirical FC'!D83/'Histoirical FC'!D69 -> 0.099624618 | E44: ='Histoirical FC'!E83/'Histoirical FC'!E69 -> 0.034271326 | F44: ='Histoirical FC'!F83/'Histoirical FC'!F69 -> -0.0059984053 | G44: ='Histoirical FC'!G83/'Histoirical FC'!G69 -> 0.11997503 | H44: ='Histoirical FC'!H83/'Histoirical FC'!H69 -> 0.097788826 | I44: ='Histoirical FC'!I83/'Histoirical FC'!I69 -> 0.249351 | J44: ='Histoirical FC'!J83/'Histoirical FC'!J69 -> 0.12308546 | ... L44: ='Histoirical FC'!L83/'Histoirical FC'!L69 -> 0.087946185 | N44: =AVERAGE(D44:L44) -> 0.096559306 | O44: =MEDIAN(D44:L44) -> 0.097788826
B45: CFO/ Total Debt | C45: ='Histoirical FC'!C83/'Histoirical FC'!C54 -> 0.15155892 | D45: ='Histoirical FC'!D83/'Histoirical FC'!D54 -> 0.2149367 | E45: ='Histoirical FC'!E83/'Histoirical FC'!E54 -> 0.071192391 | F45: ='Histoirical FC'!F83/'Histoirical FC'!F54 -> -0.013586979 | G45: ='Histoirical FC'!G83/'Histoirical FC'!G54 -> 0.277009 | H45: ='Histoirical FC'!H83/'Histoirical FC'!H54 -> 0.20944191 | I45: ='Histoirical FC'!I83/'Histoirical FC'!I54 -> 0.68720939 | J45: ='Histoirical FC'!J83/'Histoirical FC'!J54 -> 0.46005001 | ... L45: ='Histoirical FC'!L83/'Histoirical FC'!L54 -> 0.27198465 | N45: =AVERAGE(D45:L45) -> 0.26555529 | O45: =MEDIAN(D45:L45) -> 0.2149367 | P45: (Long Term Only)

Sheet Common Size Statement
B2: ="Common Size Statement-"&'Data Sheet'!B1 -> Common Size Statement-TATA STEEL LTD
B4: Particular | C4: ='Data Sheet'!B16 -> 42094 | D4: ='Data Sheet'!C16 -> 42460 | E4: ='Data Sheet'!D16 -> 42825 | F4: ='Data Sheet'!E16 -> 43190 | G4: ='Data Sheet'!F16 -> 43555 | H4: ='Data Sheet'!G16 -> 43921 | I4: ='Data Sheet'!H16 -> 44286 | J4: ='Data Sheet'!I16 -> 44651 | ... L4: ='Data Sheet'!K16 -> 45382
B5: ='Data Sheet'!A17 -> Sales | C5: ='Data Sheet'!B17/'Data Sheet'!B$17 -> 1 | D5: ='Data Sheet'!C17/'Data Sheet'!C$17 -> 1 | E5: ='Data Sheet'!D17/'Data Sheet'!D$17 -> 1 | F5: ='Data Sheet'!E17/'Data Sheet'!E$17 -> 1 | G5: ='Data Sheet'!F17/'Data Sheet'!F$17 -> 1 | H5: ='Data Sheet'!G17/'Data Sheet'!G$17 -> 1 | I5: ='Data Sheet'!H17/'Data Sheet'!H$17 -> 1 | J5: ='Data Sheet'!I17/'Data Sheet'!I$17 -> 1 | ... L5: ='Data Sheet'!K17/'Data Sheet'!K$17 -> 1
B6: ='Data Sheet'!A18 -> Raw Material Cost | C6: ='Data Sheet'!B18/'Data Sheet'!B$17 -> 0.39099499 | D6: ='Data Sheet'!C18/'Data Sheet'!C$17 -> 0.37950646 | E6: ='Data Sheet'!D18/'Data Sheet'!D$17 -> 0.3904119 | F6: ='Data Sheet'!E18/'Data Sheet'!E$17 -> 0.37433962 | G6: ='Data Sheet'!F18/'Data Sheet'!F$17 -> 0.38610668 | H6: ='Data Sheet'!G18/'Data Sheet'!G$17 -> 0.41511501 | I6: ='Data Sheet'!H18/'Data Sheet'!H$17 -> 0.35460937 | J6: ='Data Sheet'!I18/'Data Sheet'!I$17 -> 0.37332727 | ... L6: ='Data Sheet'!K18/'Data Sheet'!K$17 -> 0.42547479
B7: ='Data Sheet'!A19 -> Change in Inventory | C7: ='Data Sheet'!B19/'Data Sheet'!B$17 -> -0.008044086 | D7: ='Data Sheet'!C19/'Data Sheet'!C$17 -> -0.018880942 | E7: ='Data Sheet'!D19/'Data Sheet'!D$17 -> 0.040410983 | F7: ='Data Sheet'!E19/'Data Sheet'!E$17 -> -0.00080576673 | G7: ='Data Sheet'!F19/'Data Sheet'!F$17 -> 0.00061337363 | H7: ='Data Sheet'!G19/'Data Sheet'!G$17 -> 0.0040427231 | I7: ='Data Sheet'!H19/'Data Sheet'!H$17 -> -0.009704584 | J7: ='Data Sheet'!I19/'Data Sheet'!I$17 -> 0.031144023 | ... L7: ='Data Sheet'!K19/'Data Sheet'!K$17 -> -0.019240455
B8: ='Data Sheet'!A20 -> Power and Fuel | C8: ='Data Sheet'!B20/'Data Sheet'!B$17 -> 0.049069512 | D8: ='Data Sheet'!C20/'Data Sheet'!C$17 -> 0.048976646 | E8: ='Data Sheet'!D20/'Data Sheet'!D$17 -> 0.046490267 | F8: ='Data Sheet'!E20/'Data Sheet'!E$17 -> 0.036028101 | G8: ='Data Sheet'!F20/'Data Sheet'!F$17 -> 0.033719757 | H8: ='Data Sheet'!G20/'Data Sheet'!G$17 -> 0.03804926 | I8: ='Data Sheet'!H20/'Data Sheet'!H$17 -> 0.0370358 | J8: ='Data Sheet'!I20/'Data Sheet'!I$17 -> 0.032908335 | ... L8: ='Data Sheet'!K20/'Data Sheet'!K$17 -> 0.043949102
B9: ='Data Sheet'!A21 -> Other Mfr. Exp | C9: ='Data Sheet'!B21/'Data Sheet'!B$17 -> 0.14602104 | D9: ='Data Sheet'!C21/'Data Sheet'!C$17 -> 0.15725321 | E9: ='Data Sheet'!D21/'Data Sheet'!D$17 -> 0.14068764 | F9: ='Data Sheet'!E21/'Data Sheet'!E$17 -> 0.13757337 | G9: ='Data Sheet'!F21/'Data Sheet'!F$17 -> 0.13150512 | H9: ='Data Sheet'!G21/'Data Sheet'!G$17 -> 0.15186096 | I9: ='Data Sheet'!H21/'Data Sheet'!H$17 -> 0.13272996 | J9: ='Data Sheet'!I21/'Data Sheet'!I$17 -> 0.11819215 | ... L9: ='Data Sheet'!K21/'Data Sheet'!K$17 -> 0.14950903
B10: ='Data Sheet'!A22 -> Employee Cost | C10: ='Data Sheet'!B22/'Data Sheet'!B$17 -> 0.15345568 | D10: ='Data Sheet'!C22/'Data Sheet'!C$17 -> 0.17248741 | E10: ='Data Sheet'!D22/'Data Sheet'!D$17 -> 0.15362697 | F10: ='Data Sheet'!E22/'Data Sheet'!E$17 -> 0.13856096 | G10: ='Data Sheet'!F22/'Data Sheet'!F$17 -> 0.11897628 | H10: ='Data Sheet'!G22/'Data Sheet'!G$17 -> 0.13255632 | I10: ='Data Sheet'!H22/'Data Sheet'!H$17 -> 0.12738037 | J10: ='Data Sheet'!I22/'Data Sheet'!I$17 -> 0.095360629 | ... L10: ='Data Sheet'!K22/'Data Sheet'!K$17 -> 0.10694897
B11: ='Data Sheet'!A23 -> Selling and admin | C11: ='Data Sheet'!B23/'Data Sheet'!B$17 -> 0.11374871 | D11: ='Data Sheet'!C23/'Data Sheet'!C$17 -> 0.12659692 | E11: ='Data Sheet'!D23/'Data Sheet'!D$17 -> 0.12263928 | F11: ='Data Sheet'!E23/'Data Sheet'!E$17 -> 0.11703025 | G11: ='Data Sheet'!F23/'Data Sheet'!F$17 -> 0.10729529 | H11: ='Data Sheet'!G23/'Data Sheet'!G$17 -> 0.11156804 | I11: ='Data Sheet'!H23/'Data Sheet'!H$17 -> 0.10828253 | J11: ='Data Sheet'!I23/'Data Sheet'!I$17 -> 0.11250108 | ... L11: ='Data Sheet'!K23/'Data Sheet'!K$17 -> 0.11849368
B12: ='Data Sheet'!A24 -> Other Expenses | C12: ='Data Sheet'!B24/'Data Sheet'!B$17 -> 0.11423021 | D12: ='Data Sheet'!C24/'Data Sheet'!C$17 -> 0.10243033 | E12: ='Data Sheet'!D24/'Data Sheet'!D$17 -> 0.069513983 | F12: ='Data Sheet'!E24/'Data Sheet'!E$17 -> 0.021760489 | G12: ='Data Sheet'!F24/'Data Sheet'!F$17 -> 0.037062329 | H12: ='Data Sheet'!G24/'Data Sheet'!G$17 -> 0.029993424 | I12: ='Data Sheet'!H24/'Data Sheet'!H$17 -> 0.035085312 | J12: ='Data Sheet'!I24/'Data Sheet'!I$17 -> 0.038606296 | ... L12: ='Data Sheet'!K24/'Data Sheet'!K$17 -> 0.039303876
B13: ='Data Sheet'!A25 -> Other Income | C13: ='Data Sheet'!B25/'Data Sheet'!B$17 -> 0.042969317 | D13: ='Data Sheet'!C25/'Data Sheet'!C$17 -> 0.10146519 | E13: ='Data Sheet'!D25/'Data Sheet'!D$17 -> -0.033741136 | F13: ='Data Sheet'!E25/'Data Sheet'!E$17 -> 0.0884259 | G13: ='Data Sheet'!F25/'Data Sheet'!F$17 -> 0.0096677857 | H13: ='Data Sheet'!G25/'Data Sheet'!G$17 -> -0.020624368 | I13: ='Data Sheet'!H25/'Data Sheet'!H$17 -> 0.0011502668 | J13: ='Data Sheet'!I25/'Data Sheet'!I$17 -> 0.0053287196 | ... L13: ='Data Sheet'!K25/'Data Sheet'!K$17 -> -0.02620417
B14: ='Data Sheet'!A26 -> Depreciation | C14: ='Data Sheet'!B26/'Data Sheet'!B$17 -> 0.042605312 | D14: ='Data Sheet'!C26/'Data Sheet'!C$17 -> 0.052041039 | E14: ='Data Sheet'!D26/'Data Sheet'!D$17 -> 0.050515666 | F14: ='Data Sheet'!E26/'Data Sheet'!E$17 -> 0.046586153 | G14: ='Data Sheet'!F26/'Data Sheet'!F$17 -> 0.046564832 | H14: ='Data Sheet'!G26/'Data Sheet'!G$17 -> 0.060369992 | I14: ='Data Sheet'!H26/'Data Sheet'!H$17 -> 0.059078591 | J14: ='Data Sheet'!I26/'Data Sheet'!I$17 -> 0.03730489 | ... L14: ='Data Sheet'!K26/'Data Sheet'!K$17 -> 0.043121379
B15: ='Data Sheet'!A27 -> Interest | C15: ='Data Sheet'!B27/'Data Sheet'!B$17 -> 0.034749967 | D15: ='Data Sheet'!C27/'Data Sheet'!C$17 -> 0.041400692 | E15: ='Data Sheet'!D27/'Data Sheet'!D$17 -> 0.045166752 | F15: ='Data Sheet'!E27/'Data Sheet'!E$17 -> 0.044257859 | G15: ='Data Sheet'!F27/'Data Sheet'!F$17 -> 0.048583428 | H15: ='Data Sheet'!G27/'Data Sheet'!G$17 -> 0.053880993 | I15: ='Data Sheet'!H27/'Data Sheet'!H$17 -> 0.048669183 | J15: ='Data Sheet'!I27/'Data Sheet'!I$17 -> 0.022389812 | ... L15: ='Data Sheet'!K27/'Data Sheet'!K$17 -> 0.032759717
B16: ='Data Sheet'!A28 -> Profit before tax | C16: ='Data Sheet'!B28/'Data Sheet'!B$17 -> -0.0099501999 | D16: ='Data Sheet'!C28/'Data Sheet'!C$17 -> 0.0018915366 | E16: ='Data Sheet'!D28/'Data Sheet'!D$17 -> -0.012382611 | F16: ='Data Sheet'!E28/'Data Sheet'!E$17 -> 0.17148332 | G16: ='Data Sheet'!F28/'Data Sheet'!F$17 -> 0.10046744 | H16: ='Data Sheet'!G28/'Data Sheet'!G$17 -> -0.0099756359 | I16: ='Data Sheet'!H28/'Data Sheet'!H$17 -> 0.088574571 | J16: ='Data Sheet'!I28/'Data Sheet'!I$17 -> 0.20588228 | ... L16: ='Data Sheet'!K28/'Data Sheet'!K$17 -> -0.0050051756
... B18: ='Data Sheet'!A30 -> Net profit | C18: ='Data Sheet'!B30/'Data Sheet'!B$17 -> -0.028139176 | D18: ='Data Sheet'!C30/'Data Sheet'!C$17 -> -0.0037540436 | E18: ='Data Sheet'!D30/'Data Sheet'!D$17 -> -0.037763329 | F18: ='Data Sheet'!E30/'Data Sheet'!E$17 -> 0.10900147 | G18: ='Data Sheet'!F30/'Data Sheet'!F$17 -> 0.064808749 | H18: ='Data Sheet'!G30/'Data Sheet'!G$17 -> 0.011132723 | I18: ='Data Sheet'!H30/'Data Sheet'!H$17 -> 0.047923857 | J18: ='Data Sheet'!I30/'Data Sheet'!I$17 -> 0.16459283 | ... L18: ='Data Sheet'!K30/'Data Sheet'!K$17 -> -0.019363027
B20: ="Common Size Balance Sheet-"&'Data Sheet'!B1 -> Common Size Balance Sheet-TATA STEEL LTD
B22: Total Liabilites
B23: ='Data Sheet'!A57 -> Equity Share Capital | C23: ='Data Sheet'!B57/'Data Sheet'!B$61 -> 0.0061052999 | D23: ='Data Sheet'!C57/'Data Sheet'!C$61 -> 0.005485177 | E23: ='Data Sheet'!D57/'Data Sheet'!D$61 -> 0.0056262963 | F23: ='Data Sheet'!E57/'Data Sheet'!E$61 -> 0.0054855225 | G23: ='Data Sheet'!F57/'Data Sheet'!F$61 -> 0.0049186883 | H23: ='Data Sheet'!G57/'Data Sheet'!G$61 -> 0.0045954407 | I23: ='Data Sheet'!H57/'Data Sheet'!H$61 -> 0.0049100651 | J23: ='Data Sheet'!I57/'Data Sheet'!I$61 -> 0.0043240662 | ... L23: ='Data Sheet'!K57/'Data Sheet'!K$61 -> 0.0046319438
B24: ='Data Sheet'!A58 -> Reserves | C24: ='Data Sheet'!B58/'Data Sheet'!B$61 -> 0.19092536 | D24: ='Data Sheet'!C58/'Data Sheet'!C$61 -> 0.24175342 | E24: ='Data Sheet'!D58/'Data Sheet'!D$61 -> 0.21368305 | F24: ='Data Sheet'!E58/'Data Sheet'!E$61 -> 0.28614918 | G24: ='Data Sheet'!F58/'Data Sheet'!F$61 -> 0.29118503 | H24: ='Data Sheet'!G58/'Data Sheet'!G$61 -> 0.29071485 | I24: ='Data Sheet'!H58/'Data Sheet'!H$61 -> 0.29946047 | J24: ='Data Sheet'!I58/'Data Sheet'!I$61 -> 0.4008964 | ... L24: ='Data Sheet'!K58/'Data Sheet'!K$61 -> 0.33711152
B25: ='Data Sheet'!A59 -> Borrowings | C25: ='Data Sheet'!B59/'Data Sheet'!B$61 -> 0.50720662 | D25: ='Data Sheet'!C59/'Data Sheet'!C$61 -> 0.46350679 | E25: ='Data Sheet'!D59/'Data Sheet'!D$61 -> 0.48139029 | F25: ='Data Sheet'!E59/'Data Sheet'!E$61 -> 0.44148191 | G25: ='Data Sheet'!F59/'Data Sheet'!F$61 -> 0.43310878 | H25: ='Data Sheet'!G59/'Data Sheet'!G$61 -> 0.46690191 | I25: ='Data Sheet'!H59/'Data Sheet'!H$61 -> 0.36284574 | J25: ='Data Sheet'!I59/'Data Sheet'!I$61 -> 0.26754799 | ... L25: ='Data Sheet'!K59/'Data Sheet'!K$61 -> 0.32334981
B26: ='Data Sheet'!A60 -> Other Liabilities | C26: ='Data Sheet'!B60/'Data Sheet'!B$61 -> 0.29576272 | D26: ='Data Sheet'!C60/'Data Sheet'!C$61 -> 0.28925461 | E26: ='Data Sheet'!D60/'Data Sheet'!D$61 -> 0.29930036 | F26: ='Data Sheet'!E60/'Data Sheet'!E$61 -> 0.26688338 | G26: ='Data Sheet'!F60/'Data Sheet'!F$61 -> 0.27078751 | H26: ='Data Sheet'!G60/'Data Sheet'!G$61 -> 0.2377878 | I26: ='Data Sheet'!H60/'Data Sheet'!H$61 -> 0.33278373 | J26: ='Data Sheet'!I60/'Data Sheet'!I$61 -> 0.32723155 | ... L26: ='Data Sheet'!K60/'Data Sheet'!K$61 -> 0.33490672
B28: Total Asset
B29: ='Data Sheet'!A62 -> Net Block | C29: ='Data Sheet'!B62/'Data Sheet'!B$66 -> 0.42800974 | D29: ='Data Sheet'!C62/'Data Sheet'!C$66 -> 0.40817578 | E29: ='Data Sheet'!D62/'Data Sheet'!D$66 -> 0.53353409 | F29: ='Data Sheet'!E62/'Data Sheet'!E$66 -> 0.46044416 | G29: ='Data Sheet'!F62/'Data Sheet'!F$66 -> 0.53460528 | H29: ='Data Sheet'!G62/'Data Sheet'!G$66 -> 0.54004068 | I29: ='Data Sheet'!H62/'Data Sheet'!H$66 -> 0.55666283 | J29: ='Data Sheet'!I62/'Data Sheet'!I$66 -> 0.47194619 | ... L29: ='Data Sheet'!K62/'Data Sheet'!K$66 -> 0.55257154
B30: ='Data Sheet'!A63 -> Capital Work in Progress | C30: ='Data Sheet'!B63/'Data Sheet'!B$66 -> 0.18024163 | D30: ='Data Sheet'!C63/'Data Sheet'!C$66 -> 0.20350112 | E30: ='Data Sheet'!D63/'Data Sheet'!D$66 -> 0.091530129 | F30: ='Data Sheet'!E63/'Data Sheet'!E$66 -> 0.079600612 | G30: ='Data Sheet'!F63/'Data Sheet'!F$66 -> 0.080083063 | H30: ='Data Sheet'!G63/'Data Sheet'!G$66 -> 0.078253658 | I30: ='Data Sheet'!H63/'Data Sheet'!H$66 -> 0.077928183 | J30: ='Data Sheet'!I63/'Data Sheet'!I$66 -> 0.078058989 | ... L30: ='Data Sheet'!K63/'Data Sheet'!K$66 -> 0.12756757
B31: ='Data Sheet'!A64 -> Investments | C31: ='Data Sheet'!B64/'Data Sheet'!B$66 -> 0.021714947 | D31: ='Data Sheet'!C64/'Data Sheet'!C$66 -> 0.060569133 | E31: ='Data Sheet'!D64/'Data Sheet'!D$66 -> 0.072237228 | F31: ='Data Sheet'!E64/'Data Sheet'!E$66 -> 0.085757409 | G31: ='Data Sheet'!F64/'Data Sheet'!F$66 -> 0.024651309 | H31: ='Data Sheet'!G64/'Data Sheet'!G$66 -> 0.025226579 | I31: ='Data Sheet'!H64/'Data Sheet'!H$66 -> 0.043794701 | J31: ='Data Sheet'!I64/'Data Sheet'!I$66 -> 0.046525644 | ... L31: ='Data Sheet'!K64/'Data Sheet'!K$66 -> 0.023235356
B32: ='Data Sheet'!A65 -> Other Assets | C32: ='Data Sheet'!B74/'Data Sheet'!B66 -> 0.07332117 | D32: ='Data Sheet'!C74/'Data Sheet'!C66 -> 0.11142071 | E32: ='Data Sheet'!D74/'Data Sheet'!D66 -> 0.063137408 | F32: ='Data Sheet'!E74/'Data Sheet'!E66 -> 0.14094796 | G32: ='Data Sheet'!F74/'Data Sheet'!F66 -> 0.1595701 | H32: ='Data Sheet'!G74/'Data Sheet'!G66 -> 0.16780352 | I32: ='Data Sheet'!H74/'Data Sheet'!H66 -> 0.12236636 | J32: ='Data Sheet'!I74/'Data Sheet'!I66 -> 0.13093432 | ... L32: ='Data Sheet'!K74/'Data Sheet'!K66 -> 0.058616606
B33: ='Data Sheet'!A67 -> Receivables | C33: ='Data Sheet'!B67/'Data Sheet'!B$66 -> 0.08365237 | D33: ='Data Sheet'!C67/'Data Sheet'!C$66 -> 0.068215444 | E33: ='Data Sheet'!D67/'Data Sheet'!D$66 -> 0.067190471 | F33: ='Data Sheet'!E67/'Data Sheet'!E$66 -> 0.059483484 | G33: ='Data Sheet'!F67/'Data Sheet'!F$66 -> 0.050740325 | H33: ='Data Sheet'!G67/'Data Sheet'!G$66 -> 0.031647352 | I33: ='Data Sheet'!H67/'Data Sheet'!H$66 -> 0.039112261 | J33: ='Data Sheet'!I67/'Data Sheet'!I$66 -> 0.043362218 | ... L33: ='Data Sheet'!K67/'Data Sheet'!K$66 -> 0.023257487
B34: ='Data Sheet'!A68 -> Inventory | C34: ='Data Sheet'!B68/'Data Sheet'!B$61 -> 0.15806688 | D34: ='Data Sheet'!C68/'Data Sheet'!C$61 -> 0.11314382 | E34: ='Data Sheet'!D68/'Data Sheet'!D$61 -> 0.14383414 | F34: ='Data Sheet'!E68/'Data Sheet'!E$61 -> 0.13573567 | G34: ='Data Sheet'!F68/'Data Sheet'!F$61 -> 0.13599533 | H34: ='Data Sheet'!G68/'Data Sheet'!G$61 -> 0.1246993 | I34: ='Data Sheet'!H68/'Data Sheet'!H$61 -> 0.13642938 | J34: ='Data Sheet'!I68/'Data Sheet'!I$61 -> 0.17287763 | ... L34: ='Data Sheet'!K68/'Data Sheet'!K$61 -> 0.18252968
B35: ='Data Sheet'!A69 -> Cash & Bank | C35: ='Data Sheet'!B69/'Data Sheet'!B$61 -> 0.054993266 | D35: ='Data Sheet'!C69/'Data Sheet'!C$61 -> 0.034973996 | E35: ='Data Sheet'!D69/'Data Sheet'!D$61 -> 0.028536533 | F35: ='Data Sheet'!E69/'Data Sheet'!E$61 -> 0.038030704 | G35: ='Data Sheet'!F69/'Data Sheet'!F$61 -> 0.014354602 | H35: ='Data Sheet'!G69/'Data Sheet'!G$61 -> 0.032328912 | I35: ='Data Sheet'!H69/'Data Sheet'!H$61 -> 0.023706282 | J35: ='Data Sheet'!I69/'Data Sheet'!I$61 -> 0.056295007 | ... L35: ='Data Sheet'!K69/'Data Sheet'!K$61 -> 0.032221759

Sheet Forcasting
B2: ='Data Sheet'!B1& "-" &'Data Sheet'!A17 -> TATA STEEL LTD-Sales | G2: ='Data Sheet'!B1&"-"&'Histoirical FC'!B18 -> TATA STEEL LTD-Operating Income(EBITDA) | L2: ='Data Sheet'!B1&"-"&'Histoirical FC'!B41 -> TATA STEEL LTD-EPS
B3: Weight | C3: Year | D3: Sales | E3: Sales Growth | G3: Weight | H3: Year | I3: Ebitda | J3: Ebitda Growth | L3: Weight | M3: Year | N3: EPS | O3: EPS Growth
B4: 1 | C4: 2015 | D4: {=TRANSPOSE('Data Sheet'!B17:K17)} -> 139503.73 | G4: 1 | H4: 2015 | I4: {=TRANSPOSE('Histoirical FC'!C18:L18)} -> 3408.88 | L4: 1 | M4: 2015 | N4: {=TRANSPOSE('Histoirical FC'!C41:M41)} -> -8.8316202
B5: =B4+1 -> 2 | C5: =C4+1 -> 2016 | D5: 101964.72 | E5: =D5/D4-1 -> -0.26908965 | G5: =G4+1 -> 2 | H5: =H4+1 -> 2016 | I5: -625.24 | J5: =I5/I4-1 -> -1.1834151 | L5: =L4+1 -> 2 | M5: =M4+1 -> 2016 | N5: -9.6243276 | O5: =N5/N4-1 -> 0.089757866
B6: =B5+1 -> 3 | C6: =C5+1 -> 2017 | D6: 112299.42 | E6: =D6/D5-1 -> 0.10135565 | G6: =G5+1 -> 3 | H6: =H5+1 -> 2017 | I6: 13143.63 | J6: =I6/I5-1 -> -22.021736 | L6: =L5+1 -> 3 | M6: =M5+1 -> 2017 | N6: -0.33681277 | O6: =N6/N5-1 -> -0.96500402
B7: =B6+1 -> 4 | C7: =C6+1 -> 2018 | D7: 123249.07 | E7: =D7/D6-1 -> 0.097504065 | G7: =G6+1 -> 4 | H7: =H6+1 -> 2018 | I7: 21433.19 | J7: =I7/I6-1 -> 0.6306903 | L7: =L6+1 -> 4 | M7: =M6+1 -> 2018 | N7: 6.0759357 | O7: =N7/N6-1 -> -19.039505
B8: =B7+1 -> 5 | C8: =C7+1 -> 2019 | D8: 157668.99 | E8: =D8/D7-1 -> 0.27927124 | G8: =G7+1 -> 5 | H8: =H7+1 -> 2019 | I8: 29318.22 | J8: =I8/I7-1 -> 0.36788877 | L8: =L7+1 -> 5 | M8: =M7+1 -> 2019 | N8: 6.7447203 | O8: =N8/N7-1 -> 0.11007106
B9: =B8+1 -> 6 | C9: =C8+1 -> 2020 | D9: 139816.65 | E9: =D9/D8-1 -> -0.1132267 | G9: =G8+1 -> 6 | H9: =H8+1 -> 2020 | I9: 17463.06 | J9: =I9/I8-1 -> -0.40436152 | L9: =L8+1 -> 6 | M9: =M8+1 -> 2020 | N9: 3.6017009 | O9: =N9/N8-1 -> -0.465997
B10: =B9+1 -> 7 | C10: =C9+1 -> 2021 | D10: 156294.18 | E10: =D10/D9-1 -> 0.11785099 | G10: =G9+1 -> 7 | H10: =H9+1 -> 2021 | I10: 30504.26 | J10: =I10/I9-1 -> 0.74678779 | L10: =L9+1 -> 7 | M10: =M9+1 -> 2021 | N10: 6.6940305 | O10: =N10/N9-1 -> 0.85857482
B11: =B10+1 -> 8 | C11: =C10+1 -> 2022 | D11: 243959.17 | E11: =D11/D10-1 -> 0.56089734 | G11: =G10+1 -> 8 | H11: =H10+1 -> 2022 | I11: 63489.95 | J11: =I11/I10-1 -> 1.081347 | L11: =L10+1 -> 8 | M11: =M10+1 -> 2022 | N11: 33.119897 | O11: =N11/N10-1 -> 3.9476764
B12: =B11+1 -> 9 | C12: =C11+1 -> 2023 | D12: 243352.69 | E12: =D12/D11-1 -> -0.0024859898 | G12: =G11+1 -> 9 | H12: =H11+1 -> 2023 | I12: 32300.16 | J12: =I12/I11-1 -> -0.49125555 | L12: =L11+1 -> 9 | M12: =M11+1 -> 2023 | N12: 5.3238064 | O12: =N12/N11-1 -> -0.83925655
B13: =B12+1 -> 10 | C13: =C12+1 -> 2024 | D13: 229170.78 | E13: =D13/D12-1 -> -0.058277186 | G13: =G12+1 -> 10 | H13: =H12+1 -> 2024 | I13: 22247.92 | J13: =I13/I12-1 -> -0.31121332 | L13: =L12+1 -> 10 | M13: =M12+1 -> 2024 | N13: 0.8776545 | O13: =N13/N12-1 -> -0.8351453
B14: =B13+1 -> 11 | C14: =C13+1 -> 2025 | D14: =FORECAST(B14,$D$4:$D$13,$B$4:$B$13) -> 249271.31 | E14: =D14/D13-1 -> 0.087709812 | G14: =G13+1 -> 11 | H14: =H13+1 -> 2025 | I14: =FORECAST(G14,$I$4:$I$13,$G$4:$G$13) -> 45505.697 | J14: =I14/I13-1 -> 1.0453911 | L14: =L13+1 -> 11 | M14: =M13+1 -> 2025 | N14: =FORECAST(L14,$N$4:$N$13,$L$4:$L$13) -> 16.298339 | O14: =N14/N13-1 -> 17.570336
B15: =B14+1 -> 12 | C15: =C14+1 -> 2026 | D15: =FORECAST(B15,$D$4:$D$13,$B$4:$B$13) -> 264642.83 | E15: =D15/D14-1 -> 0.061665826 | G15: =G14+1 -> 12 | H15: =H14+1 -> 2026 | I15: =FORECAST(G15,$I$4:$I$13,$G$4:$G$13) -> 49548.841 | J15: =I15/I14-1 -> 0.08884919 | L15: =L14+1 -> 12 | M15: =M14+1 -> 2026 | N15: =FORECAST(L15,$N$4:$N$13,$L$4:$L$13) -> 18.468128 | O15: =N15/N14-1 -> 0.13312947
B16: =B15+1 -> 13 | C16: =C15+1 -> 2027 | D16: =FORECAST(B16,$D$4:$D$13,$B$4:$B$13) -> 280014.35 | E16: =D16/D15-1 -> 0.058084027 | G16: =G15+1 -> 13 | H16: =H15+1 -> 2027 | I16: =FORECAST(G16,$I$4:$I$13,$G$4:$G$13) -> 53591.985 | J16: =I16/I15-1 -> 0.08159917 | L16: =L15+1 -> 13 | M16: =M15+1 -> 2027 | N16: =FORECAST(L16,$N$4:$N$13,$L$4:$L$13) -> 20.637918 | O16: =N16/N15-1 -> 0.11748831
B17: =B16+1 -> 14 | C17: =C16+1 -> 2028 | D17: =FORECAST(B17,$D$4:$D$13,$B$4:$B$13) -> 295385.87 | E17: =D17/D16-1 -> 0.054895477 | G17: =G16+1 -> 14 | H17: =H16+1 -> 2028 | I17: =FORECAST(G17,$I$4:$I$13,$G$4:$G$13) -> 57635.13 | J17: =I17/I16-1 -> 0.075443078 | L17: =L16+1 -> 14 | M17: =M16+1 -> 2028 | N17: =FORECAST(L17,$N$4:$N$13,$L$4:$L$13) -> 22.807707 | O17: =N17/N16-1 -> 0.10513605
B18: =B17+1 -> 15 | C18: =C17+1 -> 2029 | D18: =FORECAST(B18,$D$4:$D$13,$B$4:$B$13) -> 310757.39 | E18: =D18/D17-1 -> 0.052038783 | G18: =G17+1 -> 15 | H18: =H17+1 -> 2029 | I18: =FORECAST(G18,$I$4:$I$13,$G$4:$G$13) -> 61678.274 | J18: =I18/I17-1 -> 0.070150693 | L18: =L17+1 -> 15 | M18: =M17+1 -> 2029 | N18: =FORECAST(L18,$N$4:$N$13,$L$4:$L$13) -> 24.977496 | O18: =N18/N17-1 -> 0.095134037

Sheet DCF>
B2: The Valuation School
B6: Calculation of PV of FCFF | E6: ='Intrinsic Growth'!K2 -> 45382 | F6: =E6+365 -> 45747 | G6: =F6+365 -> 46112 | H6: =G6+365 -> 46477 | I6: =H6+365 -> 46842 | J6: =I6+365 -> 47207
B8: EBIT | E8: ='Histoirical FC'!L24 -> 12365.76 | F8: =E8*(1+$E$18) -> 13659.218 | G8: =F8*(1+$E$18) -> 15087.973 | H8: =G8*(1+$E$18) -> 16666.175 | I8: =H8*(1+$E$18) -> 18409.457 | J8: =I8*(1+$E$18) -> 20335.086
B9: Tax Rate | E9: 0.25 | F9: =E9 -> 0.25 | G9: =F9 -> 0.25 | H9: =G9 -> 0.25 | I9: =H9 -> 0.25 | J9: =I9 -> 0.25
B10: EBIT(1-Tax) | E10: =E8*(1-E9) -> 9274.32 | F10: =F8*(1-F9) -> 10244.414 | G10: =G8*(1-G9) -> 11315.98 | H10: =H8*(1-H9) -> 12499.631 | I10: =I8*(1-I9) -> 13807.092 | J10: =J8*(1-J9) -> 15251.314
B11: Less:Reinvestment Rate | E11: 0.703 | F11: =E11 -> 0.703 | G11: =F11 -> 0.703 | H11: =G11 -> 0.703 | I11: =H11 -> 0.703 | J11: =I11 -> 0.703
B12: Free Cashflow to the Firm | E12: =E10*(1-E11) -> 2754.473 | F12: =F10*(1-F11) -> 3042.5909 | G12: =G10*(1-G11) -> 3360.8459 | H12: =H10*(1-H11) -> 3712.3904 | I12: =I10*(1-I11) -> 4100.7065 | J12: =J10*(1-J11) -> 4529.6403
B13: Mid Year Conversion | F13: 0.5 | G13: =F13+1 -> 1.5 | H13: =G13+1 -> 2.5 | I13: =H13+1 -> 3.5 | J13: =I13+1 -> 4.5
B14: Discounting Factor | F14: =1/(1+$E$20)^F13 -> 0.94660588 | G14: =1/(1+$E$20)^G13 -> 0.8482182 | H14: =1/(1+$E$20)^H13 -> 0.76005668 | I14: =1/(1+$E$20)^I13 -> 0.68105843 | J14: =1/(1+$E$20)^J13 -> 0.61027104
B16: PV of FCFF | F16: =F12*F14 -> 2880.1344 | G16: =G12*G14 -> 2850.7307 | H16: =H12*H14 -> 2821.6271 | I16: =I12*I14 -> 2792.8207 | J16: =J12*J14 -> 2764.3083
B18: Expected Growth rate | E18: 0.1046
B19: Terminal Growth | E19: 0.067
B20: Wacc | E20: =WACC!J42 -> 0.11599335
B22: Calculation of Terminal Value
B24: FCFF(n+1) | D24: =J12*(1+E18) -> 5003.4407
B25: WACC | D25: =E20 -> 0.11599335
B26: Terminal Growth Rate | D26: =E19 -> 0.067
B28: Terminal Value | D28: =D24/(D25-D26) -> 102124.89 | F28: Sensitivity Analysis
F29: =D42 -> 2.8334964 | G29: 0.1 | H29: =D25 -> 0.11599335 | I29: 0.13 | J29: 0.14
B30: Calculation of Equity Value | F30: 0.04 | G30: -6.3249269 | H30: -6.3249269 | I30: -19.913742 | J30: -22.631505
F31: 0.05 | G31: 1.828362 | H31: 1.828362 | I31: -16.516538 | J31: -19.913742
B32: PV of FCFF | D32: =SUM(F16:J16) -> 14109.621 | F32: =D26 -> 0.067 | G32: 1.828362 | H32: 1.828362 | I32: -16.516538 | J32: -19.913742
B33: Terminal Value | D33: =D28*J14 -> 62323.863 | F33: 0.08 | G33: 75.207962 | H33: 75.207962 | I33: 1.828362 | J33: -6.3249269
B34: Operating Asset | D34: =SUM(D32:D33) -> 76433.484 | F34: 0.09 | G34: 197.5073 | H34: 197.5073 | I34: 14.058295 | J34: 1.828362
B36: Add Cash | D36: ='Data Sheet'!K69 -> 8677.72
B37: Less Debt | D37: ='Raw FC'!N7+'Raw FC'!N8 -> 81574
B39: Value of Equity | D39: =D34+D36-D37 -> 3537.204 | E39: (FCFE)
B40: No of Share | D40: ='Data Sheet'!B6 -> 1248.3531
B42: Equity Value Per Share | D42: =D39/D40 -> 2.8334964
B44: Share price | D44: 131
B45: Discount/Premium | D45: =D44/D42 -> 46.232633

Sheet WACC
B2: Weighted Average Cost of Capital
B4: All Fig Are in INR as Stated Below
B6: PeerComs
G7: Debt / | H7: Debt / | I7: Levered | J7: Unlevered
B8: Name of Comps | C8: Country | D8: Total Debt | E8: Toatal Equity | F8: TaxRate 1 | G8: Equity | H8: Capital | I8: Beta 2 | J8: Beta 3
B10: ='Peer Comps'!C4 -> JSW Steel | C10: India | D10: ='Peer Comps'!D4 -> 95258 | E10: ='Peer Comps'!E4 -> 245951.53 | F10: 0.3 | G10: =D10/E10 -> 0.38730395 | H10: =D10/(E10+D10) -> 0.27917743 | I10: 1.09 | J10: =I10/(1+(1-F10*G10)) -> 0.57861498
B11: ='Peer Comps'!C5 -> Tata Steel | C11: India | D11: ='Peer Comps'!D5 -> 99391.76 | E11: ='Peer Comps'!E5 -> 175256.24 | F11: 0.3 | G11: =D11/E11 -> 0.56712252 | H11: =D11/(E11+D11) -> 0.3618878 | I11: =Beta!P6 -> 2.6354669 | J11: =I11/(1+(1-F11*G11)) -> 1.4402535
B12: ='Peer Comps'!C6 -> Jindal Steel | C12: India | D12: ='Peer Comps'!D6 -> 17266.45 | E12: ='Peer Comps'!E6 -> 86717.69 | F12: 0.3 | G12: =D12/E12 -> 0.19911105 | H12: =D12/(E12+D12) -> 0.16604888 | I12: 1.03 | J12: =I12/(1+(1-F12*G12)) -> 0.53085486
B13: ='Peer Comps'!C7 -> Tube Investments | C13: India | D13: ='Peer Comps'!D7 -> 698.92 | E13: ='Peer Comps'!E7 -> 51029.18 | F13: 0.3 | G13: =D13/E13 -> 0.013696477 | H13: =D13/(E13+D13) -> 0.013511418 | I13: 0.61 | J13: =I13/(1+(1-F13*G13)) -> 0.3056279
B14: ='Peer Comps'!C8 -> S A I L | C14: India | D14: ='Peer Comps'!D8 -> 41265.03 | E14: ='Peer Comps'!E8 -> 46509.71 | F14: 0.3 | G14: =D14/E14 -> 0.88723473 | H14: =D14/(E14+D14) -> 0.47012421 | I14: 1.17 | J14: =I14/(1+(1-F14*G14)) -> 0.67480681
E16: Average | F16: =AVERAGE(F10:F14) -> 0.3 | G16: =AVERAGE(G10:G14) -> 0.41089374 | H16: =AVERAGE(H10:H14) -> 0.25814995 | I16: =MEDIAN(I9:I13) -> 1.06 | J16: =MEDIAN(J9:J13) -> 0.55473492
E17: Median | F17: =MEDIAN(F10:F14) -> 0.3 | G17: =MEDIAN(G10:G14) -> 0.38730395 | H17: =MEDIAN(H10:H14) -> 0.27917743 | I17: =MEDIAN(I10:I14) -> 1.09 | J17: =MEDIAN(J10:J14) -> 0.57861498
B20: Cost of Debt | G20: Cost of Equity
B22: Pre Cost of Debt | C22: int/debt) | E22: ='Data Sheet'!K27/WACC!D11 -> 0.075535135 | G22: RisK Free Rate | J22: 0.0646 | K22: 10 YEARS GOVERNMENT BOND
B23: Tax Rate | E23: 0.3 | G23: Equity Risk Premium | J23: =RM!G8-WACC!J22 -> 0.101948 | K23: prime investors sae yearly return for nifty
B24: Post Cost of Debt | E24: =E22*(1-E23) -> 0.052874594 | G24: Levered Beta 4 | J24: =J33 -> 0.71955802
G25: Cost Of Equity | J25: =J22+J23*J24 -> 0.1379575
B28: Capital Structure | G28: Levered Beta
D29: Current | E29: Target
B30: Debt | C30: =D11 -> 99391.76 | D30: =C30/$C$32 -> 0.3618878 | E30: =H16 -> 0.25814995 | G30: Comps Median Unleverd Beta | J30: =J17 -> 0.57861498
B31: Market Capitalization | C31: =E11 -> 175256.24 | D31: =C31/$C$32 -> 0.6381122 | E31: =E32-E30 -> 0.74185005 | G31: Target Debt / Equity | J31: =E34 -> 0.3479813 | K31: BETA ALWAYS BE TAKEN OF THESE MOSTOF THE TIME COMPARABEL COMPS KA BETA BOLTA HAI NIKAL NAE
B32: Total Capital | C32: =SUM(C30:C31) -> 274648 | D32: =C32/$C$32 -> 1 | E32: =D32 -> 1 | G32: Tax Rate | J32: =F14 -> 0.3
G33: Levered Beta | J33: =J30*(1+(1-J32)*J31) -> 0.71955802
B34: Debt/Equity | D34: =D30/D31 -> 0.56712252 | E34: =E30/E31 -> 0.3479813
G35: Weighted Average Cost of Capital
B36: Notes
A37: 1 | B37: Tax Rate Is Considerd as Marginal Tax Rate of Country . | G37: Cost of Equity | J37: =J25 -> 0.1379575
A38: 2 | B38: Levered Beta is based in on 5 year monthly Data. | G38: Weight of Equity | J38: =E31 -> 0.74185005
A39: 3 | B39: Unlevered Beta= Levered Beta/(1+(1-Tax Rate)*Debt/ Equity)
A40: 4 | B40: Levered Beta= Unlevered Beta*(1+(1-Tax Rate)*Debt/ Equity) | G40: Cost of Debt | J40: =E24 -> 0.052874594
G41: Weight of Debt | J41: =E30 -> 0.25814995
G42: WACC | J42: =(J37*J38)+(J40*J41) -> 0.11599335

Sheet Relative Valuation
B2: Amount are In Crores
B3: Comparabel Companies Valuation
D5: Market Data | J5: Financial | N5: Valuation
B6: Companies | C6: Ticker | D6: Share Price | E6: Outstanding Share | F6: Equity Value | G6: Net Debt | H6: Enterprise Value | J6: Revenue | K6: EBITDA | L6: Income | N6: Ev/Revenue | O6: EV/Ebitda | P6: P/E
B8: ='Rough Data Relative valuation'!C4 -> Tata Steel | D8: ='Rough Data Relative valuation'!D4 -> 130.2 | E8: ='Rough Data Relative valuation'!M3 -> 244.55 | F8: =D8*E8 -> 31840.41 | G8: ='Rough Data Relative valuation'!L4 -> 90714.04 | H8: =F8+G8 -> 122554.45 | J8: ='Rough Data Relative valuation'!G4 -> 221011.71 | K8: ='Rough Data Relative valuation'!J4 -> 26734.912 | L8: ='Rough Data Relative valuation'!N4 -> 2831.41 | N8: =H8/J8 -> 0.55451564 | O8: =H8/K8 -> 4.5840604 | P8: =F8/L8 -> 11.245425
B9: ='Rough Data Relative valuation'!C3 -> JSW Steel | D9: ='Rough Data Relative valuation'!D3 -> 956.2 | E9: ='Rough Data Relative valuation'!M3 -> 244.55 | F9: =D9*E9 -> 233838.71 | G9: ='Rough Data Relative valuation'!L3 -> 82910 | H9: =F9+G9 -> 316748.71 | J9: ='Rough Data Relative valuation'!G3 -> 170274 | K9: ='Rough Data Relative valuation'!J3 -> 23188.736 | L9: ='Rough Data Relative valuation'!N3 -> 3498.48 | N9: =H9/J9 -> 1.8602295 | O9: =H9/K9 -> 13.659593 | P9: =F9/L9 -> 66.840088
B10: ='Rough Data Relative valuation'!C5 -> Jindal Steel | D10: ='Rough Data Relative valuation'!D5 -> 801.35 | E10: ='Rough Data Relative valuation'!M5 -> 102.01 | F10: =D10*E10 -> 81745.714 | G10: ='Rough Data Relative valuation'!L5 -> 13242.32 | H10: =F10+G10 -> 94988.034 | J10: ='Rough Data Relative valuation'!G5 -> 50068.78 | K10: ='Rough Data Relative valuation'!J5 -> 9799.463 | L10: ='Rough Data Relative valuation'!N5 -> 4082.33 | N10: =H10/J10 -> 1.8971509 | O10: =H10/K10 -> 9.6931876 | P10: =F10/L10 -> 20.024279
B11: ='Rough Data Relative valuation'!C6 -> Tube Investments | D11: ='Rough Data Relative valuation'!D6 -> 2570 | E11: ='Rough Data Relative valuation'!M6 -> 19.35 | F11: =D11*E11 -> 49729.5 | G11: ='Rough Data Relative valuation'!L6 -> -528.48 | H11: =F11+G11 -> 49201.02 | J11: ='Rough Data Relative valuation'!G6 -> 18804.8 | K11: ='Rough Data Relative valuation'!J6 -> 2256.1681 | L11: ='Rough Data Relative valuation'!N6 -> 819.65 | N11: =H11/J11 -> 2.6164075 | O11: =H11/K11 -> 21.807338 | P11: =F11/L11 -> 60.671628
