Workbook
Name UPDATE: 'Data Sheet'!$E$1

Sheet Financials>

Sheet HistoricalFS
B2: ="Historical Financial Statement- "&'Data Sheet'!B1 -> Historical Financial Statement- TATA MOTORS LTD
B3: Years | C3: ='Data Sheet'!B16 -> 42094 | D3: ='Data Sheet'!C16 -> 42460 | E3: ='Data Sheet'!D16 -> 42825 | F3: ='Data Sheet'!E16 -> 43190 | G3: ='Data Sheet'!F16 -> 43555 | H3: ='Data Sheet'!G16 -> 43921 | I3: ='Data Sheet'!H16 -> 44286 | J3: ='Data Sheet'!I16 -> 44651 | ... L3: ='Data Sheet'!K16 -> 45382 | M3: LTM
A5: # | B5: Income Statement
B6: Sales | C6: =IFERROR('Data Sheet'!B17,0) -> 263158.98 | D6: =IFERROR('Data Sheet'!C17,0) -> 273045.6 | E6: =IFERROR('Data Sheet'!D17,0) -> 269692.51 | F6: =IFERROR('Data Sheet'!E17,0) -> 291550.48 | G6: =IFERROR('Data Sheet'!F17,0) -> 301938.4 | H6: =IFERROR('Data Sheet'!G17,0) -> 261067.97 | I6: =IFERROR('Data Sheet'!H17,0) -> 249794.75 | J6: =IFERROR('Data Sheet'!I17,0) -> 278453.62 | ... L6: =IFERROR('Data Sheet'!K17,0) -> 437927.77 | M6: =IFERROR(SUM('Data Sheet'!H42:K42),0) -> 440061.14
B7: Sales Growth | D7: =D6/C6-1 -> 0.037569001 | E7: =E6/D6-1 -> -0.01228033 | F7: =F6/E6-1 -> 0.081047746 | G7: =G6/F6-1 -> 0.035629919 | H7: =H6/G6-1 -> -0.13536016 | I7: =I6/H6-1 -> -0.043181168 | J7: =J6/I6-1 -> 0.11472967 | K7: =K6/J6-1 -> 0.24245815 | ... M7: =M6/L6-1 -> 0.0048715111
B8: COGS | C8: =IFERROR(SUM('Data Sheet'!B18:B18,'Data Sheet'!B20:B22)-1*'Data Sheet'!B19,0) -> 202856.88 | D8: =IFERROR(SUM('Data Sheet'!C18:C18,'Data Sheet'!C20:C22)-1*'Data Sheet'!C19,0) -> 205509.07 | E8: =IFERROR(SUM('Data Sheet'!D18:D18,'Data Sheet'!D20:D22)-1*'Data Sheet'!D19,0) -> 205454.24 | F8: =IFERROR(SUM('Data Sheet'!E18:E18,'Data Sheet'!E20:E22)-1*'Data Sheet'!E19,0) -> 228429.83 | G8: =IFERROR(SUM('Data Sheet'!F18:F18,'Data Sheet'!F20:F22)-1*'Data Sheet'!F19,0) -> 242845.53 | H8: =IFERROR(SUM('Data Sheet'!G18:G18,'Data Sheet'!G20:G22)-1*'Data Sheet'!G19,0) -> 210376.07 | I8: =IFERROR(SUM('Data Sheet'!H18:H18,'Data Sheet'!H20:H22)-1*'Data Sheet'!H19,0) -> 195326.04 | J8: =IFERROR(SUM('Data Sheet'!I18:I18,'Data Sheet'!I20:I22)-1*'Data Sheet'!I19,0) -> 223300.01 | ... L8: =IFERROR(SUM('Data Sheet'!K18:K18,'Data Sheet'!K20:K22)-1*'Data Sheet'!K19,0) -> 334551.79 | M8: =SUM('Data Sheet'!H43:K43) -> 379563.77
B9: Cogs % Sales | C9: =C8/C6 -> 0.77085297 | D9: =D8/D6 -> 0.75265476 | E9: =E8/E6 -> 0.76180922 | F9: =F8/F6 -> 0.7835001 | G9: =G8/G6 -> 0.80428833 | H9: =H8/H6 -> 0.80582873 | I9: =I8/I6 -> 0.78194614 | J9: =J8/J6 -> 0.80192892 | ... M9: =M8/M6 -> 0.86252508
B11: Gross Profit | C11: =C6-C8 -> 60302.1 | D11: =D6-D8 -> 67536.53 | E11: =E6-E8 -> 64238.27 | F11: =F6-F8 -> 63120.65 | G11: =G6-G8 -> 59092.87 | H11: =H6-H8 -> 50691.9 | I11: =I6-I8 -> 54468.71 | J11: =J6-J8 -> 55153.61 | ... M11: =M6-M8 -> 60497.37
B12: Gross Margins | C12: =C11/C6 -> 0.22914703 | D12: =D11/D6 -> 0.24734524 | E12: =E11/E6 -> 0.23819078 | F12: =F11/F6 -> 0.2164999 | G12: =G11/G6 -> 0.19571167 | H12: =H11/H6 -> 0.19417127 | I12: =I11/I6 -> 0.21805386 | J12: =J11/J6 -> 0.19807108 | ... M12: =M11/M6 -> 0.13747492
B14: Selling & Genral Expense | C14: =IFERROR(SUM('Data Sheet'!B23:B24),0) -> 21063.45 | D14: =IFERROR(SUM('Data Sheet'!C23:C24),0) -> 29141.28 | E14: =IFERROR(SUM('Data Sheet'!D23:D24),0) -> 34649.58 | F14: =IFERROR(SUM('Data Sheet'!E23:E24),0) -> 31662.97 | G14: =IFERROR(SUM('Data Sheet'!F23:F24),0) -> 34428.54 | H14: =IFERROR(SUM('Data Sheet'!G23:G24),0) -> 32704.83 | I14: =IFERROR(SUM('Data Sheet'!H23:H24),0) -> 22181.28 | J14: =IFERROR(SUM('Data Sheet'!I23:I24),0) -> 30433.52 | ... L14: =IFERROR(SUM('Data Sheet'!K23:K24),0) -> 43837.64
B15: S&G Exp % Sales | C15: =C14/C6 -> 0.08004078 | D15: =D14/D6 -> 0.10672679 | E15: =E14/E6 -> 0.1284781 | F15: =F14/F6 -> 0.10860202 | G15: =G14/G6 -> 0.11402505 | H15: =H14/H6 -> 0.12527324 | I15: =I14/I6 -> 0.088798023 | J15: =J14/J6 -> 0.10929475 | ... M15: =M14/M6 -> 0
B17: EBITDA | C17: =C11-C14 -> 39238.65 | D17: =D11-D14 -> 38395.25 | E17: =E11-E14 -> 29588.69 | F17: =F11-F14 -> 31457.68 | G17: =G11-G14 -> 24664.33 | H17: =H11-H14 -> 17987.07 | I17: =I11-I14 -> 32287.43 | J17: =J11-J14 -> 24720.09 | ... L17: =L11-L14 -> 59538.34 | M17: =IFERROR(SUM('Data Sheet'!H50:K50),0) -> 60497.37
B18: EBITDA Margins | C18: =C17/C6 -> 0.14910626 | D18: =D17/D6 -> 0.14061845 | E18: =E17/E6 -> 0.10971269 | F18: =F17/F6 -> 0.10789788 | G18: =G17/G6 -> 0.081686629 | H18: =H17/H6 -> 0.068898034 | I18: =I17/I6 -> 0.12925584 | J18: =J17/J6 -> 0.088776328 | ... M18: =M17/M6 -> 0.13747492
B20: Intrest | C20: ='Data Sheet'!B27 -> 4861.49 | D20: ='Data Sheet'!C27 -> 4889.08 | E20: ='Data Sheet'!D27 -> 4238.01 | F20: ='Data Sheet'!E27 -> 4681.79 | G20: ='Data Sheet'!F27 -> 5758.6 | H20: ='Data Sheet'!G27 -> 7243.33 | I20: ='Data Sheet'!H27 -> 8097.17 | J20: ='Data Sheet'!I27 -> 9311.86 | ... L20: ='Data Sheet'!K27 -> 9985.76 | M20: =IFERROR(SUM('Data Sheet'!H46:K46),0) -> 8840.91
B21: Intrest % of Sale | C21: =C20/C6 -> 0.018473586 | D21: =D20/D6 -> 0.017905727 | E21: =E20/E6 -> 0.01571423 | F21: =F20/F6 -> 0.016058248 | G21: =G20/G6 -> 0.019072102 | H21: =H20/H6 -> 0.027744997 | I21: =I20/I6 -> 0.032415293 | J21: =J20/J6 -> 0.033441332 | ... M21: =M20/M6 -> 0.020090186
B23: Depriciation | C23: =IFERROR('Data Sheet'!B26,0) -> 13388.63 | D23: =IFERROR('Data Sheet'!C26,0) -> 16710.78 | E23: =IFERROR('Data Sheet'!D26,0) -> 17904.99 | F23: =IFERROR('Data Sheet'!E26,0) -> 21553.59 | G23: =IFERROR('Data Sheet'!F26,0) -> 23590.63 | H23: =IFERROR('Data Sheet'!G26,0) -> 21425.43 | I23: =IFERROR('Data Sheet'!H26,0) -> 23546.71 | J23: =IFERROR('Data Sheet'!I26,0) -> 24835.69 | ... L23: =IFERROR('Data Sheet'!K26,0) -> 27270.13 | M23: =IFERROR(SUM('Data Sheet'!H45:K45),0) -> 26580
B24: Depriciation % of Sale | C24: =C23/C6 -> 0.050876584 | D24: =D23/D6 -> 0.061201426 | E24: =E23/E6 -> 0.066390387 | F24: =F23/F6 -> 0.073927472 | G24: =G23/G6 -> 0.078130605 | H24: =H23/H6 -> 0.082068398 | I24: =I23/I6 -> 0.094264231 | J24: =J23/J6 -> 0.089191478 | ... M24: =M23/M6 -> 0.060400698
B26: Earning Befor Tax | C26: =IFERROR(C17-(C23+C20),0) -> 20988.53 | D26: =IFERROR(D17-(D23+D20),0) -> 16795.39 | E26: =IFERROR(E17-(E23+E20),0) -> 7445.69 | F26: =IFERROR(F17-(F23+F20),0) -> 5222.3 | G26: =IFERROR(G17-(G23+G20),0) -> -4684.9 | H26: =IFERROR(H17-(H23+H20),0) -> -10681.69 | I26: =IFERROR(I17-(I23+I20),0) -> 643.55 | J26: =IFERROR(J17-(J23+J20),0) -> -9427.46 | ... M26: =IFERROR(M17-(M23+M20),0) -> 25076.46
B27: Ebt % of Sale | C27: =C26/C6 -> 0.079756085 | D27: =D26/D6 -> 0.061511301 | E27: =E26/E6 -> 0.027608071 | F27: =F26/F6 -> 0.017912164 | G27: =G26/G6 -> -0.015516079 | H27: =H26/H6 -> -0.04091536 | I27: =I26/I6 -> 0.0025763152 | J27: =J26/J6 -> -0.033856482 | ... M27: =M26/M6 -> 0.056984036
B29: Tax | C29: =IFERROR('Data Sheet'!B29,0) -> 7642.91 | D29: =IFERROR('Data Sheet'!C29,0) -> 3025.05 | E29: =IFERROR('Data Sheet'!D29,0) -> 3251.23 | F29: =IFERROR('Data Sheet'!E29,0) -> 4341.93 | G29: =IFERROR('Data Sheet'!F29,0) -> -2437.45 | H29: =IFERROR('Data Sheet'!G29,0) -> 395.25 | I29: =IFERROR('Data Sheet'!H29,0) -> 2541.86 | J29: =IFERROR('Data Sheet'!I29,0) -> 4231.29 | ... L29: =IFERROR('Data Sheet'!K29,0) -> -3851.64 | M29: =IFERROR(SUM('Data Sheet'!H48:K48),0) -> -2123.21
B30: Effective Tax Rate | C30: =C29/C26 -> 0.36414699 | D30: =D29/D26 -> 0.18011192 | E30: =E29/E26 -> 0.43665933 | F30: =F29/F26 -> 0.83142102 | G30: =G29/G26 -> 0.52027791 | H30: =H29/H26 -> -0.037002572 | I30: =I29/I26 -> 3.9497475 | J30: =J29/J26 -> -0.44882609 | ... M30: =M29/M26 -> -0.084669447
B32: Net Profit | C32: =C26-C29 -> 13345.62 | D32: =D26-D29 -> 13770.34 | E32: =E26-E29 -> 4194.46 | F32: =F26-F29 -> 880.37 | G32: =G26-G29 -> -2247.45 | H32: =H26-H29 -> -11076.94 | I32: =I26-I29 -> -1898.31 | J32: =J26-J29 -> -13658.75 | ... M32: =M26-M29 -> 27199.67
B33: Net Margin | C33: =C32/C6 -> 0.050713147 | D33: =D32/D6 -> 0.050432382 | E33: =E32/E6 -> 0.015552749 | F33: =F32/F6 -> 0.0030196143 | G33: =G32/G6 -> -0.0074434057 | H33: =H32/H6 -> -0.042429334 | I33: =I32/I6 -> -0.0075994792 | J33: =J32/J6 -> -0.049052155 | ... M33: =M32/M6 -> 0.061808843
B35: No of Equity Share | C35: =IFERROR('Data Sheet'!B93,0) -> 288.74 | D35: =IFERROR('Data Sheet'!C93,0) -> 288.72 | E35: =IFERROR('Data Sheet'!D93,0) -> 288.73 | F35: =IFERROR('Data Sheet'!E93,0) -> 288.73 | G35: =IFERROR('Data Sheet'!F93,0) -> 288.73 | H35: =IFERROR('Data Sheet'!G93,0) -> 308.9 | I35: =IFERROR('Data Sheet'!H93,0) -> 332.03 | J35: =IFERROR('Data Sheet'!I93,0) -> 332.07 | ... M35: =IFERROR('Data Sheet'!L93,0) -> 0
B37: EPS | C37: =C32/C35 -> 46.220198 | D37: =D32/D35 -> 47.694444 | E37: =E32/E35 -> 14.527275 | F37: =F32/F35 -> 3.0491116 | G37: =G32/G35 -> -7.7839158 | H37: =H32/H35 -> -35.859307 | I37: =I32/I35 -> -5.7172846 | J37: =J32/J35 -> -41.132141 | ... L37: =L32/L35 -> 78.629509
B38: Earning per Growth | D38: =IFERROR(D37/C37-1,0) -> 0.031896149 | E38: =IFERROR(E37/D37-1,0) -> -0.6954095 | F38: =IFERROR(F37/E37-1,0) -> -0.79011124 | G38: =IFERROR(G37/F37-1,0) -> -3.5528471 | H38: =IFERROR(H37/G37-1,0) -> 3.6068468 | I38: =IFERROR(I37/H37-1,0) -> -0.84056344 | J38: =IFERROR(J37/I37-1,0) -> 6.194349 | K38: =IFERROR(K37/J37-1,0) -> -0.70909622 | L38: =IFERROR(L37/K37-1,0) -> -7.5713542
B40: Divident Per Share | D40: =IFERROR('Data Sheet'!C31/HistoricalFS!D35,0) -> 0.23524522 | E40: =IFERROR('Data Sheet'!D31/HistoricalFS!E35,0) -> 0 | F40: =IFERROR('Data Sheet'!E31/HistoricalFS!F35,0) -> 0 | G40: =IFERROR('Data Sheet'!F31/HistoricalFS!G35,0) -> 0 | H40: =IFERROR('Data Sheet'!G31/HistoricalFS!H35,0) -> 0 | I40: =IFERROR('Data Sheet'!H31/HistoricalFS!I35,0) -> 0 | J40: =IFERROR('Data Sheet'!I31/HistoricalFS!J35,0) -> 0 | K40: =IFERROR('Data Sheet'!J31/HistoricalFS!K35,0) -> 2.3063861 | L40: =IFERROR('Data Sheet'!K31/HistoricalFS!L35,0) -> 6.9184944
B41: Divident payoot ratio | D41: =IFERROR(D40/D37,0) -> 0.0049323401 | E41: =IFERROR(E40/E37,0) -> 0 | F41: =IFERROR(F40/F37,0) -> 0 | G41: =IFERROR(G40/G37,0) -> 0 | H41: =IFERROR(H40/H37,0) -> 0 | I41: =IFERROR(I40/I37,0) -> 0 | J41: =IFERROR(J40/J37,0) -> 0 | K41: =IFERROR(K40/K37,0) -> -0.19275308 | L41: =IFERROR(L40/L37,0) -> 0.087988524
B43: Retained Earning | D43: =IFERROR(1-D41,0) -> 0.99506766 | E43: =IFERROR(1-E41,0) -> 1 | F43: =IFERROR(1-F41,0) -> 1 | G43: =IFERROR(1-G41,0) -> 1 | H43: =IFERROR(1-H41,0) -> 1 | I43: =IFERROR(1-I41,0) -> 1 | J43: =IFERROR(1-J41,0) -> 1 | K43: =IFERROR(1-K41,0) -> 1.1927531 | L43: =IFERROR(1-L41,0) -> 0.91201148
A45: # | B45: Balance Sheet
B46: Equity Share Capital | C46: =IFERROR('Data Sheet'!B57,0) -> 643.78 | D46: =IFERROR('Data Sheet'!C57,0) -> 679.18 | E46: =IFERROR('Data Sheet'!D57,0) -> 679.22 | F46: =IFERROR('Data Sheet'!E57,0) -> 679.22 | G46: =IFERROR('Data Sheet'!F57,0) -> 679.22 | H46: =IFERROR('Data Sheet'!G57,0) -> 719.54 | I46: =IFERROR('Data Sheet'!H57,0) -> 765.81 | J46: =IFERROR('Data Sheet'!I57,0) -> 765.88 | ... L46: =IFERROR('Data Sheet'!K57,0) -> 766.5
B47: Reserves | C47: =IFERROR('Data Sheet'!B58,0) -> 55618.14 | D47: =IFERROR('Data Sheet'!C58,0) -> 78273.23 | E47: =IFERROR('Data Sheet'!D58,0) -> 57382.67 | F47: =IFERROR('Data Sheet'!E58,0) -> 94748.69 | G47: =IFERROR('Data Sheet'!F58,0) -> 59500.34 | H47: =IFERROR('Data Sheet'!G58,0) -> 62358.99 | I47: =IFERROR('Data Sheet'!H58,0) -> 54480.91 | J47: =IFERROR('Data Sheet'!I58,0) -> 43795.36 | ... L47: =IFERROR('Data Sheet'!K58,0) -> 84151.52
B48: Borrowings | C48: =IFERROR('Data Sheet'!B59,0) -> 73610.39 | D48: =IFERROR('Data Sheet'!C59,0) -> 69359.96 | E48: =IFERROR('Data Sheet'!D59,0) -> 78603.98 | F48: =IFERROR('Data Sheet'!E59,0) -> 88950.47 | G48: =IFERROR('Data Sheet'!F59,0) -> 106175.34 | H48: =IFERROR('Data Sheet'!G59,0) -> 124787.64 | I48: =IFERROR('Data Sheet'!H59,0) -> 142130.57 | J48: =IFERROR('Data Sheet'!I59,0) -> 146449.03 | ... L48: =IFERROR('Data Sheet'!K59,0) -> 107262.5
B49: Other Liabilities | C49: =IFERROR('Data Sheet'!B60,0) -> 107442.48 | D49: =IFERROR('Data Sheet'!C60,0) -> 114871.75 | E49: =IFERROR('Data Sheet'!D60,0) -> 135914.49 | F49: =IFERROR('Data Sheet'!E60,0) -> 142813.43 | G49: =IFERROR('Data Sheet'!F60,0) -> 139348.59 | H49: =IFERROR('Data Sheet'!G60,0) -> 132313.22 | I49: =IFERROR('Data Sheet'!H60,0) -> 144192.62 | J49: =IFERROR('Data Sheet'!I60,0) -> 138051.22 | ... L49: =IFERROR('Data Sheet'!K60,0) -> 177340.09
B50: Total Liabilites | C50: =IFERROR('Data Sheet'!B61,0) -> 237314.79 | D50: =IFERROR('Data Sheet'!C61,0) -> 263184.12 | E50: =IFERROR('Data Sheet'!D61,0) -> 272580.36 | F50: =IFERROR('Data Sheet'!E61,0) -> 327191.81 | G50: =IFERROR('Data Sheet'!F61,0) -> 305703.49 | H50: =IFERROR('Data Sheet'!G61,0) -> 320179.39 | I50: =IFERROR('Data Sheet'!H61,0) -> 341569.91 | J50: =IFERROR('Data Sheet'!I61,0) -> 329061.49 | ... L50: =IFERROR('Data Sheet'!K61,0) -> 369520.61
B52: Fixed Asset Net Block | C52: ='Data Sheet'!B62 -> 88479.49 | D52: ='Data Sheet'!C62 -> 107231.76 | E52: ='Data Sheet'!D62 -> 95944.08 | F52: ='Data Sheet'!E62 -> 121413.86 | G52: ='Data Sheet'!F62 -> 111234.47 | H52: ='Data Sheet'!G62 -> 127107.14 | I52: ='Data Sheet'!H62 -> 138707.61 | J52: ='Data Sheet'!I62 -> 138855.45 | ... L52: ='Data Sheet'!K62 -> 121285.46
B53: Capital Work in Progress | C53: ='Data Sheet'!B63 -> 28640.09 | D53: ='Data Sheet'!C63 -> 25918.94 | E53: ='Data Sheet'!D63 -> 33698.84 | F53: ='Data Sheet'!E63 -> 40033.5 | G53: ='Data Sheet'!F63 -> 31883.84 | H53: ='Data Sheet'!G63 -> 35622.29 | I53: ='Data Sheet'!H63 -> 20963.93 | J53: ='Data Sheet'!I63 -> 10251.09 | ... L53: ='Data Sheet'!K63 -> 35698.43
B54: Investments | C54: ='Data Sheet'!B64 -> 15336.74 | D54: ='Data Sheet'!C64 -> 23767.02 | E54: ='Data Sheet'!D64 -> 20337.92 | F54: ='Data Sheet'!E64 -> 20812.75 | G54: ='Data Sheet'!F64 -> 15770.72 | H54: ='Data Sheet'!G64 -> 16308.48 | I54: ='Data Sheet'!H64 -> 24620.28 | J54: ='Data Sheet'!I64 -> 29379.53 | ... L54: ='Data Sheet'!K64 -> 22971.07
B55: Other Assets | C55: =IFERROR('Data Sheet'!B65-SUM('Data Sheet'!B67:B69),0) -> 30891.17 | D55: =IFERROR('Data Sheet'!C65-SUM('Data Sheet'!C67:C69),0) -> 29579.36 | E55: =IFERROR('Data Sheet'!D65-SUM('Data Sheet'!D67:D69),0) -> 37360.78 | F55: =IFERROR('Data Sheet'!E65-SUM('Data Sheet'!E67:E69),0) -> 48286.86 | G55: =IFERROR('Data Sheet'!F65-SUM('Data Sheet'!F67:F69),0) -> 56155.74 | H55: =IFERROR('Data Sheet'!G65-SUM('Data Sheet'!G67:G69),0) -> 58784.94 | I55: =IFERROR('Data Sheet'!H65-SUM('Data Sheet'!H67:H69),0) -> 61717.96 | J55: =IFERROR('Data Sheet'!I65-SUM('Data Sheet'!I67:I69),0) -> 62223.77 | ... L55: =IFERROR('Data Sheet'!K65-SUM('Data Sheet'!K67:K69),0) -> 79018.86
B56: Total Non Current Asset | C56: =IFERROR(SUM(C52:C55),0) -> 163347.49 | D56: =IFERROR(SUM(D52:D55),0) -> 186497.08 | E56: =IFERROR(SUM(E52:E55),0) -> 187341.62 | F56: =IFERROR(SUM(F52:F55),0) -> 230546.97 | G56: =IFERROR(SUM(G52:G55),0) -> 215044.77 | H56: =IFERROR(SUM(H52:H55),0) -> 237822.85 | I56: =IFERROR(SUM(I52:I55),0) -> 246009.78 | J56: =IFERROR(SUM(J52:J55),0) -> 240709.84 | ... L56: =IFERROR(SUM(L52:L55),0) -> 258973.82
...

Sheet Ratio Analysis
B2: ="Ratio Analysis- "&'Data Sheet'!B1 -> Ratio Analysis- TATA MOTORS LTD
B3: Years | C3: ='Data Sheet'!B16 -> 42094 | D3: ='Data Sheet'!C16 -> 42460 | E3: ='Data Sheet'!D16 -> 42825 | F3: ='Data Sheet'!E16 -> 43190 | G3: ='Data Sheet'!F16 -> 43555 | H3: ='Data Sheet'!G16 -> 43921 | I3: ='Data Sheet'!H16 -> 44286 | J3: ='Data Sheet'!I16 -> 44651 | ... L3: ='Data Sheet'!K16 -> 45382 | M3: Trend | N3: Mean | O3: Median
B5: Sales Growth | D5: =IFERROR(HistoricalFS!D6/HistoricalFS!C6-1,0) -> 0.037569001 | E5: =IFERROR(HistoricalFS!E6/HistoricalFS!D6-1,0) -> -0.01228033 | F5: =IFERROR(HistoricalFS!F6/HistoricalFS!E6-1,0) -> 0.081047746 | G5: =IFERROR(HistoricalFS!G6/HistoricalFS!F6-1,0) -> 0.035629919 | H5: =IFERROR(HistoricalFS!H6/HistoricalFS!G6-1,0) -> -0.13536016 | I5: =IFERROR(HistoricalFS!I6/HistoricalFS!H6-1,0) -> -0.043181168 | J5: =IFERROR(HistoricalFS!J6/HistoricalFS!I6-1,0) -> 0.11472967 | K5: =IFERROR(HistoricalFS!K6/HistoricalFS!J6-1,0) -> 0.24245815 | L5: =IFERROR(HistoricalFS!L6/HistoricalFS!K6-1,0) -> 0.26580803 | N5: =IFERROR(AVERAGE(D5:L5),0) -> 0.065157874 | O5: =IFERROR(MEDIAN(D5:L5),0) -> 0.037569001
B6: EBITDA Growth | D6: =IFERROR(HistoricalFS!D7/HistoricalFS!C7-1,0) -> 0 | E6: =IFERROR(HistoricalFS!E7/HistoricalFS!D7-1,0) -> -1.326874 | F6: =IFERROR(HistoricalFS!F7/HistoricalFS!E7-1,0) -> -7.5998021 | G6: =IFERROR(HistoricalFS!G7/HistoricalFS!F7-1,0) -> -0.56038359 | H6: =IFERROR(HistoricalFS!H7/HistoricalFS!G7-1,0) -> -4.7990589 | I6: =IFERROR(HistoricalFS!I7/HistoricalFS!H7-1,0) -> -0.68099056 | J6: =IFERROR(HistoricalFS!J7/HistoricalFS!I7-1,0) -> -3.6569377 | K6: =IFERROR(HistoricalFS!K7/HistoricalFS!J7-1,0) -> 1.1132994 | L6: =IFERROR(HistoricalFS!L7/HistoricalFS!K7-1,0) -> 0.096304793 | N6: =IFERROR(AVERAGE(D6:L6),0) -> -1.9349381 | O6: =IFERROR(MEDIAN(D6:L6),0) -> -0.68099056
B7: EBIT Growth | D7: =IFERROR(HistoricalFS!D8/HistoricalFS!C8-1,0) -> 0.013074193 | E7: =IFERROR(HistoricalFS!E8/HistoricalFS!D8-1,0) -> -0.00026680088 | F7: =IFERROR(HistoricalFS!F8/HistoricalFS!E8-1,0) -> 0.11182826 | G7: =IFERROR(HistoricalFS!G8/HistoricalFS!F8-1,0) -> 0.063107782 | H7: =IFERROR(HistoricalFS!H8/HistoricalFS!G8-1,0) -> -0.13370417 | I7: =IFERROR(HistoricalFS!I8/HistoricalFS!H8-1,0) -> -0.071538697 | J7: =IFERROR(HistoricalFS!J8/HistoricalFS!I8-1,0) -> 0.1432168 | K7: =IFERROR(HistoricalFS!K8/HistoricalFS!J8-1,0) -> 0.22885637 | L7: =IFERROR(HistoricalFS!L8/HistoricalFS!K8-1,0) -> 0.21919589 | N7: =IFERROR(AVERAGE(D7:L7),0) -> 0.063752181 | O7: =IFERROR(MEDIAN(D7:L7),0) -> 0.063107782
B8: Net Profit Growth | D8: =IFERROR(HistoricalFS!D9/HistoricalFS!C9-1,0) -> -0.023607883 | E8: =IFERROR(HistoricalFS!E9/HistoricalFS!D9-1,0) -> 0.012162893 | F8: =IFERROR(HistoricalFS!F9/HistoricalFS!E9-1,0) -> 0.028472853 | G8: =IFERROR(HistoricalFS!G9/HistoricalFS!F9-1,0) -> 0.026532512 | H8: =IFERROR(HistoricalFS!H9/HistoricalFS!G9-1,0) -> 0.0019152364 | I8: =IFERROR(HistoricalFS!I9/HistoricalFS!H9-1,0) -> -0.029637302 | J8: =IFERROR(HistoricalFS!J9/HistoricalFS!I9-1,0) -> 0.025555187 | K8: =IFERROR(HistoricalFS!K9/HistoricalFS!J9-1,0) -> -0.010947476 | L8: =IFERROR(HistoricalFS!L9/HistoricalFS!K9-1,0) -> -0.036824023 | N8: =IFERROR(AVERAGE(D8:L8),0) -> -0.000708667 | O8: =IFERROR(MEDIAN(D8:L8),0) -> 0.0019152364
B9: Dividend Growth | D9: =IFERROR(HistoricalFS!D10/HistoricalFS!C10-1,0) -> 0 | E9: =IFERROR(HistoricalFS!E10/HistoricalFS!D10-1,0) -> 0 | F9: =IFERROR(HistoricalFS!F10/HistoricalFS!E10-1,0) -> 0 | G9: =IFERROR(HistoricalFS!G10/HistoricalFS!F10-1,0) -> 0 | H9: =IFERROR(HistoricalFS!H10/HistoricalFS!G10-1,0) -> 0 | I9: =IFERROR(HistoricalFS!I10/HistoricalFS!H10-1,0) -> 0 | J9: =IFERROR(HistoricalFS!J10/HistoricalFS!I10-1,0) -> 0 | K9: =IFERROR(HistoricalFS!K10/HistoricalFS!J10-1,0) -> 0 | L9: =IFERROR(HistoricalFS!L10/HistoricalFS!K10-1,0) -> 0 | N9: =IFERROR(AVERAGE(D9:L9),0) -> 0 | O9: =IFERROR(MEDIAN(D9:L9),0) -> 0
B11: Gross Margin | C11: =IFERROR(HistoricalFS!C12,0) -> 0.22914703 | D11: =IFERROR(HistoricalFS!D12,0) -> 0.24734524 | E11: =IFERROR(HistoricalFS!E12,0) -> 0.23819078 | F11: =IFERROR(HistoricalFS!F12,0) -> 0.2164999 | G11: =IFERROR(HistoricalFS!G12,0) -> 0.19571167 | H11: =IFERROR(HistoricalFS!H12,0) -> 0.19417127 | I11: =IFERROR(HistoricalFS!I12,0) -> 0.21805386 | J11: =IFERROR(HistoricalFS!J12,0) -> 0.19807108 | ... L11: =IFERROR(HistoricalFS!L12,0) -> 0.23605715 | N11: =IFERROR(AVERAGE(C11:L11),0) -> 0.21800982 | O11: =IFERROR(MEDIAN(C11:L11),0) -> 0.21727688
B12: EBITDA Margin | C12: =IFERROR(HistoricalFS!C18,0) -> 0.14910626 | D12: =IFERROR(HistoricalFS!D18,0) -> 0.14061845 | E12: =IFERROR(HistoricalFS!E18,0) -> 0.10971269 | F12: =IFERROR(HistoricalFS!F18,0) -> 0.10789788 | G12: =IFERROR(HistoricalFS!G18,0) -> 0.081686629 | H12: =IFERROR(HistoricalFS!H18,0) -> 0.068898034 | I12: =IFERROR(HistoricalFS!I18,0) -> 0.12925584 | J12: =IFERROR(HistoricalFS!J18,0) -> 0.088776328 | ... L12: =IFERROR(HistoricalFS!L18,0) -> 0.1359547 | N12: =IFERROR(AVERAGE(C12:L12),0) -> 0.11038688 | O12: =IFERROR(MEDIAN(C12:L12),0) -> 0.10880529
B13: EBIT Margin | C13: =IFERROR(SUM(HistoricalFS!C26,HistoricalFS!C20)/(HistoricalFS!C6),0) -> 0.098229671 | D13: =IFERROR(SUM(HistoricalFS!D26,HistoricalFS!D20)/(HistoricalFS!D6),0) -> 0.079417028 | E13: =IFERROR(SUM(HistoricalFS!E26,HistoricalFS!E20)/(HistoricalFS!E6),0) -> 0.043322301 | F13: =IFERROR(SUM(HistoricalFS!F26,HistoricalFS!F20)/(HistoricalFS!F6),0) -> 0.033970412 | G13: =IFERROR(SUM(HistoricalFS!G26,HistoricalFS!G20)/(HistoricalFS!G6),0) -> 0.0035560233 | H13: =IFERROR(SUM(HistoricalFS!H26,HistoricalFS!H20)/(HistoricalFS!H6),0) -> -0.013170363 | I13: =IFERROR(SUM(HistoricalFS!I26,HistoricalFS!I20)/(HistoricalFS!I6),0) -> 0.034991608 | J13: =IFERROR(SUM(HistoricalFS!J26,HistoricalFS!J20)/(HistoricalFS!J6),0) -> -0.00041514993 | ... L13: =IFERROR(SUM(HistoricalFS!L26,HistoricalFS!L20)/(HistoricalFS!L6),0) -> 0.073683863 | N13: =IFERROR(AVERAGE(C13:L13),0) -> 0.037368974 | O13: =IFERROR(MEDIAN(C13:L13),0) -> 0.03448101
B14: EBT Margin | C14: =IFERROR(HistoricalFS!C27,0) -> 0.079756085 | D14: =IFERROR(HistoricalFS!D27,0) -> 0.061511301 | E14: =IFERROR(HistoricalFS!E27,0) -> 0.027608071 | F14: =IFERROR(HistoricalFS!F27,0) -> 0.017912164 | G14: =IFERROR(HistoricalFS!G27,0) -> -0.015516079 | H14: =IFERROR(HistoricalFS!H27,0) -> -0.04091536 | I14: =IFERROR(HistoricalFS!I27,0) -> 0.0025763152 | J14: =IFERROR(HistoricalFS!J27,0) -> -0.033856482 | ... L14: =IFERROR(HistoricalFS!L27,0) -> 0.050881564 | N14: =IFERROR(AVERAGE(C14:L14),0) -> 0.014050569 | O14: =IFERROR(MEDIAN(C14:L14),0) -> 0.01024424
B15: Net Profit Margin | C15: =IFERROR(HistoricalFS!C33,0) -> 0.050713147 | D15: =IFERROR(HistoricalFS!D33,0) -> 0.050432382 | E15: =IFERROR(HistoricalFS!E33,0) -> 0.015552749 | F15: =IFERROR(HistoricalFS!F33,0) -> 0.0030196143 | G15: =IFERROR(HistoricalFS!G33,0) -> -0.0074434057 | H15: =IFERROR(HistoricalFS!H33,0) -> -0.042429334 | I15: =IFERROR(HistoricalFS!I33,0) -> -0.0075994792 | J15: =IFERROR(HistoricalFS!J33,0) -> -0.049052155 | ... L15: =IFERROR(HistoricalFS!L33,0) -> 0.059676713 | N15: =IFERROR(AVERAGE(C15:L15),0) -> 0.0061383298 | O15: =IFERROR(MEDIAN(C15:L15),0) -> -0.0022118957
B17: Sales Expenses% Sales | C17: =IFERROR(HistoricalFS!C15,0) -> 0.08004078 | D17: =IFERROR(HistoricalFS!D15,0) -> 0.10672679 | E17: =IFERROR(HistoricalFS!E15,0) -> 0.1284781 | F17: =IFERROR(HistoricalFS!F15,0) -> 0.10860202 | G17: =IFERROR(HistoricalFS!G15,0) -> 0.11402505 | H17: =IFERROR(HistoricalFS!H15,0) -> 0.12527324 | I17: =IFERROR(HistoricalFS!I15,0) -> 0.088798023 | J17: =IFERROR(HistoricalFS!J15,0) -> 0.10929475 | ... L17: =IFERROR(HistoricalFS!L15,0) -> 0.10010244 | N17: =IFERROR(AVERAGE(C17:L17),0) -> 0.10762294 | O17: =IFERROR(MEDIAN(C17:L17),0) -> 0.10894839
B18: Depriciation% Sales | C18: =IFERROR(HistoricalFS!C24,0) -> 0.050876584 | D18: =IFERROR(HistoricalFS!D24,0) -> 0.061201426 | E18: =IFERROR(HistoricalFS!E24,0) -> 0.066390387 | F18: =IFERROR(HistoricalFS!F24,0) -> 0.073927472 | G18: =IFERROR(HistoricalFS!G24,0) -> 0.078130605 | H18: =IFERROR(HistoricalFS!H24,0) -> 0.082068398 | I18: =IFERROR(HistoricalFS!I24,0) -> 0.094264231 | J18: =IFERROR(HistoricalFS!J24,0) -> 0.089191478 | ... L18: =IFERROR(HistoricalFS!L24,0) -> 0.06227084 | N18: =IFERROR(AVERAGE(C18:L18),0) -> 0.073017903 | O18: =IFERROR(MEDIAN(C18:L18),0) -> 0.072892542
B19: OperatingIncome%Sales | C19: =C13 -> 0.098229671 | D19: =D13 -> 0.079417028 | E19: =E13 -> 0.043322301 | F19: =F13 -> 0.033970412 | G19: =G13 -> 0.0035560233 | H19: =H13 -> -0.013170363 | I19: =I13 -> 0.034991608 | J19: =J13 -> -0.00041514993 | ... L19: =L13 -> 0.073683863 | N19: =IFERROR(AVERAGE(C19:L19),0) -> 0.037368974 | O19: =IFERROR(MEDIAN(C19:L19),0) -> 0.03448101
B21: Return on Capital Employed | C21: =IFERROR((HistoricalFS!C17-HistoricalFS!C23)/(SUM(HistoricalFS!C46:C48)),0) -> 0.19904181 | D21: =IFERROR((HistoricalFS!D17-HistoricalFS!D23)/(SUM(HistoricalFS!D46:D48)),0) -> 0.1462081 | E21: =IFERROR((HistoricalFS!E17-HistoricalFS!E23)/(SUM(HistoricalFS!E46:E48)),0) -> 0.085490986 | F21: =IFERROR((HistoricalFS!F17-HistoricalFS!F23)/(SUM(HistoricalFS!F46:F48)),0) -> 0.053716114 | G21: =IFERROR((HistoricalFS!G17-HistoricalFS!G23)/(SUM(HistoricalFS!G46:G48)),0) -> 0.0064542734 | H21: =IFERROR((HistoricalFS!H17-HistoricalFS!H23)/(SUM(HistoricalFS!H46:H48)),0) -> -0.018302178 | I21: =IFERROR((HistoricalFS!I17-HistoricalFS!I23)/(SUM(HistoricalFS!I46:I48)),0) -> 0.044284325 | J21: =IFERROR((HistoricalFS!J17-HistoricalFS!J23)/(SUM(HistoricalFS!J46:J48)),0) -> -0.00060520306 | ... L21: =IFERROR((HistoricalFS!L17-HistoricalFS!L23)/(SUM(HistoricalFS!L46:L48)),0) -> 0.16790573 | N21: =IFERROR(AVERAGE(C21:L21),0) -> 0.072295691 | O21: =IFERROR(MEDIAN(C21:L21),0) -> 0.049000219
B22: Retained Earning% | D22: =HistoricalFS!D43 -> 0.99506766 | E22: =HistoricalFS!E43 -> 1 | F22: =HistoricalFS!F43 -> 1 | G22: =HistoricalFS!G43 -> 1 | H22: =HistoricalFS!H43 -> 1 | I22: =HistoricalFS!I43 -> 1 | J22: =HistoricalFS!J43 -> 1 | K22: =HistoricalFS!K43 -> 1.1927531 | L22: =HistoricalFS!L43 -> 0.91201148 | N22: =IFERROR(AVERAGE(C22:L22),0) -> 1.0110925 | O22: =IFERROR(MEDIAN(C22:L22),0) -> 1
B23: Return on Equity% | C23: =IFERROR(HistoricalFS!C32/(SUM(HistoricalFS!C46:C47)),0) -> 0.2372052 | D23: =IFERROR(HistoricalFS!D32/(SUM(HistoricalFS!D46:D47)),0) -> 0.17441317 | E23: =IFERROR(HistoricalFS!E32/(SUM(HistoricalFS!E46:E47)),0) -> 0.07224119 | F23: =IFERROR(HistoricalFS!F32/(SUM(HistoricalFS!F46:F47)),0) -> 0.0092254981 | G23: =IFERROR(HistoricalFS!G32/(SUM(HistoricalFS!G46:G47)),0) -> -0.037345737 | H23: =IFERROR(HistoricalFS!H32/(SUM(HistoricalFS!H46:H47)),0) -> -0.17560555 | I23: =IFERROR(HistoricalFS!I32/(SUM(HistoricalFS!I46:I47)),0) -> -0.034360592 | J23: =IFERROR(HistoricalFS!J32/(SUM(HistoricalFS!J46:J47)),0) -> -0.30651638 | ... L23: =IFERROR(HistoricalFS!L32/(SUM(HistoricalFS!L46:L47)),0) -> 0.3077567 | N23: =IFERROR(AVERAGE(C23:L23),0) -> 0.01593272 | O23: =IFERROR(MEDIAN(C23:L23),0) -> -0.012567547
B24: Self Sustained Growth Rate | D24: =IFERROR(D22*D23,0) -> 0.1735529 | E24: =IFERROR(E22*E23,0) -> 0.07224119 | F24: =IFERROR(F22*F23,0) -> 0.0092254981 | G24: =IFERROR(G22*G23,0) -> -0.037345737 | H24: =IFERROR(H22*H23,0) -> -0.17560555 | I24: =IFERROR(I22*I23,0) -> -0.034360592 | J24: =IFERROR(J22*J23,0) -> -0.30651638 | K24: =IFERROR(K22*K23,0) -> -0.1045881 | L24: =IFERROR(L22*L23,0) -> 0.28067765 | N24: =IFERROR(AVERAGE(C24:L24),0) -> -0.013635458 | O24: =IFERROR(MEDIAN(C24:L24),0) -> -0.034360592
B25: Intrest Coverage Ratio | C25: =IFERROR((HistoricalFS!C17-HistoricalFS!C23)/(HistoricalFS!C20),0) -> 5.317304 | D25: =IFERROR((HistoricalFS!D17-HistoricalFS!D23)/(HistoricalFS!D20),0) -> 4.4352864 | E25: =IFERROR((HistoricalFS!E17-HistoricalFS!E23)/(HistoricalFS!E20),0) -> 2.7568835 | F25: =IFERROR((HistoricalFS!F17-HistoricalFS!F23)/(HistoricalFS!F20),0) -> 2.1154494 | G25: =IFERROR((HistoricalFS!G17-HistoricalFS!G23)/(HistoricalFS!G20),0) -> 0.18645157 | H25: =IFERROR((HistoricalFS!H17-HistoricalFS!H23)/(HistoricalFS!H20),0) -> -0.47469327 | I25: =IFERROR((HistoricalFS!I17-HistoricalFS!I23)/(HistoricalFS!I20),0) -> 1.0794784 | J25: =IFERROR((HistoricalFS!J17-HistoricalFS!J23)/(HistoricalFS!J20),0) -> -0.012414276 | ... L25: =IFERROR((HistoricalFS!L17-HistoricalFS!L23)/(HistoricalFS!L20),0) -> 3.2314225 | N25: =IFERROR(AVERAGE(C25:L25),0) -> 1.9315375 | O25: =IFERROR(MEDIAN(C25:L25),0) -> 1.5974639
B27: Debtor Turnover Ratio | C27: =HistoricalFS!C6/HistoricalFS!C70 -> -82.780428 | D27: =HistoricalFS!D6/HistoricalFS!D70 -> -122.82753 | E27: =HistoricalFS!E6/HistoricalFS!E70 -> -64.954843 | F27: =HistoricalFS!F6/HistoricalFS!F70 -> -27.278301 | G27: =HistoricalFS!G6/HistoricalFS!G70 -> -33.147261 | H27: =HistoricalFS!H6/HistoricalFS!H70 -> 26.237987 | I27: =HistoricalFS!I6/HistoricalFS!I70 -> -45.375976 | J27: =HistoricalFS!J6/HistoricalFS!J70 -> 1505.1547 | ... L27: =HistoricalFS!L6/HistoricalFS!L70 -> -233.56148 | N27: =IFERROR(AVERAGE(C27:L27),0) -> 76.513295 | O27: =IFERROR(MEDIAN(C27:L27),0) -> -55.16541
B28: Creditor Turnover Ratio | C28: =IFERROR(HistoricalFS!C6/HistoricalFS!C72,0) -> 73.14035 | D28: =IFERROR(HistoricalFS!D6/HistoricalFS!D72,0) -> 69.178009 | E28: =IFERROR(HistoricalFS!E6/HistoricalFS!E72,0) -> 28.996077 | F28: =IFERROR(HistoricalFS!F6/HistoricalFS!F72,0) -> 39.829301 | G28: =IFERROR(HistoricalFS!G6/HistoricalFS!G72,0) -> -64.351748 | H28: =IFERROR(HistoricalFS!H6/HistoricalFS!H72,0) -> -32.290411 | I28: =IFERROR(HistoricalFS!I6/HistoricalFS!I72,0) -> 43.457681 | J28: =IFERROR(HistoricalFS!J6/HistoricalFS!J72,0) -> -39.711013 | ... L28: =IFERROR(HistoricalFS!L6/HistoricalFS!L72,0) -> 31.951537 | N28: =IFERROR(AVERAGE(C28:L28),0) -> 20.001504 | O28: =IFERROR(MEDIAN(C28:L28),0) -> 35.890419
B29: Inventory Turnover | C29: =IFERROR(HistoricalFS!C6/HistoricalFS!C59,0) -> 8.990022 | D29: =IFERROR(HistoricalFS!D6/HistoricalFS!D59,0) -> 8.3613381 | E29: =IFERROR(HistoricalFS!E6/HistoricalFS!E59,0) -> 7.6867643 | F29: =IFERROR(HistoricalFS!F6/HistoricalFS!F59,0) -> 6.9190052 | G29: =IFERROR(HistoricalFS!G6/HistoricalFS!G59,0) -> 7.7392856 | H29: =IFERROR(HistoricalFS!H6/HistoricalFS!H59,0) -> 6.9698269 | I29: =IFERROR(HistoricalFS!I6/HistoricalFS!I59,0) -> 6.9217099 | J29: =IFERROR(HistoricalFS!J6/HistoricalFS!J59,0) -> 7.9015588 | ... L29: =IFERROR(HistoricalFS!L6/HistoricalFS!L59,0) -> 9.1639138 | N29: =IFERROR(AVERAGE(C29:L29),0) -> 7.9142289 | O29: =IFERROR(MEDIAN(C29:L29),0) -> 7.8204222
B30: Fixed Turnover | C30: =IFERROR(HistoricalFS!C6/HistoricalFS!C52,0) -> 2.9742371 | D30: =IFERROR(HistoricalFS!D6/HistoricalFS!D52,0) -> 2.5463128 | E30: =IFERROR(HistoricalFS!E6/HistoricalFS!E52,0) -> 2.8109343 | F30: =IFERROR(HistoricalFS!F6/HistoricalFS!F52,0) -> 2.4012949 | G30: =IFERROR(HistoricalFS!G6/HistoricalFS!G52,0) -> 2.714432 | H30: =IFERROR(HistoricalFS!H6/HistoricalFS!H52,0) -> 2.0539206 | I30: =IFERROR(HistoricalFS!I6/HistoricalFS!I52,0) -> 1.8008727 | J30: =IFERROR(HistoricalFS!J6/HistoricalFS!J52,0) -> 2.0053489 | ... L30: =IFERROR(HistoricalFS!L6/HistoricalFS!L52,0) -> 3.6107195 | N30: =IFERROR(AVERAGE(C30:L30),0) -> 2.5537452 | O30: =IFERROR(MEDIAN(C30:L30),0) -> 2.582846
B31: Capital Turnover Ratio | C31: =IFERROR(HistoricalFS!C6/SUM(HistoricalFS!C46:C47),0) -> 4.6773907 | D31: =IFERROR(HistoricalFS!D6/SUM(HistoricalFS!D46:D47),0) -> 3.4583567 | E31: =IFERROR(HistoricalFS!E6/SUM(HistoricalFS!E46:E47),0) -> 4.6449144 | F31: =IFERROR(HistoricalFS!F6/SUM(HistoricalFS!F46:F47),0) -> 3.0551909 | G31: =IFERROR(HistoricalFS!G6/SUM(HistoricalFS!G46:G47),0) -> 5.0172916 | H31: =IFERROR(HistoricalFS!H6/SUM(HistoricalFS!H46:H47),0) -> 4.138777 | I31: =IFERROR(HistoricalFS!I6/SUM(HistoricalFS!I46:I47),0) -> 4.5214404 | J31: =IFERROR(HistoricalFS!J6/SUM(HistoricalFS!J46:J47),0) -> 6.2487853 | ... L31: =IFERROR(HistoricalFS!L6/SUM(HistoricalFS!L46:L47),0) -> 5.1570652 | N31: =IFERROR(AVERAGE(C31:L31),0) -> 4.855278 | O31: =IFERROR(MEDIAN(C31:L31),0) -> 4.6611525
B34: Debtor Days | C34: =IFERROR(365/C27,0) -> -4.4092548 | D34: =IFERROR(365/D27,0) -> -2.9716465 | E34: =IFERROR(365/E27,0) -> -5.6192884 | F34: =IFERROR(365/F27,0) -> -13.380599 | G34: =IFERROR(365/G27,0) -> -11.011468 | H34: =IFERROR(365/H27,0) -> 13.911128 | I34: =IFERROR(365/I27,0) -> -8.043904 | J34: =IFERROR(365/J27,0) -> 0.24249999 | ... L34: =IFERROR(365/L27,0) -> -1.5627577 | N34: =IFERROR(AVERAGE(C34:L34),0) -> -3.5180036 | O34: =IFERROR(MEDIAN(C34:L34),0) -> -3.6904507
B35: Payabel Days | C35: =IFERROR(365/C28,0) -> 4.9904054 | D35: =IFERROR(365/D28,0) -> 5.2762432 | E35: =IFERROR(365/E28,0) -> 12.58791 | F35: =IFERROR(365/F28,0) -> 9.1641077 | G35: =IFERROR(365/G28,0) -> -5.6719516 | H35: =IFERROR(365/H28,0) -> -11.303665 | I35: =IFERROR(365/I28,0) -> 8.3989756 | J35: =IFERROR(365/J28,0) -> -9.191405 | ... L35: =IFERROR(365/L28,0) -> 11.423551 | N35: =IFERROR(AVERAGE(C35:L35),0) -> 3.3001242 | O35: =IFERROR(MEDIAN(C35:L35),0) -> 6.3016578
B36: Inventory Days | C36: =IFERROR(365/C29,0) -> 40.600568 | D36: =IFERROR(365/D29,0) -> 43.6533 | E36: =IFERROR(365/E29,0) -> 47.484219 | F36: =IFERROR(365/F29,0) -> 52.753249 | G36: =IFERROR(365/G29,0) -> 47.161976 | H36: =IFERROR(365/H29,0) -> 52.368589 | I36: =IFERROR(365/I29,0) -> 52.732635 | J36: =IFERROR(365/J29,0) -> 46.193417 | ... L36: =IFERROR(365/L29,0) -> 39.830143 | N36: =IFERROR(AVERAGE(C36:L36),0) -> 46.57756 | O36: =IFERROR(MEDIAN(C36:L36),0) -> 46.677696
B37: Cash Conversion Cycle(in days) | C37: =IFERROR(SUM(C34,C36)-C35,0) -> 31.200908 | D37: =IFERROR(SUM(D34,D36)-D35,0) -> 35.40541 | E37: =IFERROR(SUM(E34,E36)-E35,0) -> 29.277021 | F37: =IFERROR(SUM(F34,F36)-F35,0) -> 30.208542 | G37: =IFERROR(SUM(G34,G36)-G35,0) -> 41.822459 | H37: =IFERROR(SUM(H34,H36)-H35,0) -> 77.583383 | I37: =IFERROR(SUM(I34,I36)-I35,0) -> 36.289755 | J37: =IFERROR(SUM(J34,J36)-J35,0) -> 55.627322 | ... L37: =IFERROR(SUM(L34,L36)-L35,0) -> 26.843835 | N37: =IFERROR(AVERAGE(C37:L37),0) -> 39.759432 | O37: =IFERROR(MEDIAN(C37:L37),0) -> 34.37055
B39: CFO/Sales | C39: =IFERROR(HistoricalFS!C77/HistoricalFS!C6,0) -> 0.1210675 | D39: =IFERROR(HistoricalFS!D77/HistoricalFS!D6,0) -> 0.14360971 | E39: =IFERROR(HistoricalFS!E77/HistoricalFS!E6,0) -> 0.12404497 | F39: =IFERROR(HistoricalFS!F77/HistoricalFS!F6,0) -> 0.059759806 | G39: =IFERROR(HistoricalFS!G77/HistoricalFS!G6,0) -> 0.03865358 | H39: =IFERROR(HistoricalFS!H77/HistoricalFS!H6,0) -> 0.12141666 | I39: =IFERROR(HistoricalFS!I77/HistoricalFS!I6,0) -> 0.11572301 | J39: =IFERROR(HistoricalFS!J77/HistoricalFS!J6,0) -> 0.012684339 | ... L39: =IFERROR(HistoricalFS!L77/HistoricalFS!L6,0) -> 0.17181144 | N39: =IFERROR(AVERAGE(C39:L39),0) -> 0.10020198 | O39: =IFERROR(MEDIAN(C39:L39),0) -> 0.11839525
B40: CFO/Total Asset | C40: =IFERROR(HistoricalFS!C77/HistoricalFS!C63,0) -> 0.13425206 | D40: =IFERROR(HistoricalFS!D77/HistoricalFS!D63,0) -> 0.14899075 | E40: =IFERROR(HistoricalFS!E77/HistoricalFS!E63,0) -> 0.12273078 | F40: =IFERROR(HistoricalFS!F77/HistoricalFS!F63,0) -> 0.05325011 | G40: =IFERROR(HistoricalFS!G77/HistoricalFS!G63,0) -> 0.038177516 | H40: =IFERROR(HistoricalFS!H77/HistoricalFS!H63,0) -> 0.099000751 | I40: =IFERROR(HistoricalFS!I77/HistoricalFS!I63,0) -> 0.08462982 | J40: =IFERROR(HistoricalFS!J77/HistoricalFS!J63,0) -> 0.010733556 | ... L40: =IFERROR(HistoricalFS!L77/HistoricalFS!L63,0) -> 0.20361787 | N40: =IFERROR(AVERAGE(C40:L40),0) -> 0.099177839 | O40: =IFERROR(MEDIAN(C40:L40),0) -> 0.097697963
B41: CFO/Total Debt | C41: =IFERROR(HistoricalFS!C77/HistoricalFS!C48,0) -> 0.43281933 | D41: =IFERROR(HistoricalFS!D77/HistoricalFS!D48,0) -> 0.56534058 | E41: =IFERROR(HistoricalFS!E77/HistoricalFS!E48,0) -> 0.42560186 | F41: =IFERROR(HistoricalFS!F77/HistoricalFS!F48,0) -> 0.19587305 | G41: =IFERROR(HistoricalFS!G77/HistoricalFS!G48,0) -> 0.10992195 | H41: =IFERROR(HistoricalFS!H77/HistoricalFS!H48,0) -> 0.25401554 | I41: =IFERROR(HistoricalFS!I77/HistoricalFS!I48,0) -> 0.20338341 | J41: =IFERROR(HistoricalFS!J77/HistoricalFS!J48,0) -> 0.024117606 | ... L41: =IFERROR(HistoricalFS!L77/HistoricalFS!L48,0) -> 0.70146603 | N41: =IFERROR(AVERAGE(C41:L41),0) -> 0.31530894 | O41: =IFERROR(MEDIAN(C41:L41),0) -> 0.24728282

Sheet Data Sheet
A1: COMPANY NAME | B1: TATA MOTORS LTD | E1: =IF(B2<>B3, "A NEW VERSION OF THE WORKSHEET IS AVAILABLE", "")
A2: LATEST VERSION | B2: 2.1 | E2: PLEASE DO NOT MAKE ANY CHANGES TO THIS SHEET
A3: CURRENT VERSION | B3: 2.1
A5: META
A6: Number of shares | B6: =IF(B9>0, B9/B8, 0) -> 368.06087
A7: Face Value | B7: 2
A8: Current Price | B8: 728.25
A9: Market Capitalization | B9: 268040.33
A15: PROFIT & LOSS
A16: Report Date | B16: 42094 | C16: 42460 | D16: 42825 | E16: 43190 | F16: 43555 | G16: 43921 | H16: 44286 | I16: 44651 | J16: 45016 | K16: 45382
A17: Sales | B17: 263158.98 | C17: 273045.6 | D17: 269692.51 | E17: 291550.48 | F17: 301938.4 | G17: 261067.97 | H17: 249794.75 | I17: 278453.62 | J17: 345966.97 | K17: 437927.77
A18: Raw Material Cost | B18: 163250.36 | C18: 166134.01 | D18: 173294.08 | E18: 187896.58 | F18: 194267.91 | G18: 164899.82 | H18: 153607.36 | I18: 179295.33 | J18: 231251.26 | K18: 274321.23
A19: Change in Inventory | B19: 3330.35 | C19: 2750.99 | D19: 7399.92 | E19: 2046.58 | F19: -2053.28 | G19: -2231.19 | H19: -4684.16 | I19: -1590.49 | J19: 4781.62 | K19: 1565.53
A20: Power and Fuel | B20: 1121.75 | C20: 1143.63 | D20: 1159.82 | E20: 1308.08 | F20: 1585.93 | G20: 1264.95 | H20: 1112.87 | I20: 2178.29 | J20: 2513.33 | K20: 2195.12
A21: Other Mfr. Exp | B21: 16173.17 | C21: 12101.53 | D21: 10067.37 | E21: 10971.66 | F21: 11694.54 | G21: 11541.51 | H21: 8273.17 | I21: 9427.38 | J21: 11765.97 | K21: 17114.33
A22: Employee Cost | B22: 25641.95 | C22: 28880.89 | D22: 28332.89 | E22: 30300.09 | F22: 33243.87 | G22: 30438.6 | H22: 27648.48 | I22: 30808.52 | J22: 33654.7 | K22: 42486.64
A23: Selling and admin | B23: 23603.01 | C23: 21991.9 | D23: 30039.38 | E23: 31004.58 | F23: 32719.8 | G23: 29248.32 | H23: 23015.79 | I23: 29205.4 | J23: 34839.19 | K23: 42765.33
A24: Other Expenses | B24: -2539.56 | C24: 7149.38 | D24: 4610.2 | E24: 658.39 | F24: 1708.74 | G24: 3456.51 | H24: -834.51 | I24: 1228.12 | J24: 4908.34 | K24: 1072.31
A25: Other Income | B25: 714.03 | C25: -2669.62 | D25: 1869.1 | E25: 5932.73 | F25: -26686.25 | G25: 101.71 | H25: -11117.83 | I25: 2424.05 | J25: 6663.97 | K25: 5672.66
A26: Depreciation | B26: 13388.63 | C26: 16710.78 | D26: 17904.99 | E26: 21553.59 | F26: 23590.63 | G26: 21425.43 | H26: 23546.71 | I26: 24835.69 | J26: 24860.36 | K26: 27270.13
A27: Interest | B27: 4861.49 | C27: 4889.08 | D27: 4238.01 | E27: 4681.79 | F27: 5758.6 | G27: 7243.33 | H27: 8097.17 | I27: 9311.86 | J27: 10225.48 | K27: 9985.76
... A30: Net profit | B30: 13986.29 | C30: 11579.31 | D30: 7454.36 | E30: 8988.91 | F30: -28826.23 | G30: -12070.85 | H30: -13451.39 | I30: -11441.47 | J30: 2414.29 | K30: 31399.09
A31: Dividend Amount | C31: 67.92 | J31: 766.02 | K31: 2299.5
A40: Quarters
A41: Report Date | B41: 44742 | C41: 44834 | D41: 44926 | E41: 45016 | F41: 45107 | G41: 45199 | H41: 45291 | I41: 45382 | J41: 45473 | K41: 45565
A42: Sales | B42: 71934.66 | C42: 79611.37 | D42: 88488.59 | E42: 105932.35 | F42: 102236 | G42: 105129 | H42: 110577.14 | I42: 119986 | J42: 108048 | K42: 101450
A43: Expenses | B43: 69521.93 | C43: 74039.06 | D43: 77668.35 | E43: 92817.95 | F43: 89019 | G43: 91362 | H43: 95158.77 | I43: 102851 | J43: 92263 | K43: 89291
A44: Other Income | B44: 2380.98 | C44: 1351.14 | D44: 1129.98 | E44: 1452.86 | F44: 895 | G44: 1557 | H44: 1603.76 | I44: 1619 | J44: 1747 | K44: 1647
A45: Depreciation | B45: 5841.04 | C45: 5897.34 | D45: 6071.78 | E45: 7050.2 | F45: 6633 | G45: 6637 | H45: 6850 | I45: 7151 | J45: 6574 | K45: 6005
A46: Interest | B46: 2420.72 | C46: 2487.26 | D46: 2675.83 | E46: 2641.67 | F46: 2615 | G46: 2652 | H46: 2484.91 | I46: 2234 | J46: 2088 | K46: 2034
A47: Profit before tax | B47: -3468.05 | C47: -1461.15 | D47: 3202.61 | E47: 4875.39 | F47: 4864 | G47: 6035 | H47: 7687.22 | I47: 9369 | J47: 8870 | K47: 5767
A48: Tax | B48: 1518.96 | C48: -457.08 | D48: 262.83 | E48: -620.65 | F48: 1563 | G48: 2203 | H48: 541.79 | I48: -8160 | J48: 3178 | K48: 2317
A49: Net profit | B49: -5006.6 | C49: -944.61 | D49: 2957.71 | E49: 5407.79 | F49: 3203 | G49: 3764 | H49: 7025.11 | I49: 17407 | J49: 5566 | K49: 3343
A50: Operating Profit | B50: 2412.73 | C50: 5572.31 | D50: 10820.24 | E50: 13114.4 | F50: 13217 | G50: 13767 | H50: 15418.37 | I50: 17135 | J50: 15785 | K50: 12159
A55: BALANCE SHEET
A56: Report Date | B56: 42094 | C56: 42460 | D56: 42825 | E56: 43190 | F56: 43555 | G56: 43921 | H56: 44286 | I56: 44651 | J56: 45016 | K56: 45382
A57: Equity Share Capital | B57: 643.78 | C57: 679.18 | D57: 679.22 | E57: 679.22 | F57: 679.22 | G57: 719.54 | H57: 765.81 | I57: 765.88 | J57: 766.02 | K57: 766.5
A58: Reserves | B58: 55618.14 | C58: 78273.23 | D58: 57382.67 | E58: 94748.69 | F58: 59500.34 | G58: 62358.99 | H58: 54480.91 | I58: 43795.36 | J58: 44555.77 | K58: 84151.52
A59: Borrowings | B59: 73610.39 | C59: 69359.96 | D59: 78603.98 | E59: 88950.47 | F59: 106175.34 | G59: 124787.64 | H59: 142130.57 | I59: 146449.03 | J59: 134113.44 | K59: 107262.5
A60: Other Liabilities | B60: 107442.48 | C60: 114871.75 | D60: 135914.49 | E60: 142813.43 | F60: 139348.59 | G60: 132313.22 | H60: 144192.62 | I60: 138051.22 | J60: 155239.2 | K60: 177340.09
...

Sheet cheat Sheet 
A3: step1- | B3: start with formatinf | D3: and removing grid line(alt+w+vg) and then starting it with2nd colume and first columesize(1.5) by (alt+h+o+w)
A5: step2= | B5: second mae heading diyae " de kae start kiyae -"& name of company so that it help us in future if we change the file tommorowwe don’t have to change everything automatically name of company
B6: would change
A8: step3= | B8: formating kiyae uskae baed ltm mae nichae quarter wala jo report hai data sheet mae uska last 4month ka total le lena .
A9: step4= sales growth(cy/py-1) | D9: Thora differtiate kar kae dhikana hoga
A10: step5= | B10: ltm mae last 4 month ka expense as cogs le lo | G10: ,,, EBITDA of Ltm Must Be Taken From Data sheet.
A11: step6= we are not taking other income now as it is quiet volatile kabhi upar to kabhi bhaut nichae,
A12: step7=in ltm we have not taken seeling &genral as we have taken expense for cogs
A13: step8= | B13: margin and %of sale both are same always remember.
A14: step9= ebitda it is an important metrcis because it helps to understand the profit earned from core business activity befor deducating intrest or depriciation as help to understand how efficently business is performing.
A15: step10-after net profit we are going to take equity shares | G15: eps bhi nikalengae
A16: step11- | B16: fir hamlog divident pershare bhi nikalengae
A17: step12= retained earning =1-dividentpayoutratio | F17: as you know retained earning is 100% kui ho raha hai as kui ki wo divident bata nahi na us month mae) | P17: and see if error mae if ka function use kar kae perform kiyae function
A18: step13=yaed rakhna yae jo other asset hai na balance sheet mae usmae included hai kya | J18: wo current asset wala samjae eisi liyae non current asset aur total liabilites match kar gaya.
A19: step14= aur last mae check kar lengae by total liab=total asset
A20: step15-we cannot take cash flow in it we ahave to take it roughly | H20: as understand jo excel mae unbuild le kae aey thae wo bhaut chota hai | O20: so we are taking it from screener
A22: Ratio analysis
A23: step1= | B23: we will perform rati analysis of last 10 years and not of ltm
A24: step2= starting with all the growth matrices | F24: why we basically use if erroer always remember jabhi bhi ham usko screener mae upload karengae aur jabhi bhi kisi aisa company ka financial model nikal rahe
F25: hai tab (#na) na dhikay as it will creat to much problem samjha .
A26: step3= yaed rakhna growth kisi company ka nikal rahe ho tab kya karengae cy/py-1 | J26: & how to copy and properly shiftclick down button and after that ctrl+c then shiftclick hold and right arrow after
J27: reaching ctrl+v)
A28: Step4= then we should take all the margins | F28: and weather you are doing write or not hoiw will you understand just by seeing all the margins are in a decreasing oder. | R28: and if they are in decreasing oder then you doing right.
A30: step5= expenses AS % of SALE | D30: baet samjo na what we do in margin are similar to what we do in % of sale dono hi samillar hai | M30: ebit = operating income both are same only if you see
M31: ebitda=operting cash earned
A32: step6= return & capital employed are the money left befor giving any of its stake holder. | J32: against money taken from the stake holder and and one is pre tax and post tax any why we are calculating pre tax just because intrest is an tax shield expense
A34: step7= yae jo equity | C34: share capital+reserv kya hota shareholder fund always remember
A36: step8= return on equity=net nprofit/ shareholder fund(eqity+resev)
A38: step9= self sustained growth aur kuch nahi hai khudka kamaya wa paisa sae kitna grow kar raha hai andalways remember it is always told to when company roce is more than wacc it is always recommended
A39: to re invest in business but if your wacc is more than roce it is stupidity to retain | I39: therefor it is nessary for self sustaibned growth to have(retained earmning and return on equity)
A40: formula is RETURN ON EQUITY*RETAINED EARNING
A42: Step 10= | B42: intrest coverage expense=ebit /intrest expense) | G42: jitna jada hoga acha | I42: it will be in x nopt in % or any thing
A43: step11= debtor days kya hota hai pata hai matlab for much time debtors ko diya jata hai for clear its due on an average | M43: formula=365days/debtor turnover it will provie the number of days which is required
M44: or given by us to pay bacjk the debt
A46: step12= through inventory days what we get matlab aj agar producation band ho gaya to merae pas (for ex 40) din goods Hai jo ham bech saktae hai
A48: step 13= cash conversion cycel matlab how much time it is been taken to rotate the money how we calculate it sumof 9DEBTOR DAYS+INVENTORY DAYS )-creditor days
B49: matlab how much time it takes to convert the invested amount into cash more it is less it is good it shows how efficently the operation is working. | P49: we also have to write days with it
B50: how to do custom mae jae kae 0"days"
A51: step 14= CFO is Nothing but cash flow operation.
A53: step15= total debt is always taken as long term bvorrowing and not the total liabilites
...

Sheet cashflow Statement brought 
C3: 42064 | D3: 42430 | E3: 42795 | F3: 43160 | G3: 43525 | H3: 43891 | I3: 44256 | J3: 44621 | K3: 44986 | L3: 45352
B4: Cash from Operating Activity - | C4: 35531 | D4: 37900 | E4: 30199 | F4: 23857 | G4: 18891 | H4: 26633 | I4: 29001 | J4: 14283 | K4: 35388 | L4: 67915
B5: Profit from operations | C5: 43397 | D5: 38626 | E5: 28840 | F5: 33312 | G5: 28771 | H5: 23352 | I5: 31198 | J5: 26943 | K5: 41694 | L5: 65106
B6: Receivables | C6: -3179 | D6: -2223 | E6: -4152 | F6: -10688 | G6: -9109 | H6: 9950 | I6: -5505 | J6: 185 | K6: -2213 | L6: -1875
B7: Inventory | C7: -3692 | D7: -5743 | E7: -6621 | F7: -3560 | G7: 2069 | H7: 2326 | I7: 3814 | J7: 472 | K7: -5665 | L7: -7265
B8: Payables | C8: 3598 | D8: 3947 | E8: 9301 | F8: 7320 | G8: -4692 | H8: -8085 | I8: 5748 | J8: -7012 | K8: 6945 | L8: 13706
B9: Loans Advances | C9: 0 | D9: -520 | E9: 0 | F9: 0 | G9: 0 | H9: 0 | I9: 0 | J9: 0 | K9: 0 | L9: 0
B10: Other WC items | C10: -398 | D10: 5852 | E10: 4727 | F10: 494 | G10: 4512 | H10: 875 | I10: -4150 | J10: -4396 | K10: -2194 | L10: 2760
B11: Working capital changes | C11: -3672 | D11: 1313 | E11: 3254 | F11: -6434 | G11: -7221 | H11: 5065 | I11: -93 | J11: -10750 | K11: -3127 | L11: 7325
B12: Direct taxes | C12: -4194 | D12: -2040 | E12: -1895 | F12: -3021 | G12: -2659 | H12: -1785 | I12: -2105 | J12: -1910 | K12: -3179 | L12: -4516
B13: Cash from Investing Activity - | C13: -36232 | D13: -36694 | E13: -39571 | F13: -25139 | G13: -20878 | H13: -33115 | I13: -25672 | J13: -4444 | K13: -15417 | L13: -22782
B14: Fixed assets purchased | C14: -31962 | D14: -31503 | E14: -16072 | F14: -35079 | G14: -35304 | H14: -29702 | I14: -20205 | J14: -15168 | K14: -19230 | L14: -31414
B15: Fixed assets sold | C15: 74 | D15: 59 | E15: 53 | F15: 30 | G15: 67 | H15: 171 | I15: 351 | J15: 230 | K15: 285 | L15: 231
... B34: Net Cash Flow | C34: 4500 | D34: -2589 | E34: -3167 | F34: 730 | G34: 6843 | H34: -3092 | I34: 13232 | J34: 6459 | K34: -6272 | L34: 8128

Sheet Forcasting
B2: ='Data Sheet'!$B$1&" - "&'Data Sheet'!A17& " Forcasting " -> TATA MOTORS LTD - Sales Forcasting | G2: ='Data Sheet'!$B$1&" - "&HistoricalFS!B17& " Forcasting " -> TATA MOTORS LTD - EBITDA Forcasting | L2: ='Data Sheet'!$B$1&" - "&HistoricalFS!B37& " Forcasting " -> TATA MOTORS LTD - EPS Forcasting
B3: Year weight | C3: Year | D3: Sales | E3: Sales Growth | G3: Year weight | H3: Year | I3: Sales | J3: Sales Growth | L3: Year weight | M3: Year | N3: Sales | O3: Sales Growth
B4: 1 | C4: ='Data Sheet'!$B$16 -> 42094 | D4: {=TRANSPOSE('Data Sheet'!B17:K17)} -> 263158.98 | G4: 1 | H4: =C4 -> 42094 | I4: {=TRANSPOSE(HistoricalFS!C17:M17)} -> 39238.65 | L4: 1 | M4: ='Data Sheet'!$B$16 -> 42094 | N4: {=TRANSPOSE(HistoricalFS!C37:L37)} -> 46.220198
B5: =B4+1 -> 2 | C5: =C4+365 -> 42459 | D5: 273045.6 | E5: =D5/D4-1 -> 0.037569001 | G5: =G4+1 -> 2 | H5: =H4+365 -> 42459 | I5: 38395.25 | J5: =I5/I4-1 -> -0.021494114 | L5: =L4+1 -> 2 | M5: =M4+365 -> 42459 | N5: 47.694444 | O5: =N5/N4-1 -> 0.031896149
B6: =B5+1 -> 3 | C6: =C5+365 -> 42824 | D6: 269692.51 | E6: =D6/D5-1 -> -0.01228033 | G6: =G5+1 -> 3 | H6: =H5+365 -> 42824 | I6: 29588.69 | J6: =I6/I5-1 -> -0.22936587 | L6: =L5+1 -> 3 | M6: =M5+365 -> 42824 | N6: 14.527275 | O6: =N6/N5-1 -> -0.6954095
B7: =B6+1 -> 4 | C7: =C6+365 -> 43189 | D7: 291550.48 | E7: =D7/D6-1 -> 0.081047746 | G7: =G6+1 -> 4 | H7: =H6+365 -> 43189 | I7: 31457.68 | J7: =I7/I6-1 -> 0.063165689 | L7: =L6+1 -> 4 | M7: =M6+365 -> 43189 | N7: 3.0491116 | O7: =N7/N6-1 -> -0.79011124
B8: =B7+1 -> 5 | C8: =C7+365 -> 43554 | D8: 301938.4 | E8: =D8/D7-1 -> 0.035629919 | G8: =G7+1 -> 5 | H8: =H7+365 -> 43554 | I8: 24664.33 | J8: =I8/I7-1 -> -0.21595203 | L8: =L7+1 -> 5 | M8: =M7+365 -> 43554 | N8: -7.7839158 | O8: =N8/N7-1 -> -3.5528471
B9: =B8+1 -> 6 | C9: =C8+365 -> 43919 | D9: 261067.97 | E9: =D9/D8-1 -> -0.13536016 | G9: =G8+1 -> 6 | H9: =H8+365 -> 43919 | I9: 17987.07 | J9: =I9/I8-1 -> -0.27072538 | L9: =L8+1 -> 6 | M9: =M8+365 -> 43919 | N9: -35.859307 | O9: =N9/N8-1 -> 3.6068468
B10: =B9+1 -> 7 | C10: =C9+365 -> 44284 | D10: 249794.75 | E10: =D10/D9-1 -> -0.043181168 | G10: =G9+1 -> 7 | H10: =H9+365 -> 44284 | I10: 32287.43 | J10: =I10/I9-1 -> 0.79503554 | L10: =L9+1 -> 7 | M10: =M9+365 -> 44284 | N10: -5.7172846 | O10: =N10/N9-1 -> -0.84056344
B11: =B10+1 -> 8 | C11: =C10+365 -> 44649 | D11: 278453.62 | E11: =D11/D10-1 -> 0.11472967 | G11: =G10+1 -> 8 | H11: =H10+365 -> 44649 | I11: 24720.09 | J11: =I11/I10-1 -> -0.23437418 | L11: =L10+1 -> 8 | M11: =M10+365 -> 44649 | N11: -41.132141 | O11: =N11/N10-1 -> 6.194349
B12: =B11+1 -> 9 | C12: =C11+365 -> 45014 | D12: 345966.97 | E12: =D12/D11-1 -> 0.24245815 | G12: =G11+1 -> 9 | H12: =H11+365 -> 45014 | I12: 31815.8 | J12: =I12/I11-1 -> 0.28704224 | L12: =L11+1 -> 9 | M12: =M11+365 -> 45014 | N12: -11.965495 | O12: =N12/N11-1 -> -0.70909622
B13: =B12+1 -> 10 | C13: =C12+365 -> 45379 | D13: 437927.77 | E13: =D13/D12-1 -> 0.26580803 | G13: =G12+1 -> 10 | H13: =H12+365 -> 45379 | I13: 59538.34 | J13: =I13/I12-1 -> 0.87134505 | L13: =L12+1 -> 10 | M13: =M12+365 -> 45379 | N13: 78.629509 | O13: =N13/N12-1 -> -7.5713542
B14: =B13+1 -> 11 | C14: =C13+365 -> 45744 | D14: =FORECAST(B14,$D$4:$D$13,$B$4:$B$13) -> 362627.59 | E14: =D14/D13-1 -> -0.17194657 | G14: =G13+1 -> 11 | H14: =H13+365 -> 45744 | I14: =FORECAST(G14,$I$3:$I$13,$G$3:$G$13) -> 36573.001 | J14: =I14/I13-1 -> -0.38572353 | L14: =L13+1 -> 11 | M14: =M13+365 -> 45744 | N14: =FORECAST(L14,$N$4:$N$13,$L$4:$L$13) -> -6.5206751 | O14: =N14/N13-1 -> -1.0829291
B15: =B14+1 -> 12 | C15: =C14+365 -> 46109 | D15: =FORECAST(B15,$D$4:$D$13,$B$4:$B$13) -> 374512.66 | E15: =D15/D14-1 -> 0.032774865 | G15: =G14+1 -> 12 | H15: =H14+365 -> 46109 | I15: =FORECAST(G15,$I$3:$I$13,$G$3:$G$13) -> 37228.214 | J15: =I15/I14-1 -> 0.017915194 | L15: =L14+1 -> 12 | M15: =M14+365 -> 46109 | N15: =FORECAST(L15,$N$4:$N$13,$L$4:$L$13) -> -9.3001141 | O15: =N15/N14-1 -> 0.42625019
B16: =B15+1 -> 13 | C16: =C15+365 -> 46474 | D16: =FORECAST(B16,$D$4:$D$13,$B$4:$B$13) -> 386397.73 | E16: =D16/D15-1 -> 0.031734763 | G16: =G15+1 -> 13 | H16: =H15+365 -> 46474 | I16: =FORECAST(G16,$I$3:$I$13,$G$3:$G$13) -> 37883.426 | J16: =I16/I15-1 -> 0.017599889 | L16: =L15+1 -> 13 | M16: =M15+365 -> 46474 | N16: =FORECAST(L16,$N$4:$N$13,$L$4:$L$13) -> -12.079553 | O16: =N16/N15-1 -> 0.29886074
B17: =B16+1 -> 14 | C17: =C16+365 -> 46839 | D17: =FORECAST(B17,$D$4:$D$13,$B$4:$B$13) -> 398282.8 | E17: =D17/D16-1 -> 0.030758644 | G17: =G16+1 -> 14 | H17: =H16+365 -> 46839 | I17: =FORECAST(G17,$I$3:$I$13,$G$3:$G$13) -> 38538.639 | J17: =I17/I16-1 -> 0.01729549 | L17: =L16+1 -> 14 | M17: =M16+365 -> 46839 | N17: =FORECAST(L17,$N$4:$N$13,$L$4:$L$13) -> -14.858992 | O17: =N17/N16-1 -> 0.23009452
B18: =B17+1 -> 15 | C18: =C17+365 -> 47204 | D18: =FORECAST(B18,$D$4:$D$13,$B$4:$B$13) -> 410167.87 | E18: =D18/D17-1 -> 0.029840782 | G18: =G17+1 -> 15 | H18: =H17+365 -> 47204 | I18: =FORECAST(G18,$I$3:$I$13,$G$3:$G$13) -> 39193.851 | J18: =I18/I17-1 -> 0.017001442 | L18: =L17+1 -> 15 | M18: =M17+365 -> 47204 | N18: =FORECAST(L18,$N$4:$N$13,$L$4:$L$13) -> -17.638431 | O18: =N18/N17-1 -> 0.18705434

Sheet Sheet1
